Workbook
Name beef: #REF!
Name beef: #REF!
Name beef: #REF!
Name beef: #REF!
Name beef: #REF!
Name cocoa: #REF!
Name cocoa: #REF!
Name cocoa: #REF!
Name cocoa: #REF!
Name cocoa: #REF!
Name cocoa2: #REF!
Name cocoa2: #REF!
Name cocoa2: #REF!
Name cocoa2: #REF!
Name cocoa2: #REF!
Name coil: #REF!
Name coil: #REF!
Name coil: #REF!
Name coil: #REF!
Name coil: #REF!
Name DATES_A: #REF!
Name DATES_A: #REF!
Name DATES_A: #REF!
Name DATES_A: #REF!
Name DATES_A: #REF!
Name Donor_Rev1: [1]Budget_Donor!$A$1:$O$652
Name e: #REF!
Name e: #REF!
Name e: #REF!
Name e: #REF!
Name e: #REF!
Name ex: #REF!
Name ex: #REF!
Name ex: #REF!
Name ex: #REF!
Name ex: #REF!
Name Exp: [2]Budget!$A$1:$O$5890
Name exr: #REF!
Name exr: #REF!
Name exr: #REF!
Name exr: #REF!
Name exr: #REF!
Name Fund: [3]tbl_Funding_Source!$A$2:$B$53
Name Funding_Source: [4]Funding_Source!$A$1:$D$54
Name ge: #REF!
Name ge: #REF!
Name ge: #REF!
Name ge: #REF!
Name ge: #REF!
Name Item: [3]tbl_Item_Code!$A$2:$B$395
Name Location: [3]tbl_Location!$A$2:$B$9
Name NAMES_A: #REF!
Name NAMES_A: #REF!
Name NAMES_A: #REF!
Name NAMES_A: #REF!
Name NAMES_A: #REF!
Name PRINT_AREA_MI: #REF!
Name PRINT_AREA_MI: #REF!
Name PRINT_AREA_MI: #REF!
Name PRINT_AREA_MI: #REF!

Sheet GFS 2025_26 Budget
B1: 0 | C1: =1189-600 -> 589 | D1: Discrepancies | E1: =Sum_Bud_data!N9 -> Actual FY2025 | F1: Budget Estimate 2025/26 | G1: =Sum_Bud_data!P9 -> Budget Outturn FY2026 | H1: =Sum_Bud_data!Q9 -> Budget Statement 2026/27 (Recurrent) | I1: =Sum_Bud_data!R9 -> Budget Statement 2026/27 (Budget Support) | J1: =Sum_Bud_data!S9 -> Budget Statement 2026/27 (Development Cash) | K1: =Sum_Bud_data!T9 -> Budget Statement 2026/27 (In-kind) | L1: =Sum_Bud_data!U9 -> Budget Estimate 2026/27 | M1: =Sum_Bud_data!V9 -> Budget Statement 2027/28 (Recurrent) | N1: =Sum_Bud_data!W9 -> Budget Statement 2027/28 (Budget Support) | ... V1: =Sum_Bud_data!AE9 -> Budget Estimate 2028/29
B2: =IFERROR(LEFT(C2,1),"") | D2: Total Receipts (TR) | E2: =SUMIFS(E$6:E$1018, $B6:$B1018, "0") -> 8.3754088e+08 | F2: =SUMIFS(F$6:F$1018, $B6:$B1018, "0") -> 993780200 | G2: =SUMIFS(G$6:G$1018, $B6:$B1018, "0") -> 825726700 | H2: =SUMIFS(H$6:H$1018, $B6:$B1018, "0") -> 481018400 | I2: =SUMIFS(I$6:I$1018, $B6:$B1018, "0") -> 118010900 | J2: =SUMIFS(J$6:J$1018, $B6:$B1018, "0") -> 133083800 | K2: =SUMIFS(K$6:K$1018, $B6:$B1018, "0") -> 214157200 | L2: =SUMIFS(L$6:L$1018, $B6:$B1018, "0") -> 946270300 | ... V2: =SUMIFS(V$6:V$1018, $B6:$B1018, "0") -> 760201900
B3: =IFERROR(LEFT(C3,1),"") | D3: Total Payments (TP) | E3: =SUMIFS(E$6:E$1000, $B6:$B1000, "1")+SUMIFS(E$6:E$1000, $B6:$B1000, "2") -> 8.6433646e+08 | F3: =SUMIFS(F$6:F$1000, $B6:$B1000, "1")+SUMIFS(F$6:F$1000, $B6:$B1000, "2") -> 992831600 | G3: =SUMIFS(G$6:G$1018, $B6:$B1018, "1")+SUMIFS(G$6:G$1018, $B6:$B1018, "2") -> 824334500 | H3: =SUMIFS(H$6:H$1018, $B6:$B1018, "1")+SUMIFS(H$6:H$1018, $B6:$B1018, "2") -> 484154600 | I3: =SUMIFS(I$6:I$1018, $B6:$B1018, "1")+SUMIFS(I$6:I$1018, $B6:$B1018, "2") -> 118010900 | J3: =SUMIFS(J$6:J$1018, $B6:$B1018, "1")+SUMIFS(J$6:J$1018, $B6:$B1018, "2") -> 133083800 | K3: =SUMIFS(K$6:K$1018, $B6:$B1018, "1")+SUMIFS(K$6:K$1018, $B6:$B1018, "2") -> 214157200 | L3: =SUMIFS(L$6:L$1018, $B6:$B1018, "1")+SUMIFS(L$6:L$1018, $B6:$B1018, "2") -> 949406500 | M3: =SUMIFS(M$6:M$1018, $B6:$B1018, "1")+SUMIFS(M$6:M$1018, $B6:$B1018, "2") -> 486046300 | N3: =SUMIFS(N$6:N$1018, $B6:$B1018, "1")+SUMIFS(N$6:N$1018, $B6:$B1018, "2") -> 86953000 | ... V3: =SUMIFS(V$6:V$1018, $B6:$B1018, "1")+SUMIFS(V$6:V$1018, $B6:$B1018, "2") -> 761439900
B4: =IFERROR(LEFT(C4,1),"") | D4: Receipts less Payments | E4: =E2-E3 -> -26795589 | F4: =F2-F3 -> 948600 | G4: =G2-G3 -> 1392200 | H4: =H2-H3 -> -3136200 | I4: =I2-I3 -> 0 | J4: =J2-J3 -> 0 | K4: =K2-K3 -> 0 | L4: =L2-L3 -> -3136200 | ... V4: =V2-V3 -> -1238000
A5: GFSM 2001 Code | B5: =IFERROR(LEFT(C5,1),"") -> I | C5: Item Code | D5: Statement of Government Operations ($m) | E5: =E1 -> Actual FY2025 | F5: =F1 -> Budget Estimate 2025/26 | G5: =G1 -> Budget Outturn FY2026 | H5: =H1 -> Budget Statement 2026/27 (Recurrent) | I5: =I1 -> Budget Statement 2026/27 (Budget Support) | J5: =J1 -> Budget Statement 2026/27 (Development Cash) | K5: =K1 -> Budget Statement 2026/27 (In-kind) | L5: =L1 -> Budget Estimate 2026/27 | ... V5: =V1 -> Budget Estimate 2028/29
A6: 1 | B6: =IFERROR(LEFT(C6,1),"") | D6: REVENUE | E6: =SUM(E7,E139,E156,E269) -> 8.1096293e+08 | F6: =SUM(F7,F139,F156,F269) -> 929756100 | G6: =SUM(G7,G139,G156,G269) -> 791356900 | H6: =SUM(H7,H139,H156,H269) -> 412146400 | I6: =SUM(I7,I139,I156,I269) -> 118010900 | J6: =SUM(J7,J139,J156,J269) -> 133083800 | K6: =SUM(K7,K139,K156,K269) -> 214157200 | L6: =IFERROR(SUM(H6:K6),"") -> 877398300 | M6: =SUM(M7,M139,M156,M269) -> 459512900 | N6: =SUM(N7,N139,N156,N269) -> 86953000 | O6: =SUM(O7,O139,O156,O269) -> 105835800 | P6: =SUM(P7,P139,P156,P269) -> 233839500 | Q6: =IFERROR(SUM(M6:P6),"") -> 886141200 | R6: =SUM(R7,R139,R156,R269) -> 483292700 | S6: =SUM(S7,S139,S156,S269) -> 47529100 | T6: =SUM(T7,T139,T156,T269) -> 79504600 | U6: =SUM(U7,U139,U156,U269) -> 143848800 | V6: =IFERROR(SUM(R6:U6),"") -> 754175200
A7: 11 | B7: =IFERROR(LEFT(C7,1),"") | D7: Taxes | E7: =SUM(E8,E27,E30,E53,E111,E133) -> 3.2847224e+08 | F7: =SUM(F8,F27,F30,F53,F111,F133) -> 347077400 | G7: =SUM(G8,G27,G30,G53,G111,G133) -> 342804700 | H7: =SUM(H8,H27,H30,H53,H111,H133) -> 351914600 | I7: =SUM(I8,I27,I30,I53,I111,I133) -> 0 | J7: =SUM(J8,J27,J30,J53,J111,J133) -> 0 | K7: =SUM(K8,K27,K30,K53,K111,K133) -> 0 | L7: =IFERROR(SUM(H7:K7),"") -> 351914600 | M7: =SUM(M8,M27,M30,M53,M111,M133) -> 394737300 | N7: =SUM(N8,N27,N30,N53,N111,N133) -> 0 | O7: =SUM(O8,O27,O30,O53,O111,O133) -> 0 | P7: =SUM(P8,P27,P30,P53,P111,P133) -> 0 | Q7: =IFERROR(SUM(M7:P7),"") -> 394737300 | R7: =SUM(R8,R27,R30,R53,R111,R133) -> 414770900 | S7: =SUM(S8,S27,S30,S53,S111,S133) -> 0 | T7: =SUM(T8,T27,T30,T53,T111,T133) -> 0 | U7: =SUM(U8,U27,U30,U53,U111,U133) -> 0 | V7: =IFERROR(SUM(R7:U7),"") -> 414770900
A8: 111 | B8: =IFERROR(LEFT(C8,1),"") | D8: Taxes on income, profits, and capital gains | E8: =SUM(E12,E21) -> 76885797 | F8: =SUM(F12,F21) -> 78699500 | G8: =SUM(G12,G21) -> 78663200 | H8: =SUM(H12,H21) -> 81751200 | I8: =SUM(I12,I21) -> 0 | J8: =SUM(J12,J21) -> 0 | K8: =SUM(K12,K21) -> 0 | L8: =IFERROR(SUM(H8:K8),"") -> 81751200 | M8: =SUM(M12,M21) -> 89777000 | N8: =SUM(N12,N21) -> 0 | O8: =SUM(O12,O21) -> 0 | P8: =SUM(P12,P21) -> 0 | Q8: =IFERROR(SUM(M8:P8),"") -> 89777000 | R8: =SUM(R12,R21) -> 94209800 | S8: =SUM(S12,S21) -> 0 | T8: =SUM(T12,T21) -> 0 | U8: =SUM(U12,U21) -> 0 | V8: =IFERROR(SUM(R8:U8),"") -> 94209800
A9: 1111 | B9: =IFERROR(LEFT(C9,1),"") | D9: Payable by individuals
A10: 1111 | B10: =IFERROR(LEFT(C10,1),"") -> 0 | C10: 0001 | D10: PAYE Tax - Government (Small Business) | E10: =IFERROR(VLOOKUP($C10,'[8]Total Inflows'!$AE$4:$AH$165,2,0),"") -> 12324076 | F10: =IFERROR(VLOOKUP($C10,'[8]Total Inflows'!$AE$4:$AH$165,3,0),"") -> 11681600 | G10: =IFERROR(VLOOKUP($C10,'[8]Total Inflows'!$AE$4:$AH$165,4,0),"") -> 13386200 | H10: =IFERROR(VLOOKUP($C10,'[8]Total Inflows'!$AJ$4:$AM$110,2,0),"") -> 14303000 | I10: =IFERROR(VLOOKUP($C10,'[8]Total Inflows'!$AO$4:$AR$10,2,0),"") -> 0 | J10: =IFERROR(VLOOKUP($C10,'[8]Total Inflows'!$AU$4:$AX$54,2,0),"") -> 0 | K10: =IFERROR(VLOOKUP($C10,'[8]Total Inflows'!$AZ$4:$BC$30,2,0),"") | L10: =IFERROR(SUM(H10:K10),"") -> 14303000 | M10: =IFERROR(VLOOKUP($C10,'[8]Total Inflows'!$AJ$4:$AM$110,3,0),"") -> 15277400 | N10: =IFERROR(VLOOKUP($C10,'[8]Total Inflows'!$AO$4:$AR$10,3,0),"") -> 0 | O10: =IFERROR(VLOOKUP($C10,'[8]Total Inflows'!$AU$4:$AX$54,3,0),"") -> 0 | P10: =IFERROR(VLOOKUP($C10,'[8]Total Inflows'!$AZ$4:$BC$30,3,0),"") | Q10: =IFERROR(SUM(M10:P10),"") -> 15277400 | R10: =IFERROR(VLOOKUP($C10,'[8]Total Inflows'!$AJ$4:$AM$110,4,0),"") -> 16372000 | S10: =IFERROR(VLOOKUP($C10,'[8]Total Inflows'!$AO$4:$AR$10,4,0),"") -> 0 | T10: =IFERROR(VLOOKUP($C10,'[8]Total Inflows'!$AU$4:$AX$54,4,0),"") -> 0 | U10: =IFERROR(VLOOKUP($C10,'[8]Total Inflows'!$AZ$4:$BC$30,4,0),"") | V10: =IFERROR(SUM(R10:U10),"") -> 16372000
A11: 1111 | B11: =IFERROR(LEFT(C11,1),"") -> 0 | C11: 0002 | D11: PAYE Tax - Non-Government (Large / Small Business) | E11: =IFERROR(VLOOKUP($C11,'[8]Total Inflows'!$AE$4:$AH$165,2,0),"") -> 16454602 | F11: =IFERROR(VLOOKUP($C11,'[8]Total Inflows'!$AE$4:$AH$165,3,0),"") -> 17090300 | G11: =IFERROR(VLOOKUP($C11,'[8]Total Inflows'!$AE$4:$AH$165,4,0),"") -> 16802800 | H11: =IFERROR(VLOOKUP($C11,'[8]Total Inflows'!$AJ$4:$AM$110,2,0),"") -> 17953800 | I11: =IFERROR(VLOOKUP($C11,'[8]Total Inflows'!$AO$4:$AR$10,2,0),"") | J11: =IFERROR(VLOOKUP($C11,'[8]Total Inflows'!$AU$4:$AX$54,2,0),"") | K11: =IFERROR(VLOOKUP($C11,'[8]Total Inflows'!$AZ$4:$BC$30,2,0),"") | L11: =IFERROR(SUM(H11:K11),"") -> 17953800 | M11: =IFERROR(VLOOKUP($C11,'[9]Total Inflows'!$AI$4:$AL$110,3,0),"") -> 19176800 | N11: =IFERROR(VLOOKUP($C11,'[8]Total Inflows'!$AO$4:$AR$10,3,0),"") | O11: =IFERROR(VLOOKUP($C11,'[8]Total Inflows'!$AU$4:$AX$54,3,0),"") | P11: =IFERROR(VLOOKUP($C11,'[8]Total Inflows'!$AZ$4:$BC$30,3,0),"") | Q11: =IFERROR(SUM(M11:P11),"") -> 19176800 | R11: =IFERROR(VLOOKUP($C11,'[9]Total Inflows'!$AI$4:$AL$110,4,0),"") -> 19550900 | S11: =IFERROR(VLOOKUP($C11,'[8]Total Inflows'!$AO$4:$AR$10,4,0),"") | T11: =IFERROR(VLOOKUP($C11,'[8]Total Inflows'!$AU$4:$AX$54,4,0),"") | U11: =IFERROR(VLOOKUP($C11,'[8]Total Inflows'!$AZ$4:$BC$30,4,0),"") | V11: =IFERROR(SUM(R11:U11),"") -> 19550900
B12: =IFERROR(LEFT(C12,1),"") | E12: =SUM(E10:E11) -> 28778678 | F12: =SUM(F10:F11) -> 28771900 | G12: =SUM(G10:G11) -> 30189000 | H12: =SUM(H10:H11) -> 32256800 | I12: =SUM(I10:I11) -> 0 | J12: =SUM(J10:J11) -> 0 | K12: =SUM(K10:K11) -> 0 | L12: =IFERROR(SUM(H12:K12),"") -> 32256800 | M12: =SUM(M10:M11) -> 34454200 | N12: =SUM(N10:N11) -> 0 | O12: =SUM(O10:O11) -> 0 | P12: =SUM(P10:P11) -> 0 | Q12: =IFERROR(SUM(M12:P12),"") -> 34454200 | R12: =SUM(R10:R11) -> 35922900 | S12: =SUM(S10:S11) -> 0 | T12: =SUM(T10:T11) -> 0 | U12: =SUM(U10:U11) -> 0 | V12: =IFERROR(SUM(R12:U12),"") -> 35922900
B13: =IFERROR(LEFT(C13,1),"")
B14: =IFERROR(LEFT(C14,1),"")
A15: 1112 | B15: =IFERROR(LEFT(C15,1),"") | D15: Payable by corporations and other enterprises
A16: 1112 | B16: =IFERROR(LEFT(C16,1),"") -> 0 | C16: 0003 | D16: Corporate Tax - Small Business | E16: =IFERROR(VLOOKUP($C16,'[8]Total Inflows'!$AE$4:$AH$165,2,0),"") -> 1161421.7 | F16: =IFERROR(VLOOKUP($C16,'[8]Total Inflows'!$AE$4:$AH$165,3,0),"") -> 1399400 | G16: =IFERROR(VLOOKUP($C16,'[8]Total Inflows'!$AE$4:$AH$165,4,0),"") -> 930400 | H16: =IFERROR(VLOOKUP($C16,'[8]Total Inflows'!$AJ$4:$AM$110,2,0),"") -> 894100 | I16: =IFERROR(VLOOKUP($C16,'[8]Total Inflows'!$AO$4:$AR$10,2,0),"") | J16: =IFERROR(VLOOKUP($C16,'[8]Total Inflows'!$AU$4:$AX$54,2,0),"") | K16: =IFERROR(VLOOKUP($C16,'[8]Total Inflows'!$AZ$4:$BC$30,2,0),"") | L16: =IFERROR(SUM(H16:K16),"") -> 894100 | M16: =IFERROR(VLOOKUP($C16,'[9]Total Inflows'!$AI$4:$AL$110,3,0),"") -> 1061800 | N16: =IFERROR(VLOOKUP($C16,'[8]Total Inflows'!$AO$4:$AR$10,3,0),"") | O16: =IFERROR(VLOOKUP($C16,'[8]Total Inflows'!$AU$4:$AX$54,3,0),"") | P16: =IFERROR(VLOOKUP($C16,'[8]Total Inflows'!$AZ$4:$BC$30,3,0),"") | Q16: =IFERROR(SUM(M16:P16),"") -> 1061800 | R16: =IFERROR(VLOOKUP($C16,'[9]Total Inflows'!$AI$4:$AL$110,4,0),"") -> 1137900 | S16: =IFERROR(VLOOKUP($C16,'[8]Total Inflows'!$AO$4:$AR$10,4,0),"") | T16: =IFERROR(VLOOKUP($C16,'[8]Total Inflows'!$AU$4:$AX$54,4,0),"") | U16: =IFERROR(VLOOKUP($C16,'[8]Total Inflows'!$AZ$4:$BC$30,4,0),"") | V16: =IFERROR(SUM(R16:U16),"") -> 1137900
A17: 1112 | B17: =IFERROR(LEFT(C17,1),"") -> 0 | C17: 0004 | D17: Corporate Tax - Large Business | E17: =IFERROR(VLOOKUP($C17,'[8]Total Inflows'!$AE$4:$AH$165,2,0),"") -> 25009988 | F17: =IFERROR(VLOOKUP($C17,'[8]Total Inflows'!$AE$4:$AH$165,3,0),"") -> 24262700 | G17: =IFERROR(VLOOKUP($C17,'[8]Total Inflows'!$AE$4:$AH$165,4,0),"") -> 24889900 | H17: =IFERROR(VLOOKUP($C17,'[8]Total Inflows'!$AJ$4:$AM$110,2,0),"") -> 25394800 | I17: =IFERROR(VLOOKUP($C17,'[8]Total Inflows'!$AO$4:$AR$10,2,0),"") | J17: =IFERROR(VLOOKUP($C17,'[8]Total Inflows'!$AU$4:$AX$54,2,0),"") | K17: =IFERROR(VLOOKUP($C17,'[8]Total Inflows'!$AZ$4:$BC$30,2,0),"") | L17: =IFERROR(SUM(H17:K17),"") -> 25394800 | M17: =IFERROR(VLOOKUP($C17,'[9]Total Inflows'!$AI$4:$AL$110,3,0),"") -> 28406500 | N17: =IFERROR(VLOOKUP($C17,'[8]Total Inflows'!$AO$4:$AR$10,3,0),"") | O17: =IFERROR(VLOOKUP($C17,'[8]Total Inflows'!$AU$4:$AX$54,3,0),"") | P17: =IFERROR(VLOOKUP($C17,'[8]Total Inflows'!$AZ$4:$BC$30,3,0),"") | Q17: =IFERROR(SUM(M17:P17),"") -> 28406500 | R17: =IFERROR(VLOOKUP($C17,'[9]Total Inflows'!$AI$4:$AL$110,4,0),"") -> 30441900 | S17: =IFERROR(VLOOKUP($C17,'[8]Total Inflows'!$AO$4:$AR$10,4,0),"") | T17: =IFERROR(VLOOKUP($C17,'[8]Total Inflows'!$AU$4:$AX$54,4,0),"") | U17: =IFERROR(VLOOKUP($C17,'[8]Total Inflows'!$AZ$4:$BC$30,4,0),"") | V17: =IFERROR(SUM(R17:U17),"") -> 30441900
A18: 1112 | B18: =IFERROR(LEFT(C18,1),"") -> 0 | C18: 0005 | D18: Witholding Tax (residents) | E18: =IFERROR(VLOOKUP($C18,'[8]Total Inflows'!$AE$4:$AH$165,2,0),"") -> 637133.23 | F18: =IFERROR(VLOOKUP($C18,'[8]Total Inflows'!$AE$4:$AH$165,3,0),"") -> 670500 | G18: =IFERROR(VLOOKUP($C18,'[8]Total Inflows'!$AE$4:$AH$165,4,0),"") -> 719200 | H18: =IFERROR(VLOOKUP($C18,'[8]Total Inflows'!$AJ$4:$AM$110,2,0),"") -> 668400 | I18: =IFERROR(VLOOKUP($C18,'[8]Total Inflows'!$AO$4:$AR$10,2,0),"") | J18: =IFERROR(VLOOKUP($C18,'[8]Total Inflows'!$AU$4:$AX$54,2,0),"") | K18: =IFERROR(VLOOKUP($C18,'[8]Total Inflows'!$AZ$4:$BC$30,2,0),"") | L18: =IFERROR(SUM(H18:K18),"") -> 668400 | M18: =IFERROR(VLOOKUP($C18,'[9]Total Inflows'!$AI$4:$AL$110,3,0),"") -> 820800 | N18: =IFERROR(VLOOKUP($C18,'[8]Total Inflows'!$AO$4:$AR$10,3,0),"") | O18: =IFERROR(VLOOKUP($C18,'[8]Total Inflows'!$AU$4:$AX$54,3,0),"") | P18: =IFERROR(VLOOKUP($C18,'[8]Total Inflows'!$AZ$4:$BC$30,3,0),"") | Q18: =IFERROR(SUM(M18:P18),"") -> 820800 | R18: =IFERROR(VLOOKUP($C18,'[9]Total Inflows'!$AI$4:$AL$110,4,0),"") -> 879600 | S18: =IFERROR(VLOOKUP($C18,'[8]Total Inflows'!$AO$4:$AR$10,4,0),"") | T18: =IFERROR(VLOOKUP($C18,'[8]Total Inflows'!$AU$4:$AX$54,4,0),"") | U18: =IFERROR(VLOOKUP($C18,'[8]Total Inflows'!$AZ$4:$BC$30,4,0),"") | V18: =IFERROR(SUM(R18:U18),"") -> 879600
A19: 1112 | B19: =IFERROR(LEFT(C19,1),"") -> 0 | C19: 0006 | D19: Witholding Tax (non-residents) | E19: =IFERROR(VLOOKUP($C19,'[8]Total Inflows'!$AE$4:$AH$165,2,0),"") -> 16757774 | F19: =IFERROR(VLOOKUP($C19,'[8]Total Inflows'!$AE$4:$AH$165,3,0),"") -> 18375100 | G19: =IFERROR(VLOOKUP($C19,'[8]Total Inflows'!$AE$4:$AH$165,4,0),"") -> 18558300 | H19: =IFERROR(VLOOKUP($C19,'[8]Total Inflows'!$AJ$4:$AM$110,2,0),"") -> 18929400 | I19: =IFERROR(VLOOKUP($C19,'[8]Total Inflows'!$AO$4:$AR$10,2,0),"") | J19: =IFERROR(VLOOKUP($C19,'[8]Total Inflows'!$AU$4:$AX$54,2,0),"") | K19: =IFERROR(VLOOKUP($C19,'[8]Total Inflows'!$AZ$4:$BC$30,2,0),"") | L19: =IFERROR(SUM(H19:K19),"") -> 18929400 | M19: =IFERROR(VLOOKUP($C19,'[9]Total Inflows'!$AI$4:$AL$110,3,0),"") -> 21180200 | N19: =IFERROR(VLOOKUP($C19,'[8]Total Inflows'!$AO$4:$AR$10,3,0),"") | O19: =IFERROR(VLOOKUP($C19,'[8]Total Inflows'!$AU$4:$AX$54,3,0),"") | P19: =IFERROR(VLOOKUP($C19,'[8]Total Inflows'!$AZ$4:$BC$30,3,0),"") | Q19: =IFERROR(SUM(M19:P19),"") -> 21180200 | R19: =IFERROR(VLOOKUP($C19,'[9]Total Inflows'!$AI$4:$AL$110,4,0),"") -> 21697900 | S19: =IFERROR(VLOOKUP($C19,'[8]Total Inflows'!$AO$4:$AR$10,4,0),"") | T19: =IFERROR(VLOOKUP($C19,'[8]Total Inflows'!$AU$4:$AX$54,4,0),"") | U19: =IFERROR(VLOOKUP($C19,'[8]Total Inflows'!$AZ$4:$BC$30,4,0),"") | V19: =IFERROR(SUM(R19:U19),"") -> 21697900
A20: 1112 | B20: =IFERROR(LEFT(C20,1),"") -> 0 | C20: 0010 | D20: Tax Debts Recovered (Corporate) | E20: =IFERROR(VLOOKUP($C20,'[8]Total Inflows'!$AE$4:$AH$165,2,0),"") -> 4540802.2 | F20: =IFERROR(VLOOKUP($C20,'[8]Total Inflows'!$AE$4:$AH$165,3,0),"") -> 5219900 | G20: =IFERROR(VLOOKUP($C20,'[8]Total Inflows'!$AE$4:$AH$165,4,0),"") -> 3376400 | H20: =IFERROR(VLOOKUP($C20,'[8]Total Inflows'!$AJ$4:$AM$110,2,0),"") -> 3607700 | I20: =IFERROR(VLOOKUP($C20,'[8]Total Inflows'!$AO$4:$AR$10,2,0),"") | J20: =IFERROR(VLOOKUP($C20,'[8]Total Inflows'!$AU$4:$AX$54,2,0),"") | K20: =IFERROR(VLOOKUP($C20,'[8]Total Inflows'!$AZ$4:$BC$30,2,0),"") | L20: =IFERROR(SUM(H20:K20),"") -> 3607700 | M20: =IFERROR(VLOOKUP($C20,'[9]Total Inflows'!$AI$4:$AL$110,3,0),"") -> 3853500 | N20: =IFERROR(VLOOKUP($C20,'[8]Total Inflows'!$AO$4:$AR$10,3,0),"") | O20: =IFERROR(VLOOKUP($C20,'[8]Total Inflows'!$AU$4:$AX$54,3,0),"") | P20: =IFERROR(VLOOKUP($C20,'[8]Total Inflows'!$AZ$4:$BC$30,3,0),"") | Q20: =IFERROR(SUM(M20:P20),"") -> 3853500 | R20: =IFERROR(VLOOKUP($C20,'[9]Total Inflows'!$AI$4:$AL$110,4,0),"") -> 4129600 | S20: =IFERROR(VLOOKUP($C20,'[8]Total Inflows'!$AO$4:$AR$10,4,0),"") | T20: =IFERROR(VLOOKUP($C20,'[8]Total Inflows'!$AU$4:$AX$54,4,0),"") | U20: =IFERROR(VLOOKUP($C20,'[8]Total Inflows'!$AZ$4:$BC$30,4,0),"") | V20: =IFERROR(SUM(R20:U20),"") -> 4129600
B21: =IFERROR(LEFT(C21,1),"") | E21: =SUM(E16:E20) -> 48107118 | F21: =SUM(F16:F20) -> 49927600 | G21: =SUM(G16:G20) -> 48474200 | H21: =SUM(H16:H20) -> 49494400 | I21: =SUM(I16:I20) -> 0 | J21: =SUM(J16:J20) -> 0 | K21: =SUM(K16:K20) -> 0 | L21: =IFERROR(SUM(H21:K21),"") -> 49494400 | M21: =SUM(M16:M20) -> 55322800 | N21: =SUM(N16:N20) -> 0 | O21: =SUM(O16:O20) -> 0 | P21: =SUM(P16:P20) -> 0 | Q21: =IFERROR(SUM(M21:P21),"") -> 55322800 | R21: =SUM(R16:R20) -> 58286900 | S21: =SUM(S16:S20) -> 0 | T21: =SUM(T16:T20) -> 0 | U21: =SUM(U16:U20) -> 0 | V21: =IFERROR(SUM(R21:U21),"") -> 58286900
B22: =IFERROR(LEFT(C22,1),"") | E22: =IFERROR(SUM(#REF!),"")
B23: =IFERROR(LEFT(C23,1),"") | E23: =IFERROR(SUM(#REF!),"")
A24: 1113 | B24: =IFERROR(LEFT(C24,1),"") | D24: Unallocable taxes on income, profits, and capital gains | E24: =IFERROR(SUM(#REF!),"")
B25: =IFERROR(LEFT(C25,1),"") | E25: =IFERROR(SUM(#REF!),"")
B26: =IFERROR(LEFT(C26,1),"") | E26: =IFERROR(SUM(#REF!),"")
A27: 112 | B27: =IFERROR(LEFT(C27,1),"") | D27: Taxes on payroll and workforce | E27: =IFERROR(SUM(#REF!),"")
B28: =IFERROR(LEFT(C28,1),"") | E28: =IFERROR(SUM(#REF!),"")
B29: =IFERROR(LEFT(C29,1),"") | E29: =IFERROR(SUM(#REF!),"")
A30: 113 | B30: =IFERROR(LEFT(C30,1),"") | D30: Taxes on property | E30: =SUM(E35,E38,E41,E44,E47,E50) -> 345427.41 | F30: =SUM(F35,F38,F41,F44,F47,F50) -> 392100 | G30: =SUM(G35,G38,G41,G44,G47,G50) -> 402900 | H30: =SUM(H35,H38,H41,H44,H47,H50) -> 1630500 | I30: =SUM(I35,I38,I41,I44,I47,I50) -> 0 | J30: =SUM(J35,J38,J41,J44,J47,J50) -> 0 | K30: =SUM(K35,K38,K41,K44,K47,K50) -> 0 | L30: =IFERROR(SUM(H30:K30),"") -> 1630500 | M30: =SUM(M35,M38,M41,M44,M47,M50) -> 1659800 | N30: =SUM(N35,N38,N41,N44,N47,N50) -> 0 | O30: =SUM(O35,O38,O41,O44,O47,O50) -> 0 | P30: =SUM(P35,P38,P41,P44,P47,P50) -> 0 | Q30: =IFERROR(SUM(M30:P30),"") -> 1659800 | R30: =SUM(R35,R38,R41,R44,R47,R50) -> 1692700 | S30: =SUM(S35,S38,S41,S44,S47,S50) -> 0 | T30: =SUM(T35,T38,T41,T44,T47,T50) -> 0 | U30: =SUM(U35,U38,U41,U44,U47,U50) -> 0 | V30: =IFERROR(SUM(R30:U30),"") -> 1692700
A31: 1131 | B31: =IFERROR(LEFT(C31,1),"") | D31: Recurrent taxes on immovable property | E31: =IFERROR(SUM(#REF!),"")
A32: 1131 | B32: =IFERROR(LEFT(C32,1),"") -> 0 | C32: 0469 | D32: Poundage Land Rental | E32: =IFERROR(VLOOKUP($C32,'[8]Total Inflows'!$AE$4:$AH$165,2,0),"") -> 171483.18 | F32: =IFERROR(VLOOKUP($C32,'[8]Total Inflows'!$AE$4:$AH$165,3,0),"") -> 178500 | G32: =IFERROR(VLOOKUP($C32,'[8]Total Inflows'!$AE$4:$AH$165,4,0),"") -> 197800 | H32: =IFERROR(VLOOKUP($C32,'[8]Total Inflows'!$AJ$4:$AM$110,2,0),"") -> 1411300 | I32: =IFERROR(VLOOKUP($C32,'[8]Total Inflows'!$AO$4:$AR$10,2,0),"") | J32: =IFERROR(VLOOKUP($C32,'[8]Total Inflows'!$AU$4:$AX$54,2,0),"") | K32: =IFERROR(VLOOKUP($C32,'[8]Total Inflows'!$AZ$4:$BC$30,2,0),"") | L32: =IFERROR(SUM(H32:K32),"") -> 1411300 | M32: =IFERROR(VLOOKUP($C32,'[9]Total Inflows'!$AI$4:$AL$110,3,0),"") -> 1425700 | N32: =IFERROR(VLOOKUP($C32,'[8]Total Inflows'!$AO$4:$AR$10,3,0),"") | O32: =IFERROR(VLOOKUP($C32,'[8]Total Inflows'!$AU$4:$AX$54,3,0),"") | P32: =IFERROR(VLOOKUP($C32,'[8]Total Inflows'!$AZ$4:$BC$30,3,0),"") | Q32: =IFERROR(SUM(M32:P32),"") -> 1425700 | R32: =IFERROR(VLOOKUP($C32,'[9]Total Inflows'!$AI$4:$AL$110,4,0),"") -> 1441900 | S32: =IFERROR(VLOOKUP($C32,'[8]Total Inflows'!$AO$4:$AR$10,4,0),"") | T32: =IFERROR(VLOOKUP($C32,'[8]Total Inflows'!$AU$4:$AX$54,4,0),"") | U32: =IFERROR(VLOOKUP($C32,'[8]Total Inflows'!$AZ$4:$BC$30,4,0),"") | V32: =IFERROR(SUM(R32:U32),"") -> 1441900
A33: 1131 | B33: =IFERROR(LEFT(C33,1),"") -> 0 | C33: 0470 | D33: Rent on Tax Allotment | E33: =IFERROR(VLOOKUP($C33,'[8]Total Inflows'!$AE$4:$AH$165,2,0),"") -> 3939.23 | F33: =IFERROR(VLOOKUP($C33,'[8]Total Inflows'!$AE$4:$AH$165,3,0),"") -> 2200 | G33: =IFERROR(VLOOKUP($C33,'[8]Total Inflows'!$AE$4:$AH$165,4,0),"") -> 6200 | H33: =IFERROR(VLOOKUP($C33,'[8]Total Inflows'!$AJ$4:$AM$110,2,0),"") -> 6700 | I33: =IFERROR(VLOOKUP($C33,'[8]Total Inflows'!$AO$4:$AR$10,2,0),"") | J33: =IFERROR(VLOOKUP($C33,'[8]Total Inflows'!$AU$4:$AX$54,2,0),"") | K33: =IFERROR(VLOOKUP($C33,'[8]Total Inflows'!$AZ$4:$BC$30,2,0),"") | L33: =IFERROR(SUM(H33:K33),"") -> 6700 | M33: =IFERROR(VLOOKUP($C33,'[9]Total Inflows'!$AI$4:$AL$110,3,0),"") -> 7100 | N33: =IFERROR(VLOOKUP($C33,'[8]Total Inflows'!$AO$4:$AR$10,3,0),"") | O33: =IFERROR(VLOOKUP($C33,'[8]Total Inflows'!$AU$4:$AX$54,3,0),"") | P33: =IFERROR(VLOOKUP($C33,'[8]Total Inflows'!$AZ$4:$BC$30,3,0),"") | Q33: =IFERROR(SUM(M33:P33),"") -> 7100 | R33: =IFERROR(VLOOKUP($C33,'[9]Total Inflows'!$AI$4:$AL$110,4,0),"") -> 7600 | S33: =IFERROR(VLOOKUP($C33,'[8]Total Inflows'!$AO$4:$AR$10,4,0),"") | T33: =IFERROR(VLOOKUP($C33,'[8]Total Inflows'!$AU$4:$AX$54,4,0),"") | U33: =IFERROR(VLOOKUP($C33,'[8]Total Inflows'!$AZ$4:$BC$30,4,0),"") | V33: =IFERROR(SUM(R33:U33),"") -> 7600
A34: 1131 | B34: =IFERROR(LEFT(C34,1),"") -> 0 | C34: 0481 | D34: Industrial Properties Registration | E34: =IFERROR(VLOOKUP($C34,'[8]Total Inflows'!$AE$4:$AH$165,2,0),"") -> 170005 | F34: =IFERROR(VLOOKUP($C34,'[8]Total Inflows'!$AE$4:$AH$165,3,0),"") -> 211400 | G34: =IFERROR(VLOOKUP($C34,'[8]Total Inflows'!$AE$4:$AH$165,4,0),"") -> 198900 | H34: =IFERROR(VLOOKUP($C34,'[8]Total Inflows'!$AJ$4:$AM$110,2,0),"") -> 212500 | I34: =IFERROR(VLOOKUP($C34,'[8]Total Inflows'!$AO$4:$AR$10,2,0),"") | J34: =IFERROR(VLOOKUP($C34,'[8]Total Inflows'!$AU$4:$AX$54,2,0),"") | K34: =IFERROR(VLOOKUP($C34,'[8]Total Inflows'!$AZ$4:$BC$30,2,0),"") | L34: =IFERROR(SUM(H34:K34),"") -> 212500 | M34: =IFERROR(VLOOKUP($C34,'[9]Total Inflows'!$AI$4:$AL$110,3,0),"") -> 227000 | N34: =IFERROR(VLOOKUP($C34,'[8]Total Inflows'!$AO$4:$AR$10,3,0),"") | O34: =IFERROR(VLOOKUP($C34,'[8]Total Inflows'!$AU$4:$AX$54,3,0),"") | P34: =IFERROR(VLOOKUP($C34,'[8]Total Inflows'!$AZ$4:$BC$30,3,0),"") | Q34: =IFERROR(SUM(M34:P34),"") -> 227000 | R34: =IFERROR(VLOOKUP($C34,'[9]Total Inflows'!$AI$4:$AL$110,4,0),"") -> 243200 | S34: =IFERROR(VLOOKUP($C34,'[8]Total Inflows'!$AO$4:$AR$10,4,0),"") | T34: =IFERROR(VLOOKUP($C34,'[8]Total Inflows'!$AU$4:$AX$54,4,0),"") | U34: =IFERROR(VLOOKUP($C34,'[8]Total Inflows'!$AZ$4:$BC$30,4,0),"") | V34: =IFERROR(SUM(R34:U34),"") -> 243200
B35: =IFERROR(LEFT(C35,1),"") | E35: =SUM(E32:E34) -> 345427.41 | F35: =SUM(F32:F34) -> 392100 | G35: =SUM(G32:G34) -> 402900 | H35: =SUM(H32:H34) -> 1630500 | I35: =SUM(I32:I34) -> 0 | J35: =SUM(J32:J34) -> 0 | K35: =SUM(K32:K34) -> 0 | L35: =IFERROR(SUM(H35:K35),"") -> 1630500 | M35: =SUM(M32:M34) -> 1659800 | N35: =SUM(N32:N34) -> 0 | O35: =SUM(O32:O34) -> 0 | P35: =SUM(P32:P34) -> 0 | Q35: =IFERROR(SUM(M35:P35),"") -> 1659800 | R35: =SUM(R32:R34) -> 1692700 | S35: =SUM(S32:S34) -> 0 | T35: =SUM(T32:T34) -> 0 | U35: =SUM(U32:U34) -> 0 | V35: =IFERROR(SUM(R35:U35),"") -> 1692700
B36: =IFERROR(LEFT(C36,1),"") | E36: =IFERROR(SUM(#REF!),"")
B37: =IFERROR(LEFT(C37,1),"") | E37: =IFERROR(SUM(#REF!),"")
A38: 1132 | B38: =IFERROR(LEFT(C38,1),"") | D38: Recurrent taxes on net wealth | E38: =IFERROR(SUM(#REF!),"")
B39: =IFERROR(LEFT(C39,1),"") | E39: =IFERROR(SUM(#REF!),"")
B40: =IFERROR(LEFT(C40,1),"") | E40: =IFERROR(SUM(#REF!),"")
...

Sheet Ls_AgXLB_WorkbookFile

Sheet Sheet2
B4: 1712 | C4: Public Debt Principal Repayment Domestic | D4: 13566000 | E4: 19872000 | F4: 15100000
C6: Budget | D6: 15.5 | E6: 21.8 | F6: 17

Sheet Sum_Bud_data
B3: Actual 2018/19 | C3: Budget Estimate 2019/20 | D3: Est Outturn 2019/20 | E3: Budget Estimate 2019/20 | F3: Budget Estimate 2020/21 | G3: Budget Estimate 2021/22 | M3: Total Receipts (TR)
M4: Total Payments (TP)
A5: Revenue | B5: =B6+B11 -> #REF! | C5: =C6+C11 -> #REF! | D5: =D6+D11 -> #REF! | E5: =E6+E11 -> #REF! | F5: =F6+F11 -> #REF! | G5: =G6+G11 -> #REF! | M5: Receipts less Payments
A6: Taxes | B6: =B7+#REF! -> #REF! | C6: =C7+#REF! -> #REF! | D6: =D7+#REF! -> #REF! | E6: =E7+#REF! -> #REF! | F6: =F7+#REF! -> #REF! | G6: =G7+#REF! -> #REF! | M6: TR+TP
A7: Current revenue | B7: =B8+#REF! -> #REF! | C7: =C8+#REF! -> #REF! | D7: =D8+#REF! -> #REF! | E7: =E8+#REF! -> #REF! | F7: =F8+#REF! -> #REF! | G7: =G8+#REF! -> #REF!
A8: Tax revenue | B8: ='[18]Revenue T3'!G6 -> 116.24163 | C8: ='[18]Revenue T3'!H6 -> 112.65597 | D8: ='[18]Revenue T3'!I6 -> 115.0186 | E8: ='[18]Revenue T3'!M6 -> 115.8743 | F8: ='[18]Revenue T3'!N6 -> 118.35372 | G8: ='[18]Revenue T3'!O6 -> 118.3537
A9: Trade taxes | B9: ='[18]Revenue T3'!G12 -> 14.935478 | C9: ='[18]Revenue T3'!H12 -> 14.579595 | D9: ='[18]Revenue T3'!I12 -> 13.179244 | E9: ='[18]Revenue T3'!M12 -> 12.72232 | F9: ='[18]Revenue T3'!N12 -> 12.918094 | G9: ='[18]Revenue T3'!O12 -> 12.918091 | J9: GFSM 2001 Code | L9: Item Code | M9: GFSM2014 | N9: Actual FY2025 | O9: ='GFS 2025_26 Budget'!F1 -> Budget Estimate 2025/26 | P9: Budget Outturn FY2026 | Q9: Budget Statement 2026/27 (Recurrent) | R9: Budget Statement 2026/27 (Budget Support) | S9: Budget Statement 2026/27 (Development Cash) | T9: Budget Statement 2026/27 (In-kind) | U9: Budget Estimate 2026/27 | V9: Budget Statement 2027/28 (Recurrent) | W9: Budget Statement 2027/28 (Budget Support) | X9: Budget Statement 2027/28 (Development Cash) | Y9: Budget Statement 2027/28 (In-kind) | Z9: Budget Estimate 2027/28 | AA9: Budget Statement 2028/29 (Recurrent) | AB9: Budget Statement 2028/29 (Budget Support) | AC9: Budget Statement 2028/29 (Development Cash) | AD9: Budget Statement 2028/29 (In-kind) | AE9: Budget Estimate 2028/29
J10: 1 | M10: REVENUE | N10: =SUM(N11,N20,N21,N31) -> 810.96293 | O10: =SUM(O11,O20,O21,O31) -> 929.7561 | P10: =SUM(P11,P20,P21,P31) -> 791.3569 | Q10: =SUM(Q11,Q20,Q21,Q31) -> 412.1464 | R10: =SUM(R11,R20,R21,R31) -> 118.0109 | S10: =SUM(S11,S20,S21,S31) -> 133.0838 | T10: =SUM(T11,T20,T21,T31) -> 214.1572 | U10: =IFERROR(SUM(Q10:T10),"") -> 877.3983 | V10: =SUM(V11,V20,V21,V31) -> 459.5129 | W10: =SUM(W11,W20,W21,W31) -> 86.953 | X10: =SUM(X11,X20,X21,X31) -> 105.8358 | Y10: =SUM(Y11,Y20,Y21,Y31) -> 233.8395 | Z10: =IFERROR(SUM(V10:Y10),"") -> 886.1412 | AA10: =SUM(AA11,AA20,AA21,AA31) -> 483.2927 | AB10: =SUM(AB11,AB20,AB21,AB31) -> 47.5291 | AC10: =SUM(AC11,AC20,AC21,AC31) -> 79.5046 | AD10: =SUM(AD11,AD20,AD21,AD31) -> 143.8488 | AE10: =IFERROR(SUM(AA10:AD10),"") -> 754.1752
A11: Grants (in cash) | B11: ='[18]Revenue T3'!G24 -> 39.164689 | C11: ='[18]Revenue T3'!H24 -> 60.864747 | D11: ='[18]Revenue T3'!I24 -> 47.700687 | E11: ='[18]Revenue T3'!M24 -> 53.180303 | F11: ='[18]Revenue T3'!N24 -> 42.798625 | G11: ='[18]Revenue T3'!O24 -> 42.798615 | J11: 11 | M11: Taxes | N11: =SUM(N12,N13,N14,N18,N19) -> 328.47224 | O11: =SUM(O12,O13,O14,O18,O19) -> 347.0774 | P11: =SUM(P12,P13,P14,P18,P19) -> 342.8047 | Q11: =SUM(Q12,Q13,Q14,Q18,Q19) -> 351.9146 | R11: =SUM(R12,R13,R14,R18,R19) -> 0 | S11: =SUM(S12,S13,S14,S18,S19) -> 0 | T11: =SUM(T12,T13,T14,T18,T19) -> 0 | U11: =IFERROR(SUM(Q11:T11),"") -> 351.9146 | V11: =SUM(V12,V13,V14,V18,V19) -> 394.7373 | W11: =SUM(W12,W13,W14,W18,W19) -> 0 | X11: =SUM(X12,X13,X14,X18,X19) -> 0 | Y11: =SUM(Y12,Y13,Y14,Y18,Y19) -> 0 | Z11: =IFERROR(SUM(V11:Y11),"") -> 394.7373 | AA11: =SUM(AA12,AA13,AA14,AA18,AA19) -> 414.7709 | AB11: =SUM(AB12,AB13,AB14,AB18,AB19) -> 0 | AC11: =SUM(AC12,AC13,AC14,AC18,AC19) -> 0 | AD11: =SUM(AD12,AD13,AD14,AD18,AD19) -> 0 | AE11: =IFERROR(SUM(AA11:AD11),"") -> 414.7709
J12: 111 | M12: Taxes on income, profits, n capital gains | N12: ='GFS 2025_26 Budget'!E8/10^6 -> 76.885797 | O12: ='GFS 2025_26 Budget'!F8/10^6 -> 78.6995 | P12: ='GFS 2025_26 Budget'!G8/10^6 -> 78.6632 | Q12: ='GFS 2025_26 Budget'!H8/10^6 -> 81.7512 | R12: ='GFS 2025_26 Budget'!I8/10^6 -> 0 | S12: ='GFS 2025_26 Budget'!J8/10^6 -> 0 | T12: ='GFS 2025_26 Budget'!K8/10^6 -> 0 | U12: =IFERROR(SUM(Q12:T12),"") -> 81.7512 | V12: ='GFS 2025_26 Budget'!M8/10^6 -> 89.777 | W12: ='GFS 2025_26 Budget'!N8/10^6 -> 0 | X12: ='GFS 2025_26 Budget'!O8/10^6 -> 0 | Y12: ='GFS 2025_26 Budget'!P8/10^6 -> 0 | Z12: =IFERROR(SUM(V12:Y12),"") -> 89.777 | AA12: ='GFS 2025_26 Budget'!R8/10^6 -> 94.2098 | AB12: ='GFS 2025_26 Budget'!S8/10^6 -> 0 | AC12: ='GFS 2025_26 Budget'!T8/10^6 -> 0 | AD12: ='GFS 2025_26 Budget'!U8/10^6 -> 0 | AE12: =IFERROR(SUM(AA12:AD12),"") -> 94.2098
A13: Total expenditure | B13: =B14+#REF! -> #REF! | C13: =C14+#REF! -> #REF! | D13: =D14+#REF! -> #REF! | E13: =E14+#REF! -> #REF! | F13: =F14+#REF! -> #REF! | G13: =G14+#REF! -> #REF! | J13: 113 | M13: Taxes on property | N13: ='GFS 2025_26 Budget'!E30/10^6 -> 0.34542741 | O13: ='GFS 2025_26 Budget'!F30/10^6 -> 0.3921 | P13: ='GFS 2025_26 Budget'!G30/10^6 -> 0.4029 | Q13: ='GFS 2025_26 Budget'!H30/10^6 -> 1.6305 | R13: ='GFS 2025_26 Budget'!I30/10^6 -> 0 | S13: ='GFS 2025_26 Budget'!J30/10^6 -> 0 | T13: ='GFS 2025_26 Budget'!K30/10^6 -> 0 | U13: =IFERROR(SUM(Q13:T13),"") -> 1.6305 | V13: ='GFS 2025_26 Budget'!M30/10^6 -> 1.6598 | W13: ='GFS 2025_26 Budget'!N30/10^6 -> 0 | X13: ='GFS 2025_26 Budget'!O30/10^6 -> 0 | Y13: ='GFS 2025_26 Budget'!P30/10^6 -> 0 | Z13: =IFERROR(SUM(V13:Y13),"") -> 1.6598 | AA13: ='GFS 2025_26 Budget'!R30/10^6 -> 1.6927 | AB13: ='GFS 2025_26 Budget'!S30/10^6 -> 0 | AC13: ='GFS 2025_26 Budget'!T30/10^6 -> 0 | AD13: ='GFS 2025_26 Budget'!U30/10^6 -> 0 | AE13: =IFERROR(SUM(AA13:AD13),"") -> 1.6927
A14: Current expenditure | B14: =SUM(B18:B20) -> 269.05647 | C14: =SUM(C18:C20) -> 271.55381 | D14: =SUM(D18:D20) -> 254.16626 | E14: =SUM(E18:E20) -> 270.31585 | F14: =SUM(F18:F20) -> 263.01278 | G14: =SUM(G18:G20) -> 260.08224 | J14: 114 | M14: Taxes on goods and services | N14: =SUM(N15:N17) -> 218.06865 | O14: =SUM(O15:O17) -> 228.3233 | P14: =SUM(P15:P17) -> 229.595 | Q14: =SUM(Q15:Q17) -> 235.2506 | R14: =SUM(R15:R17) -> 0 | S14: =SUM(S15:S17) -> 0 | T14: =SUM(T15:T17) -> 0 | U14: =IFERROR(SUM(Q14:T14),"") -> 235.2506 | V14: =SUM(V15:V17) -> 264.333 | W14: =SUM(W15:W17) -> 0 | X14: =SUM(X15:X17) -> 0 | Y14: =SUM(Y15:Y17) -> 0 | Z14: =IFERROR(SUM(V14:Y14),"") -> 264.333 | AA14: =SUM(AA15:AA17) -> 278.1088 | AB14: =SUM(AB15:AB17) -> 0 | AC14: =SUM(AC15:AC17) -> 0 | AD14: =SUM(AD15:AD17) -> 0 | AE14: =IFERROR(SUM(AA14:AD14),"") -> 278.1088
M15: ='GFS 2025_26 Budget'!D54 -> General taxes on goods and services | N15: ='GFS 2025_26 Budget'!E54/10^6 -> 142.93908 | O15: ='GFS 2025_26 Budget'!F54/10^6 -> 145.0368 | P15: ='GFS 2025_26 Budget'!G54/10^6 -> 152.0117 | Q15: ='GFS 2025_26 Budget'!H54/10^6 -> 160.8533 | R15: ='GFS 2025_26 Budget'!I54/10^6 -> 0 | S15: ='GFS 2025_26 Budget'!J54/10^6 -> 0 | T15: ='GFS 2025_26 Budget'!K54/10^6 -> 0 | U15: =IFERROR(SUM(Q15:T15),"") -> 160.8533 | V15: ='GFS 2025_26 Budget'!M54/10^6 -> 175.2889 | W15: ='GFS 2025_26 Budget'!N54/10^6 -> 0 | X15: ='GFS 2025_26 Budget'!O54/10^6 -> 0 | Y15: ='GFS 2025_26 Budget'!P54/10^6 -> 0 | Z15: =IFERROR(SUM(V15:Y15),"") -> 175.2889 | AA15: ='GFS 2025_26 Budget'!R54/10^6 -> 184.7199 | AB15: ='GFS 2025_26 Budget'!S54/10^6 -> 0 | AC15: ='GFS 2025_26 Budget'!T54/10^6 -> 0 | AD15: ='GFS 2025_26 Budget'!U54/10^6 -> 0 | AE15: =IFERROR(SUM(AA15:AD15),"") -> 184.7199
M16: ='GFS 2025_26 Budget'!D67 -> Excises | N16: ='GFS 2025_26 Budget'!E71/10^6 -> 67.725569 | O16: ='GFS 2025_26 Budget'!F71/10^6 -> 71.1154 | P16: ='GFS 2025_26 Budget'!G71/10^6 -> 69.5871 | Q16: ='GFS 2025_26 Budget'!H71/10^6 -> 65.3534 | R16: ='GFS 2025_26 Budget'!I71/10^6 -> 0 | S16: ='GFS 2025_26 Budget'!J71/10^6 -> 0 | T16: ='GFS 2025_26 Budget'!K71/10^6 -> 0 | U16: =IFERROR(SUM(Q16:T16),"") -> 65.3534 | V16: ='GFS 2025_26 Budget'!M71/10^6 -> 79.4185 | W16: ='GFS 2025_26 Budget'!N71/10^6 -> 0 | X16: ='GFS 2025_26 Budget'!O71/10^6 -> 0 | Y16: ='GFS 2025_26 Budget'!P71/10^6 -> 0 | Z16: =IFERROR(SUM(V16:Y16),"") -> 79.4185 | AA16: ='GFS 2025_26 Budget'!R71/10^6 -> 83.1092 | AB16: ='GFS 2025_26 Budget'!S71/10^6 -> 0 | AC16: ='GFS 2025_26 Budget'!T71/10^6 -> 0 | AD16: ='GFS 2025_26 Budget'!U71/10^6 -> 0 | AE16: =IFERROR(SUM(AA16:AD16),"") -> 83.1092
M17: ='GFS 2025_26 Budget'!D79 -> Taxes on use of goods and on permission to use goods or perform activities | N17: ='GFS 2025_26 Budget'!E79/10^6 -> 7.4040075 | O17: ='GFS 2025_26 Budget'!F79/10^6 -> 12.1711 | P17: ='GFS 2025_26 Budget'!G79/10^6 -> 7.9962 | Q17: ='GFS 2025_26 Budget'!H79/10^6 -> 9.0439 | R17: ='GFS 2025_26 Budget'!I79/10^6 -> 0 | S17: ='GFS 2025_26 Budget'!J79/10^6 -> 0 | T17: ='GFS 2025_26 Budget'!K79/10^6 -> 0 | U17: =IFERROR(SUM(Q17:T17),"") -> 9.0439 | V17: ='GFS 2025_26 Budget'!M79/10^6 -> 9.6256 | W17: ='GFS 2025_26 Budget'!N79/10^6 -> 0 | X17: ='GFS 2025_26 Budget'!O79/10^6 -> 0 | Y17: ='GFS 2025_26 Budget'!P79/10^6 -> 0 | Z17: =IFERROR(SUM(V17:Y17),"") -> 9.6256 | AA17: ='GFS 2025_26 Budget'!R79/10^6 -> 10.2797 | AB17: ='GFS 2025_26 Budget'!S79/10^6 -> 0 | AC17: ='GFS 2025_26 Budget'!T79/10^6 -> 0 | AD17: ='GFS 2025_26 Budget'!U79/10^6 -> 0 | AE17: =IFERROR(SUM(AA17:AD17),"") -> 10.2797
A18: Wages and salaries | B18: ='[18]Expenditure T13'!G6 -> 82.731045 | C18: ='[18]Expenditure T13'!H6 -> 81.694613 | D18: ='[18]Expenditure T13'!I6 -> 85.748415 | E18: ='[18]Expenditure T13'!L6 -> 85.487247 | F18: ='[18]Expenditure T13'!M6 -> 85.212324 | G18: ='[18]Expenditure T13'!N6 -> 85.21863 | J18: 115 | M18: Taxes on international trade n transactions | N18: ='GFS 2025_26 Budget'!E111/10^6 -> 33.172365 | O18: ='GFS 2025_26 Budget'!F111/10^6 -> 39.6625 | P18: ='GFS 2025_26 Budget'!G111/10^6 -> 34.1436 | Q18: ='GFS 2025_26 Budget'!H111/10^6 -> 33.2823 | R18: ='GFS 2025_26 Budget'!I111/10^6 -> 0 | S18: ='GFS 2025_26 Budget'!J111/10^6 -> 0 | T18: ='GFS 2025_26 Budget'!K111/10^6 -> 0 | U18: =IFERROR(SUM(Q18:T18),"") -> 33.2823 | V18: ='GFS 2025_26 Budget'!M111/10^6 -> 38.9675 | W18: ='GFS 2025_26 Budget'!N111/10^6 -> 0 | X18: ='GFS 2025_26 Budget'!O111/10^6 -> 0 | Y18: ='GFS 2025_26 Budget'!P111/10^6 -> 0 | Z18: =IFERROR(SUM(V18:Y18),"") -> 38.9675 | AA18: ='GFS 2025_26 Budget'!R111/10^6 -> 40.7596 | AB18: ='GFS 2025_26 Budget'!S111/10^6 -> 0 | AC18: ='GFS 2025_26 Budget'!T111/10^6 -> 0 | AD18: ='GFS 2025_26 Budget'!U111/10^6 -> 0 | AE18: =IFERROR(SUM(AA18:AD18),"") -> 40.7596
A19: Other expenditures | B19: ='[18]Expenditure T13'!G5-'[18]Expenditure T13'!G6 -> 101.1068 | C19: ='[18]Expenditure T13'!H5-'[18]Expenditure T13'!H6 -> 104.64057 | D19: ='[18]Expenditure T13'!I5-'[18]Expenditure T13'!I6 -> 83.199216 | E19: ='[18]Expenditure T13'!L5-'[18]Expenditure T13'!L6 -> 99.609972 | F19: ='[18]Expenditure T13'!M5-'[18]Expenditure T13'!M6 -> 92.581832 | G19: ='[18]Expenditure T13'!N5-'[18]Expenditure T13'!N6 -> 89.64498 | J19: 116 | M19: Other taxes | N19: ='GFS 2025_26 Budget'!E133 -> 0 | O19: ='GFS 2025_26 Budget'!F133 -> 0 | P19: ='GFS 2025_26 Budget'!G133 -> 0 | Q19: ='GFS 2025_26 Budget'!H133 -> 0 | R19: ='GFS 2025_26 Budget'!I133 -> 0 | S19: ='GFS 2025_26 Budget'!J133 -> 0 | T19: ='GFS 2025_26 Budget'!K133 -> 0 | U19: =IFERROR(SUM(Q19:T19),"") -> 0 | V19: ='GFS 2025_26 Budget'!M133 -> 0 | W19: ='GFS 2025_26 Budget'!N133 -> 0 | X19: ='GFS 2025_26 Budget'!O133 -> 0 | Y19: ='GFS 2025_26 Budget'!P133 -> 0 | Z19: =IFERROR(SUM(V19:Y19),"") -> 0 | AA19: ='GFS 2025_26 Budget'!R133 -> 0 | AB19: ='GFS 2025_26 Budget'!S133 -> 0 | AC19: ='GFS 2025_26 Budget'!T133 -> 0 | AD19: ='GFS 2025_26 Budget'!U133 -> 0 | AE19: =IFERROR(SUM(AA19:AD19),"") -> 0
A20: Additional expenditures | B20: ='[18]Expenditure T13'!G10 -> 85.218628 | C20: ='[18]Expenditure T13'!H10 -> 85.218628 | D20: ='[18]Expenditure T13'!I10 -> 85.218628 | E20: ='[18]Expenditure T13'!L10 -> 85.218628 | F20: ='[18]Expenditure T13'!M10 -> 85.218628 | G20: ='[18]Expenditure T13'!N10 -> 85.218628 | J20: 12 | M20: Social contributions [GFS] | N20: ='GFS 2025_26 Budget'!E139/10^6 -> 0 | O20: ='GFS 2025_26 Budget'!F139/10^6 -> 0 | P20: ='GFS 2025_26 Budget'!G139/10^6 -> 0 | Q20: ='GFS 2025_26 Budget'!H139/10^6 -> 0 | R20: ='GFS 2025_26 Budget'!I139/10^6 -> 0 | S20: ='GFS 2025_26 Budget'!J139/10^6 -> 0 | T20: ='GFS 2025_26 Budget'!K139/10^6 -> 0 | U20: =IFERROR(SUM(Q20:T20),"") -> 0 | V20: ='GFS 2025_26 Budget'!M139/10^6 -> 0 | W20: ='GFS 2025_26 Budget'!N139/10^6 -> 0 | X20: ='GFS 2025_26 Budget'!O139/10^6 -> 0 | Y20: ='GFS 2025_26 Budget'!P139/10^6 -> 0 | Z20: =IFERROR(SUM(V20:Y20),"") -> 0 | AA20: ='GFS 2025_26 Budget'!R139/10^6 -> 0 | AB20: ='GFS 2025_26 Budget'!S139/10^6 -> 0 | AC20: ='GFS 2025_26 Budget'!T139/10^6 -> 0 | AD20: ='GFS 2025_26 Budget'!U139/10^6 -> 0 | AE20: =IFERROR(SUM(AA20:AD20),"") -> 0
J21: 13 | M21: Grants | N21: =SUM(N24,N27,N30) -> 426.62162 | O21: =SUM(O24,O27,O30) -> 509.2681 | P21: =SUM(P24,P27,P30) -> 386.8363 | Q21: =SUM(Q24,Q27,Q30) -> 0 | R21: =SUM(R24,R27,R30) -> 118.0109 | S21: =SUM(S24,S27,S30) -> 133.0793 | T21: =SUM(T24,T27,T30) -> 212.6572 | U21: =IFERROR(SUM(Q21:T21),"") -> 463.7474 | V21: =SUM(V24,V27,V30) -> 0 | W21: =SUM(W24,W27,W30) -> 86.953 | X21: =SUM(X24,X27,X30) -> 105.8357 | Y21: =SUM(Y24,Y27,Y30) -> 232.3395 | Z21: =IFERROR(SUM(V21:Y21),"") -> 425.1282 | AA21: =SUM(AA24,AA27,AA30) -> 0 | AB21: =SUM(AB24,AB27,AB30) -> 47.5291 | AC21: =SUM(AC24,AC27,AC30) -> 79.5045 | AD21: =SUM(AD24,AD27,AD30) -> 142.3488 | AE21: =IFERROR(SUM(AA21:AD21),"") -> 269.3824
M22: Current | N22: =ROUND(SUM('GFS 2025_26 Budget'!E167,'GFS 2025_26 Budget'!E212)/10^6,1) -> 91.6 | O22: =ROUND(SUM('GFS 2025_26 Budget'!F167,'GFS 2025_26 Budget'!F212)/10^6,1) -> 120.2 | P22: =ROUND(SUM('GFS 2025_26 Budget'!G167,'GFS 2025_26 Budget'!G212)/10^6,1) -> 109.5 | Q22: =ROUND(SUM('GFS 2025_26 Budget'!H167,'GFS 2025_26 Budget'!H212)/10^6,1) -> 0 | R22: =ROUND(SUM('GFS 2025_26 Budget'!I167,'GFS 2025_26 Budget'!I212)/10^6,1) -> 115 | S22: =ROUND(SUM('GFS 2025_26 Budget'!J167,'GFS 2025_26 Budget'!J212)/10^6,1) -> 0 | T22: =ROUND(SUM('GFS 2025_26 Budget'!K167,'GFS 2025_26 Budget'!K212)/10^6,1) -> 0 | U22: =IFERROR(SUM(Q22:T22),"") -> 115 | V22: =ROUND(SUM('GFS 2025_26 Budget'!M167,'GFS 2025_26 Budget'!M212)/10^6,1) -> 0 | W22: =ROUND(SUM('GFS 2025_26 Budget'!N167,'GFS 2025_26 Budget'!N212)/10^6,1) -> 84 | X22: =ROUND(SUM('GFS 2025_26 Budget'!O167,'GFS 2025_26 Budget'!O212)/10^6,1) -> 0 | Y22: =ROUND(SUM('GFS 2025_26 Budget'!P167,'GFS 2025_26 Budget'!P212)/10^6,1) -> 0 | Z22: =IFERROR(SUM(V22:Y22),"") -> 84 | AA22: =ROUND(SUM('GFS 2025_26 Budget'!R167,'GFS 2025_26 Budget'!R212)/10^6,1) -> 0 | AB22: =ROUND(SUM('GFS 2025_26 Budget'!S167,'GFS 2025_26 Budget'!S212)/10^6,1) -> 44.5 | AC22: =ROUND(SUM('GFS 2025_26 Budget'!T167,'GFS 2025_26 Budget'!T212)/10^6,1) -> 0 | AD22: =ROUND(SUM('GFS 2025_26 Budget'!U167,'GFS 2025_26 Budget'!U212)/10^6,1) -> 0 | AE22: =IFERROR(SUM(AA22:AD22),"") -> 44.5
M23: Capital | N23: =ROUND(SUM('GFS 2025_26 Budget'!E203,'GFS 2025_26 Budget'!E257)/10^6,1) -> 335 | O23: =ROUND(SUM('GFS 2025_26 Budget'!F203,'GFS 2025_26 Budget'!F257)/10^6,1) -> 389 | P23: =ROUND(SUM('GFS 2025_26 Budget'!G203,'GFS 2025_26 Budget'!G257)/10^6,1) -> 277.3 | Q23: =ROUND(SUM('GFS 2025_26 Budget'!H203,'GFS 2025_26 Budget'!H257)/10^6,1) -> 0 | R23: =ROUND(SUM('GFS 2025_26 Budget'!I203,'GFS 2025_26 Budget'!I257)/10^6,1) -> 3 | S23: =ROUND(SUM('GFS 2025_26 Budget'!J203,'GFS 2025_26 Budget'!J257)/10^6,1) -> 133.1 | T23: =ROUND(SUM('GFS 2025_26 Budget'!K203,'GFS 2025_26 Budget'!K257)/10^6,1) -> 212.7 | U23: =IFERROR(SUM(Q23:T23),"") -> 348.8 | V23: =ROUND(SUM('GFS 2025_26 Budget'!M203,'GFS 2025_26 Budget'!M257)/10^6,1) -> 0 | W23: =ROUND(SUM('GFS 2025_26 Budget'!N203,'GFS 2025_26 Budget'!N257)/10^6,1) -> 3 | X23: =ROUND(SUM('GFS 2025_26 Budget'!O203,'GFS 2025_26 Budget'!O257)/10^6,1) -> 105.8 | Y23: =ROUND(SUM('GFS 2025_26 Budget'!P203,'GFS 2025_26 Budget'!P257)/10^6,1) -> 232.3 | Z23: =IFERROR(SUM(V23:Y23),"") -> 341.1 | AA23: =ROUND(SUM('GFS 2025_26 Budget'!R203,'GFS 2025_26 Budget'!R257)/10^6,1) -> 0 | AB23: =ROUND(SUM('GFS 2025_26 Budget'!S203,'GFS 2025_26 Budget'!S257)/10^6,1) -> 3 | AC23: =ROUND(SUM('GFS 2025_26 Budget'!T203,'GFS 2025_26 Budget'!T257)/10^6,1) -> 79.5 | AD23: =ROUND(SUM('GFS 2025_26 Budget'!U203,'GFS 2025_26 Budget'!U257)/10^6,1) -> 142.3 | AE23: =IFERROR(SUM(AA23:AD23),"") -> 224.8
A24: Overall deficit/surplus | B24: =B5-#REF! -> #REF! | C24: =C5-#REF! -> #REF! | D24: =D5-#REF! -> #REF! | E24: =E5-#REF! -> #REF! | F24: =F5-#REF! -> #REF! | G24: =G5-#REF! -> #REF! | J24: 131 | M24: From foreign governments | N24: ='GFS 2025_26 Budget'!E157/10^6 -> 234.76038 | O24: ='GFS 2025_26 Budget'!F157/10^6 -> 289.2048 | P24: ='GFS 2025_26 Budget'!G157/10^6 -> 204.0416 | Q24: ='GFS 2025_26 Budget'!H157/10^6 -> 0 | R24: ='GFS 2025_26 Budget'!I157/10^6 -> 65.7721 | S24: ='GFS 2025_26 Budget'!J157/10^6 -> 44.66 | T24: ='GFS 2025_26 Budget'!K157/10^6 -> 89.21 | U24: =IFERROR(SUM(Q24:T24),"") -> 199.6421 | V24: ='GFS 2025_26 Budget'!M157/10^6 -> 0 | W24: ='GFS 2025_26 Budget'!N157/10^6 -> 57.2226 | X24: ='GFS 2025_26 Budget'!O157/10^6 -> 16.9615 | Y24: ='GFS 2025_26 Budget'!P157/10^6 -> 102.851 | Z24: =IFERROR(SUM(V24:Y24),"") -> 177.0351 | AA24: ='GFS 2025_26 Budget'!R157/10^6 -> 0 | AB24: ='GFS 2025_26 Budget'!S157/10^6 -> 17.7987 | AC24: ='GFS 2025_26 Budget'!T157/10^6 -> 16.2655 | AD24: ='GFS 2025_26 Budget'!U157/10^6 -> 79.6583 | AE24: =IFERROR(SUM(AA24:AD24),"") -> 113.7225
M25: current | N25: ='GFS 2025_26 Budget'!E167/10^6 -> 59.687538 | O25: ='GFS 2025_26 Budget'!F167/10^6 -> 81.6734 | P25: ='GFS 2025_26 Budget'!G167/10^6 -> 82.2195 | Q25: ='GFS 2025_26 Budget'!H167/10^6 -> 0 | R25: ='GFS 2025_26 Budget'!I167/10^6 -> 65.7721 | S25: ='GFS 2025_26 Budget'!J167/10^6 -> 0 | T25: ='GFS 2025_26 Budget'!K167/10^6 -> 0 | U25: =IFERROR(SUM(Q25:T25),"") -> 65.7721 | V25: ='GFS 2025_26 Budget'!M167/10^6 -> 0 | W25: ='GFS 2025_26 Budget'!N167/10^6 -> 57.2226 | X25: ='GFS 2025_26 Budget'!O167/10^6 -> 0 | Y25: ='GFS 2025_26 Budget'!P167/10^6 -> 0 | Z25: =IFERROR(SUM(V25:Y25),"") -> 57.2226 | AA25: ='GFS 2025_26 Budget'!R167/10^6 -> 0 | AB25: ='GFS 2025_26 Budget'!S167/10^6 -> 17.7987 | AC25: ='GFS 2025_26 Budget'!T167/10^6 -> 0 | AD25: ='GFS 2025_26 Budget'!U167/10^6 -> 0 | AE25: =IFERROR(SUM(AA25:AD25),"") -> 17.7987
M26: capital | N26: ='GFS 2025_26 Budget'!E203/10^6 -> 175.07284 | O26: ='GFS 2025_26 Budget'!F203/10^6 -> 207.5314 | P26: ='GFS 2025_26 Budget'!G203/10^6 -> 121.8221 | Q26: ='GFS 2025_26 Budget'!H203/10^6 -> 0 | R26: ='GFS 2025_26 Budget'!I203/10^6 -> 0 | S26: ='GFS 2025_26 Budget'!J203/10^6 -> 44.66 | T26: ='GFS 2025_26 Budget'!K203/10^6 -> 89.21 | U26: =IFERROR(SUM(Q26:T26),"") -> 133.87 | V26: ='GFS 2025_26 Budget'!M203/10^6 -> 0 | W26: ='GFS 2025_26 Budget'!N203/10^6 -> 0 | X26: ='GFS 2025_26 Budget'!O203/10^6 -> 16.9615 | Y26: ='GFS 2025_26 Budget'!P203/10^6 -> 102.851 | Z26: =IFERROR(SUM(V26:Y26),"") -> 119.8125 | AA26: ='GFS 2025_26 Budget'!R203/10^6 -> 0 | AB26: ='GFS 2025_26 Budget'!S203/10^6 -> 0 | AC26: ='GFS 2025_26 Budget'!T203/10^6 -> 16.2655 | AD26: ='GFS 2025_26 Budget'!U203/10^6 -> 79.6583 | AE26: =IFERROR(SUM(AA26:AD26),"") -> 95.9238
J27: 132 | M27: From international organizations | N27: ='GFS 2025_26 Budget'!E206/10^6 -> 191.86124 | O27: ='GFS 2025_26 Budget'!F206/10^6 -> 220.0633 | P27: ='GFS 2025_26 Budget'!G206/10^6 -> 182.7947 | Q27: ='GFS 2025_26 Budget'!H206/10^6 -> 0 | R27: ='GFS 2025_26 Budget'!I206/10^6 -> 52.2388 | S27: ='GFS 2025_26 Budget'!J206/10^6 -> 88.4193 | T27: ='GFS 2025_26 Budget'!K206/10^6 -> 123.4472 | U27: =IFERROR(SUM(Q27:T27),"") -> 264.1053 | V27: ='GFS 2025_26 Budget'!M206/10^6 -> 0 | W27: ='GFS 2025_26 Budget'!N206/10^6 -> 29.7304 | X27: ='GFS 2025_26 Budget'!O206/10^6 -> 88.8742 | Y27: ='GFS 2025_26 Budget'!P206/10^6 -> 129.4885 | Z27: =IFERROR(SUM(V27:Y27),"") -> 248.0931 | AA27: ='GFS 2025_26 Budget'!R206/10^6 -> 0 | AB27: ='GFS 2025_26 Budget'!S206/10^6 -> 29.7304 | AC27: ='GFS 2025_26 Budget'!T206/10^6 -> 63.239 | AD27: ='GFS 2025_26 Budget'!U206/10^6 -> 62.6905 | AE27: =IFERROR(SUM(AA27:AD27),"") -> 155.6599
M28: current | N28: ='GFS 2025_26 Budget'!E212/10^6 -> 31.890486 | O28: ='GFS 2025_26 Budget'!F212/10^6 -> 38.5626 | P28: ='GFS 2025_26 Budget'!G212/10^6 -> 27.3164 | Q28: ='GFS 2025_26 Budget'!H212/10^6 -> 0 | R28: ='GFS 2025_26 Budget'!I212/10^6 -> 49.2388 | S28: ='GFS 2025_26 Budget'!J212/10^6 -> 0 | T28: ='GFS 2025_26 Budget'!K212/10^6 -> 0 | U28: =IFERROR(SUM(Q28:T28),"") -> 49.2388 | V28: ='GFS 2025_26 Budget'!M212/10^6 -> 0 | W28: ='GFS 2025_26 Budget'!N212/10^6 -> 26.7304 | X28: ='GFS 2025_26 Budget'!O212/10^6 -> 0 | Y28: ='GFS 2025_26 Budget'!P212/10^6 -> 0 | Z28: =IFERROR(SUM(V28:Y28),"") -> 26.7304 | AA28: ='GFS 2025_26 Budget'!R212/10^6 -> 0 | AB28: ='GFS 2025_26 Budget'!S212/10^6 -> 26.7304 | AC28: ='GFS 2025_26 Budget'!T212/10^6 -> 0 | AD28: ='GFS 2025_26 Budget'!U212/10^6 -> 0 | AE28: =IFERROR(SUM(AA28:AD28),"") -> 26.7304
M29: capital | N29: ='GFS 2025_26 Budget'!E257/10^6 -> 159.97075 | O29: ='GFS 2025_26 Budget'!F257/10^6 -> 181.5007 | P29: ='GFS 2025_26 Budget'!G257/10^6 -> 155.4783 | Q29: ='GFS 2025_26 Budget'!H257/10^6 -> 0 | R29: ='GFS 2025_26 Budget'!I257/10^6 -> 3 | S29: ='GFS 2025_26 Budget'!J257/10^6 -> 88.4193 | T29: ='GFS 2025_26 Budget'!K257/10^6 -> 123.4472 | U29: =IFERROR(SUM(Q29:T29),"") -> 214.8665 | V29: ='GFS 2025_26 Budget'!M257/10^6 -> 0 | W29: ='GFS 2025_26 Budget'!N257/10^6 -> 3 | X29: ='GFS 2025_26 Budget'!O257/10^6 -> 88.8742 | Y29: ='GFS 2025_26 Budget'!P257/10^6 -> 129.4885 | Z29: =IFERROR(SUM(V29:Y29),"") -> 221.3627 | AA29: ='GFS 2025_26 Budget'!R257/10^6 -> 0 | AB29: ='GFS 2025_26 Budget'!S257/10^6 -> 3 | AC29: ='GFS 2025_26 Budget'!T257/10^6 -> 63.239 | AD29: ='GFS 2025_26 Budget'!U257/10^6 -> 62.6905 | AE29: =IFERROR(SUM(AA29:AD29),"") -> 128.9295
J30: 133 | M30: From other general government units | N30: ='GFS 2025_26 Budget'!E259 | O30: ='GFS 2025_26 Budget'!F259 -> 0 | P30: ='GFS 2025_26 Budget'!G259 -> 0 | Q30: ='GFS 2025_26 Budget'!H259 -> 0 | R30: ='GFS 2025_26 Budget'!I259 -> 0 | S30: ='GFS 2025_26 Budget'!J259 -> 0 | T30: ='GFS 2025_26 Budget'!K259 -> 0 | U30: =IFERROR(SUM(Q30:T30),"") -> 0 | V30: ='GFS 2025_26 Budget'!M259 -> 0 | W30: ='GFS 2025_26 Budget'!N259 -> 0 | X30: ='GFS 2025_26 Budget'!O259 -> 0 | Y30: ='GFS 2025_26 Budget'!P259 -> 0 | Z30: =IFERROR(SUM(V30:Y30),"") -> 0 | AA30: ='GFS 2025_26 Budget'!R259 -> 0 | AB30: ='GFS 2025_26 Budget'!S259 -> 0 | AC30: ='GFS 2025_26 Budget'!T259 -> 0 | AD30: ='GFS 2025_26 Budget'!U259 -> 0 | AE30: =IFERROR(SUM(AA30:AD30),"") -> 0 | AN30: FY2019 Est Outturn | AO30: Budget Estimate 2019/20 | AP30: Actual Jul_Jan 2019/20 | AQ30: 2019/20 Total Est Outturn | AR30: 2020/21 Total Est | AS30: Budget Estimate for 2021/22 | AT30: Budget Estimates for for 2022/23
J31: 14 | M31: Other revenue | N31: =SUM(N32,N33,N34,N35) -> 55.869071 | O31: =SUM(O32,O33,O34,O35) -> 73.4106 | P31: =SUM(P32,P33,P34,P35) -> 61.7159 | Q31: =SUM(Q32,Q33,Q34,Q35) -> 60.2318 | R31: =SUM(R32,R33,R34,R35) -> 0 | S31: =SUM(S32,S33,S34,S35) -> 0.0045 | T31: =SUM(T32,T33,T34,T35) -> 1.5 | U31: =IFERROR(SUM(Q31:T31),"") -> 61.7363 | V31: =SUM(V32,V33,V34,V35) -> 64.7756 | W31: =SUM(W32,W33,W34,W35) -> 0 | X31: =SUM(X32,X33,X34,X35) -> 0.0001 | Y31: =SUM(Y32,Y33,Y34,Y35) -> 1.5 | Z31: =IFERROR(SUM(V31:Y31),"") -> 66.2757 | AA31: =SUM(AA32,AA33,AA34,AA35) -> 68.5218 | AB31: =SUM(AB32,AB33,AB34,AB35) -> 0 | AC31: =SUM(AC32,AC33,AC34,AC35) -> 0.0001 | AD31: =SUM(AD32,AD33,AD34,AD35) -> 1.5 | AE31: =IFERROR(SUM(AA31:AD31),"") -> 70.0219
A32: Total financing | B32: =0-B24 -> #REF! | C32: =0-C24 -> #REF! | D32: =0-D24 -> #REF! | E32: =0-E24 -> #REF! | F32: =0-F24 -> #REF! | G32: =0-G24 -> #REF! | J32: 141 | M32: Property income [GFS] | N32: ='GFS 2025_26 Budget'!E270/10^6 -> 35.204181 | O32: ='GFS 2025_26 Budget'!F270/10^6 -> 41.8929 | P32: ='GFS 2025_26 Budget'!G270/10^6 -> 39.4128 | Q32: ='GFS 2025_26 Budget'!H270/10^6 -> 36.0685 | R32: ='GFS 2025_26 Budget'!I270/10^6 -> 0 | S32: ='GFS 2025_26 Budget'!J270/10^6 -> 0 | T32: ='GFS 2025_26 Budget'!K270/10^6 -> 0 | U32: =IFERROR(SUM(Q32:T32),"") -> 36.0685 | V32: ='GFS 2025_26 Budget'!M270/10^6 -> 38.9881 | W32: ='GFS 2025_26 Budget'!N270/10^6 -> 0 | X32: ='GFS 2025_26 Budget'!O270/10^6 -> 0 | Y32: ='GFS 2025_26 Budget'!P270/10^6 -> 0 | Z32: =IFERROR(SUM(V32:Y32),"") -> 38.9881 | AA32: ='GFS 2025_26 Budget'!R270/10^6 -> 40.911 | AB32: ='GFS 2025_26 Budget'!S270/10^6 -> 0 | AC32: ='GFS 2025_26 Budget'!T270/10^6 -> 0 | AD32: ='GFS 2025_26 Budget'!U270/10^6 -> 0 | AE32: =IFERROR(SUM(AA32:AD32),"") -> 40.911
A33: External financing | B33: =B34-B35 -> 31.703562 | C33: =C34-C35 -> 22.319517 | D33: =D34-D35 -> -5.933052 | E33: =E34-E35 -> -6.648 | F33: =F34-F35 -> 8.70902 | G33: =G34-G35 -> 5.089983 | J33: 142 | M33: Sales of goods and services | N33: ='GFS 2025_26 Budget'!E306/10^6 -> 19.617804 | O33: ='GFS 2025_26 Budget'!F306/10^6 -> 29.9278 | P33: ='GFS 2025_26 Budget'!G306/10^6 -> 21.2942 | Q33: ='GFS 2025_26 Budget'!H306/10^6 -> 22.9853 | R33: ='GFS 2025_26 Budget'!I306/10^6 -> 0 | S33: ='GFS 2025_26 Budget'!J306/10^6 -> 0 | T33: ='GFS 2025_26 Budget'!K306/10^6 -> 0 | U33: =IFERROR(SUM(Q33:T33),"") -> 22.9853 | V33: ='GFS 2025_26 Budget'!M306/10^6 -> 24.536 | W33: ='GFS 2025_26 Budget'!N306/10^6 -> 0 | X33: ='GFS 2025_26 Budget'!O306/10^6 -> 0 | Y33: ='GFS 2025_26 Budget'!P306/10^6 -> 0 | Z33: =IFERROR(SUM(V33:Y33),"") -> 24.536 | AA33: ='GFS 2025_26 Budget'!R306/10^6 -> 26.2769 | AB33: ='GFS 2025_26 Budget'!S306/10^6 -> 0 | AC33: ='GFS 2025_26 Budget'!T306/10^6 -> 0 | AD33: ='GFS 2025_26 Budget'!U306/10^6 -> 0 | AE33: =IFERROR(SUM(AA33:AD33),"") -> 26.2769 | AM33: Compensation of Employees ($m) | AN33: 134.34065 | AO33: 162.2079 | AP33: 83.597862 | AQ33: 152.35776 | AR33: 158.7634 | AS33: 158.449 | AT33: 158.449
A34: Disbursements | B34: ='[18]Balance and Financing T1&T5'!H81 -> 36.28256 | C34: ='[18]Balance and Financing T1&T5'!I81 -> 30.15 | D34: =[18]RawGFS!L850/1000000 -> 0 | E34: =[18]RawGFS!O850/1000000 -> 0 | F34: ='[18]Balance and Financing T1&T5'!R81 -> 15.35702 | G34: ='[18]Balance and Financing T1&T5'!S81 -> 11.737983 | J34: 143 | M34: Fines, penalties, and forfeits | N34: ='GFS 2025_26 Budget'!E398/10^6 -> 0.9320862 | O34: ='GFS 2025_26 Budget'!F398/10^6 -> 0.8066 | P34: ='GFS 2025_26 Budget'!G398/10^6 -> 1.0089 | Q34: ='GFS 2025_26 Budget'!H398/10^6 -> 1.178 | R34: 0 | S34: 0 | T34: 0 | U34: =IFERROR(SUM(Q34:T34),"") -> 1.178 | V34: ='GFS 2025_26 Budget'!M398/10^6 -> 1.2515 | W34: 0 | X34: 0 | Y34: 0 | Z34: =IFERROR(SUM(V34:Y34),"") -> 1.2515 | AA34: ='GFS 2025_26 Budget'!R398/10^6 -> 1.3339 | AB34: 0 | AC34: 0 | AD34: 0 | AE34: =IFERROR(SUM(AA34:AD34),"") -> 1.3339 | AM34: Total Domestic Revenue ($m) | AN34: 271.53355 | AO34: 305.6131 | AP34: 158.21095 | AQ34: 290.15221 | AR34: 306.0364 | AS34: 306.027 | AT34: 306.0176
A35: Repayments | B35: ='[18]Balance and Financing T1&T5'!H83 -> 4.578998 | C35: ='[18]Balance and Financing T1&T5'!I83 -> 7.830483 | D35: =[18]RawGFS!L855/1000000 -> 5.933052 | E35: ='[18]Balance and Financing T1&T5'!N83 -> 6.648 | F35: ='[18]Balance and Financing T1&T5'!R83 -> 6.648 | G35: ='[18]Balance and Financing T1&T5'!S83 -> 6.648 | J35: 144 | M35: ='GFS 2025_26 Budget'!D401 -> Transfer not elswhere | N35: ='GFS 2025_26 Budget'!E401/10^6 -> 0.115 | O35: ='GFS 2025_26 Budget'!F401/10^6 -> 0.7833 | P35: ='GFS 2025_26 Budget'!G401/10^6 -> 0 | Q35: ='GFS 2025_26 Budget'!H401/10^6 -> 0 | R35: ='GFS 2025_26 Budget'!I401/10^6 -> 0 | S35: ='GFS 2025_26 Budget'!J401/10^6 -> 0.0045 | T35: ='GFS 2025_26 Budget'!K401/10^6 -> 1.5 | U35: =IFERROR(SUM(Q35:T35),"") -> 1.5045 | V35: ='GFS 2025_26 Budget'!M401/10^6 -> 0 | W35: ='GFS 2025_26 Budget'!N401/10^6 -> 0 | X35: ='GFS 2025_26 Budget'!O401/10^6 -> 0.0001 | Y35: ='GFS 2025_26 Budget'!P401/10^6 -> 1.5 | Z35: =IFERROR(SUM(V35:Y35),"") -> 1.5001 | AA35: ='GFS 2025_26 Budget'!R401/10^6 -> 0 | AB35: ='GFS 2025_26 Budget'!S401/10^6 -> 0 | AC35: ='GFS 2025_26 Budget'!T401/10^6 -> 0.0001 | AD35: ='GFS 2025_26 Budget'!U401/10^6 -> 1.5 | AE35: =IFERROR(SUM(AA35:AD35),"") -> 1.5001 | AM35: Wage Bill Fiscal anchor 53%> | AN35: =AN33/AN34 -> 0.49474791 | AO35: =AO33/AO34 -> 0.53076226 | AP35: =AP33/AP34 -> 0.52839491 | AQ35: =AQ33/AQ34 -> 0.525096 | AR35: =AR33/AR34 -> 0.51877293 | AS35: =AS33/AS34 -> 0.5177615 | AT35: =AT33/AT34 -> 0.51777741
A36: of which: Bonds | B36: ='[18]Balance and Financing T1&T5'!H86 -> 14.603 | C36: ='[18]Balance and Financing T1&T5'!I86 -> 3.36 | D36: ='[18]Balance and Financing T1&T5'!J86 -> 10.36 | E36: ='[18]Balance and Financing T1&T5'!N86 -> 3 | F36: ='[18]Balance and Financing T1&T5'!R86 -> 7.109088 | G36: ='[18]Balance and Financing T1&T5'!S86 -> 6 | AM36: Domestic revenue Fiscal anchor >23% | AN36: =AN34/#REF! -> #REF! | AQ36: =AQ34/#REF! -> #REF! | AR36: =AR34/#REF! -> #REF! | AS36: =AS34/#REF! -> #REF! | AT36: =AT34/#REF! -> #REF!
A37: Repayments | B37: ='[18]Balance and Financing T1&T5'!H87 -> 6.891255 | C37: ='[18]Balance and Financing T1&T5'!I87 -> 6.96 | D37: ='[18]Balance and Financing T1&T5'!J87 -> 10.36 | E37: ='[18]Balance and Financing T1&T5'!N87 -> 3 | F37: ='[18]Balance and Financing T1&T5'!R87 -> 3 | G37: ='[18]Balance and Financing T1&T5'!S87 -> 3 | J37: 2 | M37: EXPENSE | N37: =SUM(N38,N41,N42,N46,N49,N53,N54) -> 541.08415 | O37: =SUM(O38,O41,O42,O46,O49,O53,O54) -> 617.421 | P37: =SUM(P38,P41,P42,P46,P49,P53,P54) -> 519.7125 | Q37: =SUM(Q38,Q41,Q42,Q46,Q49,Q53,Q54) -> 368.1625 | R37: =SUM(R38,R41,R42,R46,R49,R53,R54) -> 104.4969 | S37: =SUM(S38,S41,S42,S46,S49,S53,S54) -> 76.135002 | T37: =SUM(T38,T41,T42,T46,T49,T53,T54) -> 61.035003 | U37: =IFERROR(SUM(Q37:T37),"") -> 609.82941 | V37: =SUM(V38,V41,V42,V46,V49,V53,V54) -> 385.1246 | W37: =SUM(W38,W41,W42,W46,W49,W53,W54) -> 77.239001 | X37: =SUM(X38,X41,X42,X46,X49,X53,X54) -> 48.889202 | Y37: =SUM(Y38,Y41,Y42,Y46,Y49,Y53,Y54) -> 73.115503 | Z37: =IFERROR(SUM(V37:Y37),"") -> 584.36831 | AA37: =SUM(AA38,AA41,AA42,AA46,AA49,AA53,AA54) -> 409.2277 | AB37: =SUM(AB38,AB41,AB42,AB46,AB49,AB53,AB54) -> 46.815101 | AC37: =SUM(AC38,AC41,AC42,AC46,AC49,AC53,AC54) -> 48.063302 | AD37: =SUM(AD38,AD41,AD42,AD46,AD49,AD53,AD54) -> 72.494403 | AE37: =IFERROR(SUM(AA37:AD37),"") -> 576.60051
A38: Net Changes in Government Investment / Bank Balance | B38: =((B33+#REF!)-B32) -> #REF! | C38: =((C33+#REF!)-C32) -> #REF! | D38: =((D33+#REF!)-D32) -> #REF! | E38: =((E33+#REF!)-E32) -> #REF! | F38: =((F33+#REF!)-F32) -> #REF! | G38: =((G33+#REF!)-G32) -> #REF! | J38: 21 | M38: Compensation of employees | N38: =SUM(N39,N40) -> 184.19837 | O38: =SUM(O39,O40) -> 193.8232 | P38: =SUM(P39,P40) -> 191.9193 | Q38: =SUM(Q39,Q40) -> 194.5455 | R38: =SUM(R39,R40) -> 15.5414 | S38: =SUM(S39,S40) -> 0.3666 | T38: =SUM(T39,T40) -> 0.2937 | U38: =IFERROR(SUM(Q38:T38),"") -> 210.7472 | V38: =SUM(V39,V40) -> 200.1715 | W38: =SUM(W39,W40) -> 6.1546 | X38: =SUM(X39,X40) -> 0.2396 | Y38: =SUM(Y39,Y40) -> 0.4137 | Z38: =IFERROR(SUM(V38:Y38),"") -> 206.9794 | AA38: =SUM(AA39,AA40) -> 203.2172 | AB38: =SUM(AB39,AB40) -> 0.2882 | AC38: =SUM(AC39,AC40) -> 0.2436 | AD38: =SUM(AD39,AD40) -> 0.4137 | AE38: =IFERROR(SUM(AA38:AD38),"") -> 204.1627
A39: Others: Treasury Deposit at NRBT | J39: 211 | M39: Wages and salaries | N39: ='GFS 2025_26 Budget'!E418/10^6 -> 171.21795 | O39: ='GFS 2025_26 Budget'!F418/10^6 -> 178.8978 | P39: ='GFS 2025_26 Budget'!G418/10^6 -> 178.4581 | Q39: ='GFS 2025_26 Budget'!H418/10^6 -> 179.4057 | R39: ='GFS 2025_26 Budget'!I418/10^6 -> 15.5152 | S39: ='GFS 2025_26 Budget'!J418/10^6 -> 0.3666 | T39: ='GFS 2025_26 Budget'!K418/10^6 -> 0.2937 | U39: =IFERROR(SUM(Q39:T39),"") -> 195.5812 | V39: ='GFS 2025_26 Budget'!M418/10^6 -> 185.0317 | W39: ='GFS 2025_26 Budget'!N418/10^6 -> 6.1284 | X39: ='GFS 2025_26 Budget'!O418/10^6 -> 0.2396 | Y39: ='GFS 2025_26 Budget'!P418/10^6 -> 0.4137 | Z39: =IFERROR(SUM(V39:Y39),"") -> 191.8134 | AA39: ='GFS 2025_26 Budget'!R418/10^6 -> 188.0774 | AB39: ='GFS 2025_26 Budget'!S418/10^6 -> 0.262 | AC39: ='GFS 2025_26 Budget'!T418/10^6 -> 0.2436 | AD39: ='GFS 2025_26 Budget'!U418/10^6 -> 0.4137 | AE39: =IFERROR(SUM(AA39:AD39),"") -> 188.9967
A40: ADB Urban Development Loan | J40: 212 | M40: Social contributions | N40: ='GFS 2025_26 Budget'!E450/10^6 -> 12.98042 | O40: ='GFS 2025_26 Budget'!F450/10^6 -> 14.9254 | P40: ='GFS 2025_26 Budget'!G450/10^6 -> 13.4612 | Q40: ='GFS 2025_26 Budget'!H450/10^6 -> 15.1398 | R40: ='GFS 2025_26 Budget'!I450/10^6 -> 0.0262 | S40: ='GFS 2025_26 Budget'!J450/10^6 -> 0 | T40: ='GFS 2025_26 Budget'!K450/10^6 -> 0 | U40: =IFERROR(SUM(Q40:T40),"") -> 15.166 | V40: ='GFS 2025_26 Budget'!M450/10^6 -> 15.1398 | W40: ='GFS 2025_26 Budget'!N450/10^6 -> 0.0262 | X40: ='GFS 2025_26 Budget'!O450/10^6 -> 0 | Y40: ='GFS 2025_26 Budget'!P450/10^6 -> 0 | Z40: =IFERROR(SUM(V40:Y40),"") -> 15.166 | AA40: ='GFS 2025_26 Budget'!R450/10^6 -> 15.1398 | AB40: ='GFS 2025_26 Budget'!S450/10^6 -> 0.0262 | AC40: ='GFS 2025_26 Budget'!T450/10^6 -> 0 | AD40: ='GFS 2025_26 Budget'!U450/10^6 -> 0 | AE40: =IFERROR(SUM(AA40:AD40),"") -> 15.166
J41: 22 | M41: Use of goods and services | N41: ='GFS 2025_26 Budget'!E579/10^6 -> 237.3093 | O41: ='GFS 2025_26 Budget'!F579/10^6 -> 313.3205 | P41: ='GFS 2025_26 Budget'!G579/10^6 -> 238.3413 | Q41: ='GFS 2025_26 Budget'!H579/10^6 -> 124.0289 | R41: ='GFS 2025_26 Budget'!I579/10^6 -> 32.7086 | S41: ='GFS 2025_26 Budget'!J579/10^6 -> 57.1428 | T41: ='GFS 2025_26 Budget'!K579/10^6 -> 41.735 | U41: =IFERROR(SUM(Q41:T41),"") -> 255.6153 | V41: ='GFS 2025_26 Budget'!M579/10^6 -> 136.1874 | W41: ='GFS 2025_26 Budget'!N579/10^6 -> 19.1151 | X41: ='GFS 2025_26 Budget'!O579/10^6 -> 43.5361 | Y41: ='GFS 2025_26 Budget'!P579/10^6 -> 55.2753 | Z41: =IFERROR(SUM(V41:Y41),"") -> 254.1139 | AA41: ='GFS 2025_26 Budget'!R579/10^6 -> 139.7958 | AB41: ='GFS 2025_26 Budget'!S579/10^6 -> 15.5067 | AC41: ='GFS 2025_26 Budget'!T579/10^6 -> 42.55525 | AD41: ='GFS 2025_26 Budget'!U579/10^6 -> 54.6542 | AE41: =IFERROR(SUM(AA41:AD41),"") -> 252.51195
A42: Discrepancy | J42: 24 | M42: Interest | N42: =SUM(N43,N44,N45) -> 6.9135733 | O42: =SUM(O43,O44,O45) -> 5.9091 | P42: =SUM(P43,P44,P45) -> 5.9278 | Q42: =SUM(Q43,Q44,Q45) -> 6.369 | R42: =SUM(R43,R44,R45) -> 1e-06 | S42: =SUM(S43,S44,S45) -> 2e-06 | T42: =SUM(T43,T44,T45) -> 3e-06 | U42: =IFERROR(SUM(Q42:T42),"") -> 6.369006 | V42: =SUM(V43,V44,V45) -> 6.369 | W42: =SUM(W43,W44,W45) -> 1e-06 | X42: =SUM(X43,X44,X45) -> 2e-06 | Y42: =SUM(Y43,Y44,Y45) -> 3e-06 | Z42: =IFERROR(SUM(V42:Y42),"") -> 6.369006 | AA42: =SUM(AA43,AA44,AA45) -> 6.369 | AB42: =SUM(AB43,AB44,AB45) -> 1e-06 | AC42: =SUM(AC43,AC44,AC45) -> 2e-06 | AD42: =SUM(AD43,AD44,AD45) -> 3e-06 | AE42: =IFERROR(SUM(AA42:AD42),"") -> 6.369006
...

Sheet Tables
B2: Table 2: Government Finance Statistics (GFS) Summary Table | AD2: Tepile 13: Fakamatala Ngaahi Ngaue 'a e Pule'anga ($m) | AU2: Table 13: Statement of Government Operations (% change)
