Workbook

Sheet Consolidation

Sheet Data
A1: Fiscal Indicators
B3: FY2018 | C3: FY2019 | D3: FY2020 | E3: FY2021 | F3: FY2022 | G3: FY2023 | H3: FY2024 | I3: FY2025 | J3: FY2026 | K3: FY2027 | L3: FY2028 | M3: FY2029
B4: 1998/99 | C4: 1999/00 | D4: 2000/01 | E4: 2001/02 | F4: 2002/03 | G4: 2003/04 | H4: 2004/05 | I4: 2005/06 | J4: 2006/07 | K4: 2007/08 | L4: 2008/09 | M4: 2009/10 | N4: 2010/11 | O4: 2011/12 | P4: 2012/13 | Q4: 2013/14 | R4: 2014/15 | S4: 2015/16 | T4: 2016/17 | U4: 2017/18 | V4: 2018/19 | W4: 2019/20 | X4: 2020/21 | Y4: 2021/22 | Z4: 2022/23 | AA4: 2023/24 | AB4: 2024/25 | AC4: 2025/26 | AD4: 2026/27 | AE4: 2027/28 | AF4: 2028/29
A5: Nominal GDP | B5: {=GDP!H30:R30} -> 849.27589 | C5: 851.8788 | D5: 872.3634 | E5: 871.52186 | F5: 845.38451 | G5: 845.02152 | H5: 856.58691 | I5: 894.93264 | J5: 936.61967 | K5: 978.86661 | L5: 1030.4138 | O5: =GDP!B33 -> 892.85834 | P5: =GDP!C33 -> 896.23017 | Q5: =GDP!D33 -> 914.06999 | R5: =GDP!E33 -> 924.25039 | S5: =GDP!F33 -> 985.23894 | T5: =GDP!G33 -> 1016.7894 | U5: =GDP!H33 -> 1023.7803 | V5: =GDP!I33 -> 1021.6464 | ... AE5: =GDP!R33 -> 1211.4138
A6: Real GDP | B6: {=GDP!H39:R39} -> 0.5 | C6: -0.3 | D6: 1.8 | E6: -0.9 | F6: -2.1 | G6: 2.8 | H6: 1.7 | I6: 2.7 | J6: 3.4 | K6: 3.7 | L6: 3.9 | U6: {=GDP!AA39:AK39} -> 0 | V6: 0 | W6: 0 | X6: 0 | Y6: 0 | Z6: 0 | AA6: 0 | AB6: 0 | AC6: 0 | AD6: 0 | AE6: 0
A9: Exports
A10: Imports
A13: Monetary Indicators
B16: 1998/99 | C16: 1999/00 | D16: 2000/01 | E16: 2001/02 | F16: 2002/03 | G16: 2003/04 | H16: 2004/05 | I16: 2005/06 | J16: 2006/07 | K16: 2007/08 | L16: 2008/09 | M16: 2009/10 | N16: 2010/11 | O16: 2011/12 | P16: 2012/13 | Q16: 2013/14 | R16: 2014/15 | S16: 2015/16 | T16: 2016/17 | U16: 2017/18 | V16: 2018/19 | W16: 2019/20 | X16: 2020/21 | Y16: 2021/22 | Z16: 2022/23 | AA16: 2023/24 | AB16: 2024/25 | AC16: 2025/26 | AD16: 2026/27 | AE16: 2027/28 | AF16: 2028/29
A17: Total private | B17: 290.46 | C17: 358.9 | D17: 393.93 | E17: 432.39 | F17: 429.38 | G17: 430.29 | H17: 426.02 | I17: 470/68 | J17: 499.7
A18: Housing | B18: 126.92 | C18: 170.65 | D18: 190.83 | E18: 201.21 | F18: 204.63 | G18: 206.26 | H18: 201.24 | I18: 197.44 | J18: 204.36
A19: Personal | B19: 56.72
A20: Business | B20: 93.3
A21: Agriculture | B21: 9.6 | M21: =204.36+66.7+211.1+17.5+0.1 -> 499.76
A22: Other | B22: =B17-SUM(B18:B21) -> 3.92 | M22: =197.44+58.29+196+18.9+0.1 -> 470.73
A23: Remmittances | M23: =170.65+57.58+117.3+12.1+1.2 -> 358.83
A24: Inflation
A25: Foreign Reserves
B27: 1998/99 | C27: 1999/00 | D27: 2000/01 | E27: 2001/02 | F27: 2002/03 | G27: 2003/04 | H27: 2004/05 | I27: 2005/06 | J27: 2006/07 | K27: 2007/08 | L27: 2008/09 | M27: 2009/10 | N27: 2010/11 | O27: 2011/12 | P27: 2012/13 | Q27: 2013/14 | R27: 2014/15 | S27: 2015/16 | T27: 2016/17 | U27: 2017/18 | V27: 2018/19 | W27: 2019/20 | X27: 2020/21 | Y27: 2021/22 | Z27: 2022/23 | AA27: 2023/24 | AB27: 2024/25 | AC27: 2025/26 | AD27: 2026/27 | AE27: 2027/28 | AF27: 2028/29

Sheet Monetary Policy Data
B2: AUD | C2: CAD | D2: CHF | E2: EUR | F2: FJD | G2: GBP | H2: JPY | I2: NZD | J2: SEK | K2: SGD | L2: USD | M2: WST | N2: CNY
A3: 44197 | B3: 0.5658 | C3: 0.5574 | D3: 0.3864 | E3: 0.3594 | F3: 0.868 | G3: 0.3206 | H3: 45.3713 | I3: 0.6085 | J3: 3.6319 | K3: 0.5835 | L3: 0.4386 | M3: 1.0277 | N3: 2.8532 | P3: =1/B3 -> 1.767409
A4: 44228 | B4: 0.5605 | C4: 0.5531 | D4: 0.3886 | E4: 0.3594 | F4: 0.8597 | G4: 0.3136 | H4: 45.7801 | I4: 0.6009 | J4: 3.6279 | K4: 0.5808 | L4: 0.4358 | M4: 1.0181 | N4: 2.8352
A5: 44256 | B5: 0.5677 | C5: 0.5518 | D5: 0.405 | E5: 0.3677 | F5: 0.868 | G5: 0.3157 | H5: 47.5581 | I5: 0.6134 | J5: 3.741 | K5: 0.5918 | L5: 0.439 | M5: 1.03 | N5: 2.8562
A6: 44287 | B6: 0.5697 | C6: 0.55 | D6: 0.4034 | E6: 0.3667 | F6: 0.8706 | G6: 0.317 | H6: 47.8379 | I6: 0.616 | J6: 3.7332 | K6: 0.5892 | L6: 0.4401 | M6: 1.0352 | N6: 2.8632
B9: =1/B3 -> 1.767409 | C9: =1/C3 -> 1.7940438 | D9: =1/D3 -> 2.5879917 | E9: =1/E3 -> 2.7824151 | F9: =1/F3 -> 1.1520737 | G9: =1/G3 -> 3.1191516 | H9: =1/H3 -> 0.022040365 | I9: =1/I3 -> 1.6433854 | ... N9: =1/N3 -> 0.35048367
B10: =1/B4 -> 1.7841213 | C10: =1/C4 -> 1.8079913 | D10: =1/D4 -> 2.5733402 | E10: =1/E4 -> 2.7824151 | F10: =1/F4 -> 1.1631965 | G10: =1/G4 -> 3.1887755 | H10: =1/H4 -> 0.021843552 | I10: =1/I4 -> 1.6641704 | ... N10: =1/N4 -> 0.3527088
B11: =1/B5 -> 1.7614937 | C11: =1/C5 -> 1.8122508 | D11: =1/D5 -> 2.4691358 | E11: =1/E5 -> 2.7196084 | F11: =1/F5 -> 1.1520737 | G11: =1/G5 -> 3.1675641 | H11: =1/H5 -> 0.021026912 | I11: =1/I5 -> 1.6302576 | ... N11: =1/N5 -> 0.35011554
A13: 45170 | B13: 0.6487 | C13: 0.5653 | D13: 0.3729 | E13: 0.3899 | F13: 0.9315 | G13: 0.3354 | H13: 61.5089 | I13: 0.7032 | J13: 4.6265 | K13: 0.5728 | L13: 0.4174 | M13: 1.1568 | N13: 3.0456
A14: 45200 | B14: 0.6542 | C14: 0.5702 | D14: 0.3742 | E14: 0.3933 | F14: 0.9358 | G14: 0.3409 | H14: 62.1124 | I14: 0.7034 | J14: 4.5847 | K14: 0.5736 | L14: 0.4163 | M14: 1.1574 | N14: 3.0422
A15: 45231 | B15: 0.6447 | C15: 0.5753 | D15: 0.3718 | E15: 0.3871 | F15: 0.9354 | G15: 0.3367 | H15: 62.7441 | I15: 0.6991 | J15: 4.4789 | K15: 0.5694 | L15: 0.4191 | M15: 1.1559 | N15: 3.0292
A16: 45261 | B16: 0.6348 | C16: 0.5709 | D16: 0.3661 | E16: 0.3887 | F16: 0.9335 | G16: 0.3347 | H16: 61.13 | I16: 0.6827 | J16: 4.3659 | K16: 0.57 | L16: 0.4246 | M16: 1.1526 | N16: 3.0335
B18: =1/B13 -> 1.5415446 | C18: =1/C13 -> 1.7689722 | D18: =1/D13 -> 2.6816841 | E18: =1/E13 -> 2.5647602 | F18: =1/F13 -> 1.0735373 | G18: =1/G13 -> 2.9815146 | H18: =1/H13 -> 0.01625781 | I18: =1/I13 -> 1.4220705 | ... N18: =1/N13 -> 0.32834253
B19: =1/B14 -> 1.5285845 | C19: =1/C14 -> 1.7537706 | D19: =1/D14 -> 2.6723677 | E19: =1/E14 -> 2.5425884 | F19: =1/F14 -> 1.0686044 | G19: =1/G14 -> 2.9334116 | H19: =1/H14 -> 0.016099845 | I19: =1/I14 -> 1.4216662 | ... N19: =1/N14 -> 0.32870949
B20: =1/B16 -> 1.5752993 | C20: =1/C16 -> 1.7516202 | D20: =1/D16 -> 2.7314941 | E20: =1/E16 -> 2.5726782 | F20: =1/F16 -> 1.0712373 | G20: =1/G16 -> 2.9877502 | H20: =1/H16 -> 0.01635858 | I20: =1/I16 -> 1.4647722 | ... N20: =1/N16 -> 0.32965222
B29: AUD | C29: CAD | D29: CHF | E29: EUR | F29: FJD | G29: GBP | H29: JPY | I29: NZD | J29: SEK | K29: SGD | L29: USD | M29: WST | N29: CNY
A30: 42005 | B30: 0.6245 | C30: 0.6126 | D30: 0.7389 | E30: 0.4354 | F30: 0.9716 | G30: 0.3343 | H30: 60.1133 | I30: 0.6594 | J30: 4.1108 | K30: 0.6801 | L30: 0.5069 | M30: 1.1824 | N30: 3.1508 | V30: AUD | W30: CAD | X30: CHF | Y30: EUR | Z30: FJD | AA30: GBP | AB30: JPY | AC30: NZD | AD30: SEK | AE30: SGD | AF30: USD | AG30: WST | AH30: CNY | AO30: NEER | AP30: REER | AT30: Broad money | AY30: Import Prices | BD30: Brent Oil Price
A31: 42036 | B31: 0.639 | C31: 0.6269 | D31: 0.7328 | E31: 0.4404 | F31: 0.9783 | G31: 0.3264 | H31: 59.2652 | I31: 0.6692 | J31: 4.1826 | K31: 0.6801 | L31: 0.4999 | M31: 1.1799 | N31: 3.1253 | U31: 42005 | V31: =1/B30 -> 1.601281 | W31: =1/C30 -> 1.6323865 | X31: =1/D30 -> 1.3533631 | Y31: =1/E30 -> 2.2967386 | Z31: =1/F30 -> 1.0292301 | AA31: =1/G30 -> 2.9913252 | AB31: =1/H30 -> 0.016635254 | AC31: =1/I30 -> 1.5165302 | ... AH31: =1/N30 -> 0.31737971 | AN31: 40238 | AO31: 101.3 | AP31: 112.3 | AS31: 40238 | AT31: 284.7
A32: 42064 | B32: 0.6405 | C32: 0.628 | D32: 0.7432 | E32: 0.4593 | F32: 0.9757 | G32: 0.3322 | H32: 59.8198 | I32: 0.6635 | J32: 4.2519 | K32: 0.6875 | L32: 0.4974 | M32: 1.1621 | N32: 3.1038 | U32: 42036 | V32: =1/B31 -> 1.5649452 | W32: =1/C31 -> 1.5951507 | X32: =1/D31 -> 1.3646288 | Y32: =1/E31 -> 2.270663 | Z32: =1/F31 -> 1.0221813 | AA32: =1/G31 -> 3.0637255 | AB32: =1/H31 -> 0.016873308 | AC32: =1/I31 -> 1.4943216 | ... AH32: =1/N31 -> 0.31996928 | AN32: 40269 | AO32: 99.3 | AP32: 111.1 | AS32: 40269 | AT32: 285.1
A33: 42095 | B33: 0.6428 | C33: 0.6173 | D33: 0.7419 | E33: 0.4631 | F33: 0.9777 | G33: 0.3341 | H33: 59.6417 | I33: 0.6549 | J33: 4.3296 | K33: 0.6767 | L33: 0.4992 | M33: 1.1735 | N33: 3.0962 | U33: 42064 | V33: =1/B32 -> 1.5612802 | W33: =1/C32 -> 1.5923567 | X33: =1/D32 -> 1.3455328 | Y33: =1/E32 -> 2.1772262 | Z33: =1/F32 -> 1.0249052 | AA33: =1/G32 -> 3.0102348 | AB33: =1/H32 -> 0.016716873 | AC33: =1/I32 -> 1.507159 | ... AH33: =1/N32 -> 0.32218571 | AN33: 40299 | AO33: 99 | AP33: 112 | AS33: 40299 | AT33: 289.1
A34: 42125 | B34: 0.6242 | C34: 0.6035 | D34: 0.7303 | E34: 0.4437 | F34: 0.9643 | G34: 0.3206 | H34: 59.6931 | I34: 0.6662 | J34: 4.1347 | K34: 0.6632 | L34: 0.4954 | M34: 1.1735 | N34: 3.0979 | U34: 42095 | V34: =1/B33 -> 1.5556938 | W34: =1/C33 -> 1.6199579 | X34: =1/D33 -> 1.3478906 | Y34: =1/E33 -> 2.1593608 | Z34: =1/F33 -> 1.0228086 | AA34: =1/G33 -> 2.9931158 | AB34: =1/H33 -> 0.016766792 | AC34: =1/I33 -> 1.5269507 | ... AH34: =1/N33 -> 0.32297655 | AN34: 40330 | AO34: 101.1 | AP34: 112.2 | AS34: 40330 | AT34: 291.5
A35: 42156 | B35: 0.6175 | C35: 0.5928 | D35: 0.7225 | E35: 0.4269 | F35: 0.9484 | G35: 0.3077 | H35: 59.1901 | I35: 0.6807 | J35: 3.9651 | K35: 0.6468 | L35: 0.4792 | M35: 1.1421 | N35: 2.9736 | U35: 42125 | V35: =1/B34 -> 1.6020506 | W35: =1/C34 -> 1.6570008 | X35: =1/D34 -> 1.3693003 | Y35: =1/E34 -> 2.2537751 | Z35: =1/F34 -> 1.0370217 | AA35: =1/G34 -> 3.1191516 | AB35: =1/H34 -> 0.016752355 | AC35: =1/I34 -> 1.5010507 | ... AH35: =1/N34 -> 0.32279932 | AN35: 40360 | AO35: 99.9 | AP35: 114.8 | AS35: 40360 | AT35: 291.2
A36: 42186 | B36: 0.6232 | C36: 0.5972 | D36: 0.7209 | E36: 0.4226 | F36: 0.9436 | G36: 0.2987 | H36: 57.1985 | I36: 0.6954 | J36: 3.9645 | K36: 0.6351 | L36: 0.4645 | M36: 1.1463 | N36: 2.8838 | U36: 42156 | V36: =1/B35 -> 1.6194332 | W36: =1/C35 -> 1.6869096 | X36: =1/D35 -> 1.384083 | Y36: =1/E35 -> 2.342469 | Z36: =1/F35 -> 1.0544074 | AA36: =1/G35 -> 3.2499188 | AB36: =1/H35 -> 0.016894717 | AC36: =1/I35 -> 1.469076 | ... AH36: =1/N35 -> 0.33629271 | AN36: 40391 | AO36: 98.5 | AP36: 115.2 | AS36: 40391 | AT36: 288.9
A37: 42217 | B37: 0.6253 | C37: 0.6039 | D37: 0.7215 | E37: 0.4117 | F37: 0.9372 | G37: 0.294 | H37: 56.4637 | I37: 0.6971 | J37: 3.9313 | K37: 0.643 | L37: 0.4586 | M37: 1.1609 | N37: 2.904 | U37: 42186 | V37: =1/B36 -> 1.6046213 | W37: =1/C36 -> 1.6744809 | X37: =1/D36 -> 1.3871549 | Y37: =1/E36 -> 2.3663038 | Z37: =1/F36 -> 1.0597711 | AA37: =1/G36 -> 3.3478406 | AB37: =1/H36 -> 0.017482976 | AC37: =1/I36 -> 1.4380213 | ... AH37: =1/N36 -> 0.34676469 | AN37: 40422 | AO37: 99.2 | AP37: 115.7 | AS37: 40422 | AT37: 286.8
A38: 42248 | B38: 0.6327 | C38: 0.5948 | D38: 0.434 | E38: 0.3976 | F38: 0.9252 | G38: 0.2924 | H38: 53.7337 | I38: 0.7043 | J38: 3.7557 | K38: 0.6362 | L38: 0.4476 | M38: 1.1543 | N38: 2.8514 | U38: 42217 | V38: =1/B37 -> 1.5992324 | W38: =1/C37 -> 1.6559033 | X38: =1/D37 -> 1.3860014 | Y38: =1/E37 -> 2.4289531 | Z38: =1/F37 -> 1.0670081 | AA38: =1/G37 -> 3.4013605 | AB38: =1/H37 -> 0.017710494 | AC38: =1/I37 -> 1.4345144 | ... AH38: =1/N37 -> 0.34435262 | AN38: 40452 | AO38: 99.5 | AP38: 115.2 | AS38: 40452 | AT38: 302.5
A39: 42278 | B39: 0.6264 | C39: 0.5931 | D39: 0.4616 | E39: 0.4024 | F39: 0.923 | G39: 0.2954 | H39: 54.3409 | I39: 0.6759 | J39: 3.779 | K39: 0.6368 | L39: 0.453 | M39: 1.1496 | N39: 2.8751 | U39: 42248 | V39: =1/B38 -> 1.5805279 | W39: =1/C38 -> 1.6812374 | X39: =1/D38 -> 2.3041475 | Y39: =1/E38 -> 2.5150905 | Z39: =1/F38 -> 1.0808474 | AA39: =1/G38 -> 3.4199726 | AB39: =1/H38 -> 0.018610295 | AC39: =1/I38 -> 1.4198495 | ... AH39: =1/N38 -> 0.35070492 | AN39: 40483 | AO39: 100.7 | AP39: 114.6 | AS39: 40483 | AT39: 297.3
A40: 42309 | B40: 0.6244 | C40: 0.595 | D40: 0.4504 | E40: 0.4163 | F40: 0.9262 | G40: 0.2943 | H40: 54.8451 | I40: 0.6804 | J40: 3.8956 | K40: 0.6354 | L40: 0.4476 | M40: 1.14 | N40: 2.8507 | U40: 42278 | V40: =1/B39 -> 1.596424 | W40: =1/C39 -> 1.6860563 | X40: =1/D39 -> 2.1663778 | Y40: =1/E39 -> 2.4850895 | Z40: =1/F39 -> 1.0834236 | AA40: =1/G39 -> 3.3852404 | AB40: =1/H39 -> 0.018402345 | AC40: =1/I39 -> 1.4795088 | ... AH40: =1/N39 -> 0.34781399 | AN40: 40513 | AO40: 101.2 | AP40: 114.6 | AS40: 40513 | AT40: 305.5
A41: 42339 | B41: 0.6185 | C41: 0.6174 | D41: 0.4468 | E41: 0.4125 | F41: 0.921 | G41: 0.2997 | H41: 54.7296 | I41: 0.6656 | J41: 3.8346 | K41: 0.6359 | L41: 0.4498 | M41: 1.1385 | N41: 2.9009 | U41: 42309 | V41: =1/B40 -> 1.6015375 | W41: =1/C40 -> 1.6806723 | X41: =1/D40 -> 2.2202487 | Y41: =1/E40 -> 2.4021139 | Z41: =1/F40 -> 1.0796804 | AA41: =1/G40 -> 3.3978933 | AB41: =1/H40 -> 0.018233169 | AC41: =1/I40 -> 1.4697237 | ... AH41: =1/N40 -> 0.35079103 | AN41: 40544 | AO41: 100.9 | AP41: 116.5 | AS41: 40544 | AT41: 297.5
A42: 42370 | B42: 0.6295 | C42: 0.6304 | D42: 0.444 | E42: 0.4062 | F42: 0.9181 | G42: 0.3069 | H42: 52.3113 | I42: 0.675 | J42: 3.7882 | K42: 0.6365 | L42: 0.4424 | M42: 1.1294 | N42: 2.9064 | U42: 42339 | V42: =1/B41 -> 1.6168149 | W42: =1/C41 -> 1.6196955 | X42: =1/D41 -> 2.2381379 | Y42: =1/E41 -> 2.4242424 | Z42: =1/F41 -> 1.0857763 | AA42: =1/G41 -> 3.33667 | AB42: =1/H41 -> 0.018271648 | AC42: =1/I41 -> 1.5024038 | ... AH42: =1/N41 -> 0.3447206 | AN42: 40575 | AO42: 101.2 | AP42: 116 | AS42: 40575 | AT42: 287.9
... A48: 42552 | B48: 0.6018 | C48: 0.5926 | D48: 0.4447 | E48: 0.4096 | F48: 0.9149 | G48: 0.345 | H48: 47.2661 | I48: 0.639 | J48: 3.8962 | K48: 0.6154 | L48: 0.4537 | M48: 1.117 | N48: 3.0312 | U48: 42522 | V48: =1/B47 -> 1.6498928 | W48: =1/C47 -> 1.7208742 | X48: =1/D47 -> 2.2977941 | Y48: =1/E47 -> 2.5018764 | Z48: =1/F47 -> 1.0940919 | AA48: =1/G47 -> 3.1555696 | AB48: =1/H47 -> 0.021039167 | AC48: =1/I47 -> 1.5573898 | ... AH48: =1/N47 -> 0.33735915 | AN48: 40756 | AO48: 108 | AP48: 122.2 | AS48: 40756 | AT48: 294.2
A49: 42583 | B49: 0.5967 | C49: N/A | D49: N/A | E49: 0.4054 | F49: 0.9087 | G49: 0.3469 | H49: 46.0817 | I49: 0.6317 | J49: N/A | K49: N/A | L49: 0.4555 | M49: 1.1321 | N49: 3.0273 | U49: 42552 | V49: =1/B48 -> 1.6616816 | W49: =1/C48 -> 1.6874789 | X49: =1/D48 -> 2.248707 | Y49: =1/E48 -> 2.4414062 | Z49: =1/F48 -> 1.0930156 | AA49: =1/G48 -> 2.8985507 | AB49: =1/H48 -> 0.021156812 | AC49: =1/I48 -> 1.5649452 | ... AH49: =1/N48 -> 0.32990235 | AN49: 40787 | AO49: 106.9 | AP49: 120.7 | AS49: 40787 | AT49: 289.6
A50: 42614 | B50: 0.6045 | C50: 0.6009 | D50: 0.4452 | E50: 0.408 | F50: 0.9199 | G50: 0.348 | H50: 46.7263 | I50: 0.6282 | J50: 3.9189 | K50: 0.6275 | L50: 0.4588 | M50: 1.1468 | N50: 3.0607 | U50: 42583 | V50: =1/B49 -> 1.675884 | W50: =1/C49 -> #VALUE! | X50: =1/D49 -> #VALUE! | Y50: =1/E49 -> 2.4666996 | Z50: =1/F49 -> 1.1004732 | AA50: =1/G49 -> 2.8826751 | AB50: =1/H49 -> 0.021700588 | AC50: =1/I49 -> 1.5830299 | ... AH50: =1/N49 -> 0.33032735 | AN50: 40817 | AO50: 105.5 | AP50: 118.1 | AS50: 40817 | AT50: 296.2
A51: 42644 | U51: 42614 | V51: =1/B50 -> 1.6542597 | W51: =1/C50 -> 1.6641704 | X51: =1/D50 -> 2.2461815 | Y51: =1/E50 -> 2.4509804 | Z51: =1/F50 -> 1.0870747 | AA51: =1/G50 -> 2.8735632 | AB51: =1/H50 -> 0.021401224 | AC51: =1/I50 -> 1.5918497 | ... AH51: =1/N50 -> 0.32672265 | AN51: 40848 | AO51: 105.5 | AP51: 117.3 | AS51: 40848 | AT51: 295.15042
A52: 42675 | B52: 0.6027 | C52: 0.6105 | D52: 0.4506 | E52: 0.4196 | F52: 0.9215 | G52: 0.3652 | H52: 49.2301 | I52: 0.6367 | J52: 4.1488 | K52: 0.6425 | L52: 0.454 | M52: 1.1432 | N52: 3.1068 | U52: 42644 | V52: =V51+0.0012 -> 1.6554597 | W52: =W51+0.0012 -> 1.6653704 | X52: =X51+0.0012 -> 2.2473815 | Y52: =Y51+0.0012 -> 2.4521804 | Z52: =Z51+0.0012 -> 1.0882747 | AA52: =AA51+0.0012 -> 2.8747632 | AB52: =AB51+0.0012 -> 0.022601224 | AC52: =AC51+0.0012 -> 1.5930497 | ... AH52: =AH51+0.0012 -> 0.32792265 | AN52: 40878 | AO52: 105.1 | AP52: 116 | AS52: 40878 | AT52: 299.88445
A53: 42705 | B53: 0.6103 | C53: 0.599 | D53: 0.4561 | E53: 0.4247 | F53: 0.927 | G53: 0.359 | H53: 52.1237 | I53: 0.6384 | J53: 4.1439 | K53: 0.6489 | L53: 0.4492 | M53: 1.1366 | N53: 3.1082 | U53: 42675 | V53: =1/B52 -> 1.6592003 | W53: =1/C52 -> 1.6380016 | X53: =1/D52 -> 2.2192632 | Y53: =1/E52 -> 2.3832221 | Z53: =1/F52 -> 1.0851872 | AA53: =1/G52 -> 2.7382256 | AB53: =1/H52 -> 0.020312776 | AC53: =1/I52 -> 1.5705984 | ... AH53: =1/N52 -> 0.3218746 | AN53: 40909 | AO53: 104.9 | AP53: 117.9 | AS53: 40909 | AT53: 289.8532
A54: 42736 | B54: 0.603 | C54: 0.5943 | D54: 0.4518 | E54: 0.422 | F54: 0.9221 | G54: 0.3645 | H54: 51.7174 | I54: 0.6325 | J54: 4.0318 | K54: 0.6468 | L54: 0.4497 | M54: 1.1409 | N54: 3.1009 | U54: 42705 | V54: =1/B53 -> 1.6385384 | W54: =1/C53 -> 1.6694491 | X54: =1/D53 -> 2.1925016 | Y54: =1/E53 -> 2.3546032 | Z54: =1/F53 -> 1.0787487 | AA54: =1/G53 -> 2.7855153 | AB54: =1/H53 -> 0.019185131 | AC54: =1/I53 -> 1.566416 | ... AH54: =1/N53 -> 0.32172962 | AN54: 40940 | AO54: 105 | AP54: 118.5 | AS54: 40940 | AT54: 277.76306
A55: 42767 | B55: 0.594 | C55: 0.5967 | D55: 0.4541 | E55: 0.4262 | F55: 0.9213 | G55: 0.3637 | H55: 51.5245 | I55: 0.6301 | J55: 4.0538 | K55: 0.648 | L55: 0.4553 | M55: 1.1415 | N55: 3.1296 | U55: 42736 | V55: =1/B54 -> 1.6583748 | W55: =1/C54 -> 1.6826519 | X55: =1/D54 -> 2.2133687 | Y55: =1/E54 -> 2.3696682 | Z55: =1/F54 -> 1.0844811 | AA55: =1/G54 -> 2.7434842 | AB55: =1/H54 -> 0.019335852 | AC55: =1/I54 -> 1.5810277 | ... AH55: =1/N54 -> 0.32248702 | AN55: 40969 | AO55: 104.7 | AP55: 119.9 | AS55: 40969 | AT55: 283.5471
A56: 42795 | B56: 0.5888 | C56: 0.6016 | D56: 0.4484 | E56: 0.4192 | F56: 0.9154 | G56: 0.3635 | H56: 50.8292 | I56: 0.6417 | J56: 4.0089 | K56: 0.6353 | L56: 0.4492 | M56: 1.135 | N56: 3.098 | U56: 42767 | V56: =1/B55 -> 1.6835017 | W56: =1/C55 -> 1.675884 | X56: =1/D55 -> 2.2021581 | Y56: =1/E55 -> 2.3463163 | Z56: =1/F55 -> 1.0854228 | AA56: =1/G55 -> 2.7495188 | AB56: =1/H55 -> 0.019408243 | AC56: =1/I55 -> 1.5870497 | ... AH56: =1/N55 -> 0.31952965 | AN56: 41000 | AO56: 104.2 | AP56: 120.3 | AS56: 41000 | AT56: 288.69166
A57: 42826 | B57: 0.5914 | C57: 0.5993 | D57: 0.4448 | E57: 0.4155 | F57: 0.9128 | G57: 0.3528 | H57: 49.1894 | I57: 0.6404 | J57: 4.004 | K57: 0.6281 | L57: 0.4462 | M57: 1.1344 | N57: 3.0744 | U57: 42795 | V57: =1/B56 -> 1.6983696 | W57: =1/C56 -> 1.662234 | X57: =1/D56 -> 2.2301517 | Y57: =1/E56 -> 2.3854962 | Z57: =1/F56 -> 1.0924186 | AA57: =1/G56 -> 2.7510316 | AB57: =1/H56 -> 0.019673731 | AC57: =1/I56 -> 1.5583606 | ... AH57: =1/N56 -> 0.3227889 | AN57: 41030 | AO57: 103.5 | AP57: 118.5 | AS57: 41030 | AT57: 294.25329
A58: 42856 | B58: 0.5956 | C58: 0.6036 | D58: 0.4361 | E58: 0.401 | F58: 0.9034 | G58: 0.3427 | H58: 49.7221 | I58: 0.6396 | J58: 3.8989 | K58: 0.622 | L58: 0.4434 | M58: 1.0896 | N58: 3.0545 | U58: 42826 | V58: =1/B57 -> 1.6909029 | W58: =1/C57 -> 1.6686134 | X58: =1/D57 -> 2.2482014 | Y58: =1/E57 -> 2.4067389 | Z58: =1/F57 -> 1.0955302 | AA58: =1/G57 -> 2.8344671 | AB58: =1/H57 -> 0.020329583 | AC58: =1/I57 -> 1.561524 | ... AH58: =1/N57 -> 0.32526672 | AN58: 41061 | AO58: 103.3 | AP58: 121.7 | AS58: 41061 | AT58: 293.22898
...

Sheet GDP
B1: 2011/12 | C1: 2012/13 | D1: 2013/14 | E1: 2014/15 | F1: 2015/16 | G1: 2016/17 | H1: 2017/18 | I1: 2018/19 | J1: 2019/20r | K1: 2020/21 | L1: 2021/22 | M1: 2022/23 | N1: 2023/24f | O1: 2024/25f | P1: 2025/26f | Q1: 2026/27f | R1: 2027/28f
A2: GDP at constant prices (2016/17 prices TOPm) | B2: 11/12 | C2: 12/13 | D2: 13/14 | E2: 014/15 | F2: 15/16 | G2: 16/17 | H2: 17/18 | I2: 18/19 | J2: 19/20r | K2: 20/21 | L2: 21/22 | M2: 22/23p | N2: 23/24f | O2: 24/25f | P2: 25/26f | Q2: 26/27f | R2: 27/28f
A3: Primary Sector | B3: 169.69859 | C3: 176.41022 | D3: 180.81959 | E3: 177.66615 | F3: 175.43017 | G3: 171.01764 | H3: 175.43083 | I3: 184.61732 | J3: 190.34761 | K3: 188.66465 | L3: 193.96019 | M3: 225.76517 | N3: 205.3844 | O3: 211.75576 | P3: 218.84543 | Q3: 223.23684 | R3: 227.582
A4: Fishing | B4: 19.882251 | C4: 18.789285 | D4: 19.401575 | E4: 21.515773 | F4: 26.284896 | G4: 19.275379 | H4: 16.902112 | I4: 20.017383 | J4: 24.180957 | K4: 21.479261 | L4: 20.08561 | M4: 22.005838 | N4: 20.323987 | O4: 20.951918 | P4: 21.685634 | Q4: 22.521142 | R4: 23.46703
A5: Agriculture sector | B5: =B3-B4 -> 149.81634 | C5: =C3-C4 -> 157.62094 | D5: =D3-D4 -> 161.41802 | E5: =E3-E4 -> 156.15038 | F5: =F3-F4 -> 149.14528 | G5: =G3-G4 -> 151.74226 | H5: =H3-H4 -> 158.52872 | I5: =I3-I4 -> 164.59993 | ... R5: =R3-R4 -> 204.11497
A7: Industrial Sector | B7: 147.37107 | C7: 126.11531 | D7: 136.14788 | E7: 135.4453 | F7: 152.30931 | G7: 166.96926 | H7: 142.39497 | I7: 148.97079 | J7: 150.07564 | K7: 178.55675 | L7: 156.67568 | M7: 139.22309 | N7: 148.38986 | O7: 156.22828 | P7: 165.6293 | Q7: 176.26813 | R7: 188.4493
A8: Mining and Quarrying | B8: 8.3748478 | C8: 6.2277372 | D8: 6.5018693 | E8: 6.5964839 | F8: 5.8829426 | G8: 6.0752275 | H8: 6.7012654 | I8: 4.07248 | J8: 3.582104 | K8: 3.8959102 | L8: 4.1629465 | M8: 3.1365906 | N8: 3.4661345 | O8: 3.742383 | P8: 4.0685145 | Q8: 4.4472404 | R8: 4.8901624
A9: Manufacturing | B9: 52.579929 | C9: 53.620971 | D9: 54.105167 | E9: 55.742488 | F9: 59.881518 | G9: 60.803691 | H9: 59.722468 | I9: 56.849823 | J9: 58.88822 | K9: 63.242166 | L9: 50.450671 | M9: 43.844426 | N9: 44.219703 | O9: 44.743526 | P9: 45.577923 | Q9: 46.669029 | R9: 48.119752
A10: Electricity, water and waste | B10: 19.182777 | C10: 19.968971 | D10: 20.672116 | E10: 21.032341 | F10: 22.600144 | G10: 24.670702 | H10: 24.959273 | I10: 27.186355 | J10: 29.580339 | K10: 29.81205 | L10: 31.140483 | M10: 32.849121 | N10: 34.470554 | O10: 35.857304 | P10: 37.611802 | Q10: 39.403252 | R10: 41.251593
A11: Construction with PG | B11: 67.23352 | C11: 46.297629 | D11: 54.868731 | E11: 52.07399 | F11: 63.944706 | G11: 75.41964 | H11: 51.011965 | I11: 60.86213 | J11: 58.024978 | K11: 81.606622 | L11: 70.921576 | M11: 59.392947 | N11: 66.233466 | O11: 71.885067 | P11: 78.371059 | Q11: 85.748612 | R11: 94.187788
A13: Services | B13: 462.77236 | C13: 478.94222 | D13: 473.85559 | E13: 479.52048 | F13: 506.13364 | G13: 514.32219 | H13: 531.45008 | I13: 518.2907 | J13: 531.94016 | K13: 504.30046 | L13: 494.74864 | M13: 480.03326 | N13: 502.81265 | O13: 526.9486 | P13: 552.14494 | Q13: 579.36163 | R13: 614.38254
A14: Wholesale and retail | B14: 85.622069 | C14: 85.890326 | D14: 83.220297 | E14: 85.403676 | F14: 98.05526 | G14: 100.57109 | H14: 106.83039 | I14: 107.28075 | J14: 109.9771 | K14: 95.342798 | L14: 94.480372 | M14: 98.027347 | N14: 103.96124 | O14: 113.08472 | P14: 120.44521 | Q14: 128.28478 | R14: 141.766
A15: Transport and stroage | B15: 26.502738 | C15: 28.73089 | D15: 30.113165 | E15: 31.6649 | F15: 31.04777 | G15: 36.307791 | H15: 37.83137 | I15: 35.803383 | J15: 31.581557 | K15: 20.697273 | L15: 27.928567 | M15: 26.693429 | N15: 27.686276 | O15: 28.755321 | P15: 29.971259 | Q15: 31.281275 | R15: 32.736331
A16: Accommodation and food services | B16: 16.397103 | C16: 23.0714 | D16: 22.110733 | E16: 23.722849 | F16: 27.660261 | G16: 30.039452 | H16: 32.26387 | I16: 31.204923 | J16: 22.636194 | K16: 9.6439821 | L16: 9.2481585 | M16: 22.896288 | N16: 28.981748 | O16: 31.509971 | P16: 34.247998 | Q16: 37.513236 | R16: 41.40666
A17: Information and communication | B17: 23.965787 | C17: 24.623403 | D17: 19.694139 | E17: 22.221173 | F17: 22.696005 | G17: 22.541018 | H17: 24.644849 | I17: 24.515023 | J17: 31.979585 | K17: 28.384082 | L17: 33.523449 | M17: 26.693429 | N17: 27.686276 | O17: 28.755321 | P17: 29.971259 | Q17: 31.281275 | R17: 32.736331
A18: Financial and insurance activities | B18: 51.565478 | C18: 49.954849 | D18: 50.521214 | E18: 46.339033 | F18: 50.133918 | G18: 48.000121 | H18: 50.141445 | I18: 50.215538 | J18: 52.714182 | K18: 51.086318 | L18: 45.328479 | M18: 51.338974 | N18: 53.191208 | O18: 55.219836 | P18: 58.348185 | Q18: 61.458669 | R18: 64.749817
A19: Real estate activities | B19: 89.851459 | C19: 91.181959 | D19: 90.65428 | E19: 92.446127 | F19: 92.024895 | G19: 93.156887 | H19: 91.58141 | I19: 82.754757 | J19: 91.229375 | K19: 92.221385 | L19: 69.589777 | M19: 57.635425 | N19: 58.498389 | O19: 59.447125 | P19: 60.371771 | Q19: 61.373632 | R19: 62.489311
... A28: Other service activities | B28: 15.622307 | C28: 16.946642 | D28: 18.004236 | E28: 17.277097 | F28: 17.493388 | G28: 16.892726 | H28: 17.491225 | I28: 16.944047 | J28: 16.867938 | K28: 15.142074 | L28: 13.078175 | M28: 11.599664 | N28: 11.911286 | O28: 12.295455 | P28: 12.764931 | Q28: 13.309675 | R28: 14.184604
A30: GDP at factor cost | B30: =SUM(B3,B7,B13) -> 779.84202 | C30: =SUM(C3,C7,C13) -> 781.46775 | D30: =SUM(D3,D7,D13) -> 790.82306 | E30: =SUM(E3,E7,E13) -> 792.63194 | F30: =SUM(F3,F7,F13) -> 833.87312 | G30: =SUM(G3,G7,G13) -> 852.30909 | H30: =SUM(H3,H7,H13) -> 849.27589 | I30: =SUM(I3,I7,I13) -> 851.8788 | ... R30: =SUM(R3,R7,R13) -> 1030.4138
A31: add taxes (VAT, excise) | B31: 113.40877 | C31: 115.73105 | D31: 123.33268 | E31: 131.70366 | F31: 152.04009 | G31: 165.28878 | H31: 175.26784 | I31: 170.54906 | J31: 168.26164 | K31: 172.83243 | L31: 175.00135 | M31: 196.81656 | N31: 203.5 | O31: 194 | P31: 190 | Q31: 189 | R31: 183
A32: less subsidies on products | B32: 0.39245479 | C32: 0.96864186 | D32: 0.085755992 | E32: 0.085210143 | F32: 0.67427298 | G32: 0.80846416 | H32: 0.76338098 | I32: 0.78145856 | J32: 0.7586428 | K32: 0.71732133 | L32: 0.85543941 | M32: 1.0590751 | N32: 1.1 | O32: 1.1 | P32: 2 | Q32: 2 | R32: 2
A33: GDP at market prices | B33: =SUM(B30:B31)-B32 -> 892.85834 | C33: =SUM(C30:C31)-C32 -> 896.23017 | D33: =SUM(D30:D31)-D32 -> 914.06999 | E33: =SUM(E30:E31)-E32 -> 924.25039 | F33: =SUM(F30:F31)-F32 -> 985.23894 | G33: =SUM(G30:G31)-G32 -> 1016.7894 | H33: =SUM(H30:H31)-H32 -> 1023.7803 | I33: =SUM(I30:I31)-I32 -> 1021.6464 | ... R33: =SUM(R30:R31)-R32 -> 1211.4138
B37: 11/12 | C37: 12/13 | D37: 13/14 | E37: 014/15 | F37: 15/16 | G37: 16/17 | H37: 17/18 | I37: 18/19 | J37: 19/20r | K37: 20/21 | L37: 21/22 | M37: 22/23p | N37: 23/24f | O37: 24/25f | P37: 25/26f | Q37: 26/27f | R37: 27/28f
A38: GDP growth | C38: =(C33/B33-1)*100 -> 0.37764393 | D38: =(D33/C33-1)*100 -> 1.9905402 | E38: =(E33/D33-1)*100 -> 1.1137441 | F38: =(F33/E33-1)*100 -> 6.5987044 | G38: =(G33/F33-1)*100 -> 3.2023165 | H38: =(H33/G33-1)*100 -> 0.68755058 | I38: =(I33/H33-1)*100 -> -0.20843749 | J38: =(J33/I33-1)*100 -> 1.7833949 | ... R38: =(R33/Q33-1)*100 -> 3.9067272
A39: MOF GDP | H39: 0.5 | I39: -0.3 | J39: 1.8 | K39: -0.9 | L39: -2.1 | M39: 2.8 | N39: 1.7 | O39: 2.7 | P39: 3.4 | Q39: 3.7 | R39: 3.9
A40: IMF GDP | L40: -2.3 | M40: 2.1 | N40: 2.7 | O40: 2.3
A41: NRBT | F41: 6.6 | G41: 3.2 | H41: 0.53 | I41: -0.29 | J41: 1.81 | K41: -0.93 | L41: -2.13 | M41: 2.79 | N41: 1.72 | O41: 2.65 | P41: 2.45
A42: Statistics | D42: 1.9905402 | E42: 1.1137441 | F42: 6.5987044 | G42: 3.2023165 | H42: 0.52782727 | I42: -0.28520879 | J42: 1.8061874 | K42: -0.9349263 | L42: -2.1285445 | M42: 2.7901437 | N42: 1.7165411
A44: Primary
A45: Secondary
A46: Tertiary

Sheet Monthly indicators
B1: 37987 | C1: 38018 | D1: 38047 | E1: 38078 | F1: 38108 | G1: 38139 | H1: 38169 | I1: 38200 | J1: 38231 | K1: 38261 | L1: 38292 | M1: 38322 | N1: 38353 | O1: 38384 | P1: 38412 | Q1: 38443 | R1: 38473 | S1: 38504 | T1: 38534 | U1: 38565 | V1: 38596 | W1: 38626 | X1: 38657 | Y1: 38687 | Z1: 38718 | AA1: 38749 | AB1: 38777 | AC1: 38808 | AD1: 38838 | AE1: 38869 | AF1: 38899 | AG1: 38930 | AH1: 38961 | AI1: 38991 | AJ1: 39022 | AK1: 39052 | AL1: 39083 | AM1: 39114 | AN1: 39142 | AO1: 39173 | AP1: 39203 | AQ1: 39234 | AR1: 39264 | AS1: 39295 | AT1: 39326 | AU1: 39356 | AV1: 39387 | AW1: 39417 | AX1: 39448 | AY1: 39479 | AZ1: 39508 | BA1: 39539 | BB1: 39569 | BC1: 39600 | BD1: 39630 | BE1: 39661 | BF1: 39692 | BG1: 39722 | BH1: 39753 | BI1: 39783 | BJ1: 39814 | BK1: 39845 | BL1: 39873 | BM1: 39904 | BN1: 39934 | BO1: 39965 | BP1: 39995 | BQ1: 40026 | BR1: 40057 | BS1: 40087 | BT1: 40118 | BU1: 40148 | BV1: 40179 | BW1: 40210 | BX1: 40238 | BY1: 40269 | BZ1: 40299 | CA1: 40330 | CB1: 40360 | CC1: 40391 | CD1: 40422 | CE1: 40452 | CF1: 40483 | CG1: 40513 | CH1: 40544 | CI1: 40575 | CJ1: 40603 | CK1: 40634 | CL1: 40664 | CM1: 40695 | CN1: 40725 | CO1: 40756 | CP1: 40787 | CQ1: 40817 | CR1: 40848 | CS1: 40878 | CT1: 40909 | CU1: 40940 | CV1: 40969 | CW1: 41000 | CX1: 41030 | CY1: 41061 | CZ1: 41091 | DA1: 41122 | DB1: 41153 | DC1: 41183 | DD1: 41214 | DE1: 41244 | DF1: 41275 | DG1: 41306 | DH1: 41334 | DI1: 41365 | DJ1: 41395 | DK1: 41426 | DL1: 41456 | DM1: 41487 | DN1: 41518 | DO1: 41548 | DP1: 41579 | DQ1: 41609 | DR1: 41640 | DS1: 41671 | DT1: 41699 | DU1: 41730 | DV1: 41760 | DW1: 41791 | DX1: 41821 | DY1: 41852 | DZ1: 41883 | EA1: 41913 | EB1: 41944 | EC1: 41974 | ED1: 42005 | EE1: 42036 | EF1: 42064 | EG1: 42095 | EH1: 42125 | EI1: 42156 | EJ1: 42186 | EK1: 42217 | EL1: 42248 | EM1: 42278 | EN1: 42309 | EO1: 42339 | EP1: 42370 | EQ1: 42401 | ER1: 42430 | ES1: 42461 | ET1: 42491 | EU1: 42522 | EV1: 42552 | EW1: 42583 | EX1: 42614 | EY1: 42644 | EZ1: 42675 | FA1: 42705 | FB1: 42736 | FC1: 42767 | FD1: 42795 | FE1: 42826 | FF1: 42856 | FG1: 42887 | FH1: 42917 | FI1: 42948 | FJ1: 42979 | FK1: 43009 | FL1: 43040 | FM1: 43070 | FN1: 43101 | FO1: 43132 | FP1: 43160 | FQ1: 43191 | FR1: 43221 | FS1: 43252 | FT1: 43282 | FU1: 43313 | FV1: 43344 | FW1: 43374 | FX1: 43405 | FY1: 43435 | FZ1: 43466 | GA1: 43497 | GB1: 43525 | GC1: 43556 | GD1: 43586 | GE1: 43617 | GF1: 43647 | GG1: 43678 | GH1: 43709 | GI1: 43739 | GJ1: 43770 | GK1: 43800 | GL1: 43831 | GM1: 43862 | GN1: 43891 | GO1: 43922 | GP1: 43952 | GQ1: 43983 | GR1: 44013 | GS1: 44044 | GT1: 44075 | GU1: 44105 | GV1: 44136 | GW1: 44166 | GX1: 44197 | GY1: 44228 | GZ1: 44256 | HA1: 44287 | HB1: 44317 | HC1: 44348 | HD1: 44378 | HE1: 44409 | HF1: 44440 | HG1: 44470 | HH1: 44501 | HI1: 44531 | HJ1: 44562 | HK1: 44593 | HL1: 44621 | HM1: 44652 | HN1: 44682 | HO1: 44713 | HP1: 44743 | HQ1: 44774 | HR1: 44805 | HS1: 44835 | HT1: 44866 | HU1: 44896 | HV1: 44927 | HW1: 44958 | HX1: 44986 | HY1: 45017 | HZ1: 45047 | IA1: 45078 | IB1: 45108 | IC1: 45139 | ID1: 45170 | IE1: 45200 | IF1: 45231 | IG1: 45261 | IH1: 45292 | II1: 45323 | IJ1: 45352 | IK1: 45383 | IL1: 45413 | IM1: 45444 | IN1: 45474 | IO1: 45505 | IP1: 45536 | IQ1: 45566 | IR1: 45597 | IS1: 45627 | IT1: 45658 | IU1: 45689 | IV1: 45717 | IW1: 45748 | IX1: 45778 | IY1: 45809 | IZ1: 45839 | JA1: 45870 | JB1: 45901 | JC1: 45931 | JD1: 45962 | JE1: 45992 | JF1: 46023 | JG1: 46054 | JH1: 46082 | JI1: 46113 | JJ1: 46143 | JK1: 46174 | JL1: 46204 | JM1: 46235 | JN1: 46266 | JO1: 46296 | JP1: 46327 | JQ1: 46357
A2: Monetary variables
A3: Foreign Reserves | B3: 54.9 | C3: 54.3 | D3: 56.3 | E3: 60.4 | F3: 63.9 | G3: 89.7 | H3: 89.5 | I3: 78.4 | J3: 79 | K3: 87.1 | L3: 91.5 | M3: 93.4 | N3: 87.1 | O3: 85.4 | P3: 80.9 | Q3: 83.2 | R3: 85.9 | S3: 82.121 | T3: 80.694 | U3: 81.5 | V3: 82.8 | W3: 82.4 | X3: 81.8 | Y3: 85.7 | Z3: 87.2 | AA3: 82.4 | AB3: 77.4 | AC3: 83.9 | AD3: 84.2 | AE3: 83.2 | AF3: 86.3 | AG3: 85.7 | AH3: 85.3 | AI3: 89.2 | AJ3: 84.6 | AK3: 84.2 | AL3: 85.4 | AM3: 84.2 | AN3: 90.4 | AO3: 80.6 | AP3: 84.9 | AQ3: 91.6 | AR3: 90.3 | AS3: 97.7 | AT3: 104.8 | AU3: 109 | AV3: 94.8 | AW3: 114.6 | AX3: 113.1 | AY3: 101.8 | AZ3: 96.3 | BA3: 89.7 | BB3: 89.5 | BC3: 89.1 | BD3: 86.2 | BE3: 91.3 | BF3: 128.5 | BG3: 121.6 | BH3: 122.7 | BI3: 123.9 | BJ3: 130.4 | BK3: 131.1 | BL3: 130.6 | BM3: 132.6 | BN3: 132.1 | BO3: 136.3 | BP3: 139.4 | BQ3: 159.2 | BR3: 163.3 | BS3: 160.7 | BT3: 159.9 | BU3: 160.4 | BV3: 160.8 | BW3: 153.5 | BX3: 155.5 | BY3: 161.4 | BZ3: 166.7 | CA3: 170.5 | CB3: 178 | CC3: 174.1 | CD3: 172.7 | CE3: 176.5 | CF3: 168 | CG3: 177.5 | CH3: 165.2 | CI3: 158.8 | CJ3: 157.1 | CK3: 160.1 | CL3: 170.2 | CM3: 203.8 | CN3: 197.6 | CO3: 212.4 | CP3: 208.1 | CQ3: 213.9 | CR3: 212.9 | CS3: 226 | CT3: 229.5 | CU3: 230.6 | CV3: 239.2 | CW3: 240.3 | CX3: 245 | CY3: 246.1 | CZ3: 251.1 | DA3: 252.7 | DB3: 247.9 | DC3: 246.2 | DD3: 253.7 | DE3: 257.3 | DF3: 260.3 | DG3: 258 | DH3: 244.8 | DI3: 258.4 | DJ3: 259.2 | DK3: 263.3 | DL3: 252.69805 | DM3: 256.2 | DN3: 254.2 | DO3: 260.6 | DP3: 265.4 | DQ3: 271.8 | DR3: 276.7 | DS3: 281.1 | DT3: 274.8 | DU3: 267.9 | DV3: 266.8 | DW3: 274.4 | DX3: 280.4 | DY3: 283.9 | DZ3: 270.9 | EA3: 271.5 | EB3: 267.9 | EC3: 293.6 | ED3: 287.2 | EE3: 281.3 | EF3: 270.2 | EG3: 272.1 | EH3: 281.1 | EI3: 289.7 | EJ3: 302.6 | EK3: 310.9 | EL3: 311.7 | EM3: 315.8 | EN3: 319 | EO3: 327.8 | EP3: 326.3 | EQ3: 328.5 | ER3: 317.3 | ES3: 322.9 | ET3: 330.7 | EU3: 354.9 | EV3: 367.4 | EW3: 366.3 | EX3: 363.7 | EY3: 367 | EZ3: 360.9 | FA3: 378.8 | FB3: 380.8 | FC3: 377.7 | FD3: 366 | FE3: 371.7 | FF3: 392.3 | FG3: 407.9 | FH3: 408.9 | FI3: 405 | FJ3: 403 | FK3: 413.6 | FL3: 424.8 | FM3: 422.6 | FN3: 424.1 | FO3: 448 | FP3: 447.7 | FQ3: 445.9 | FR3: 441.9 | FS3: 468.7 | FT3: 476.5 | FU3: 475 | FV3: 452.2 | FW3: 457.3 | FX3: 468.7 | FY3: 478.5 | FZ3: 478.9 | GA3: 473.5 | GB3: 465 | GC3: 464.2 | GD3: 468.3 | GE3: 484.3 | GF3: 492.9 | GG3: 491.8 | GH3: 490.8 | GI3: 489.3 | GJ3: 489.5 | GK3: 487.4 | GL3: 482.9 | GM3: 479.8 | GN3: 457.5 | GO3: 475.1 | GP3: 489.6 | GQ3: 543.8 | GR3: 555.9 | GS3: 556.1 | GT3: 576.5 | GU3: 581.6 | GV3: 590.2 | GW3: 675.6 | GX3: 705.3 | GY3: 692.4 | GZ3: 685.7 | HA3: 679.7 | HB3: 689.5 | HC3: 715.2 | HD3: 704.8 | HE3: 751.7 | HF3: 757 | HG3: 757 | HH3: 783.9 | HI3: 817.5 | HJ3: 856.1 | HK3: 867.3 | HL3: 861.4 | HM3: 884 | HN3: 880.4 | HO3: 871.2 | HP3: 884.8 | HQ3: 871 | HR3: 895.3 | HS3: 877 | HT3: 866.2 | HU3: 868.9 | HV3: 911.1 | HW3: 911.2 | HX3: 883.7 | HY3: 860.5 | HZ3: 864.8 | IA3: 921.4 | IB3: 945.2 | IC3: 920 | ID3: 886.1 | IE3: 891.2 | IF3: 892 | IG3: 901.7 | IH3: 894.7 | II3: 891.4 | IJ3: 868.7 | IK3: 904.8 | IL3: 893 | IM3: 924.3 | IN3: 909.1 | IO3: 905.5 | IP3: 887.4 | IQ3: 898.2 | IR3: 892.2 | IS3: 889.1 | IT3: 878 | IU3: 865.4 | IV3: 842.6 | IW3: 867.6 | IX3: 871.5 | IY3: 925.1 | IZ3: 921 | JA3: 921.1 | JB3: 897.2 | JC3: 939.5 | JD3: 940.3 | JE3: 961,7 | JF3: 958.6 | JG3: 959.6 | JH3: 924.5 | JI3: 938.9 | JJ3: 970.9
A4: Import cover | B4: 3.3 | C4: 3.4 | D4: 3.4 | E4: 3.6 | F4: 3.9 | G4: 5.4 | H4: 5.5 | I4: 4.8 | J4: 4.8 | K4: 5.4 | L4: 5.3 | M4: 5.4 | N4: 5 | O4: 4.8 | P4: 4.5 | Q4: 4.7 | R4: 4.7 | S4: 4.4 | T4: 4.3 | U4: 4.3 | V4: 4.3 | W4: 4.2 | X4: 4.2 | Y4: 4.4 | Z4: 4.5 | AA4: 4.3 | AB4: 3.9 | AC4: 4.2 | AD4: 4.3 | AE4: 4.3 | AF4: 4.4 | AG4: 4.3 | AH4: 4.2 | AI4: 4.4 | AJ4: 4.3 | AK4: 4.3 | AL4: 4.3 | AM4: 4.2 | AN4: 4.5 | AO4: 4 | AP4: 4.1 | AQ4: 4.4 | AR4: 4.2 | AS4: 4.4 | AT4: 4.8 | AU4: 4.8 | AV4: 4 | AW4: 4.9 | AX4: 4.8 | AY4: 4.6 | AZ4: 4.1 | BA4: 3.6 | BB4: 3.6 | BC4: 3.5 | BD4: 3.3 | BE4: 3.6 | BF4: 5 | BG4: 4.8 | BH4: 4.9 | BI4: 4.6 | BJ4: 4.8 | BK4: 4.9 | BL4: 4.9 | BM4: 5.1 | BN4: 5 | BO4: 5.3 | BP4: 5.6 | BQ4: 6.5 | BR4: 6.7 | BS4: 6.7 | BT4: 6.7 | BU4: 6.8 | BV4: 6.6 | BW4: 6.2 | BX4: 6.2 | BY4: 6.3 | BZ4: 6.6 | CA4: 7.1 | CB4: 7.4144921 | CC4: 7.1968389 | CD4: 7.0980639 | CE4: 7.2389723 | CF4: 6.8364944 | CG4: 7.0582376 | CH4: 6.5 | CI4: 6.2 | CJ4: 6.0948848 | CK4: 6.3 | CL4: 6.5009958 | CM4: 7.6934505 | CN4: 7.5069763 | CO4: 8.0659795 | CP4: 7.8 | CQ4: 8 | CR4: 7.8 | CS4: 8.2 | CT4: 8.2 | CU4: 8.2 | CV4: 8.6 | CW4: 8.4916067 | CX4: 8.4708495 | CY4: 8.5494487 | CZ4: 8.6405513 | DA4: 8.5746951 | DB4: 8.511346 | DC4: 8.5 | DD4: 8.8 | DE4: 9 | DF4: 9.1 | DG4: 8.9 | DH4: 8.5 | DI4: 9 | DJ4: 9.1 | DK4: 9.1 | DL4: 8.8 | DM4: 9 | DN4: 8.9 | DO4: 8.9 | DP4: 9 | DQ4: 9.3 | DR4: 9.4 | DS4: 9.4 | DT4: 9.1 | DU4: 8.9 | DV4: 8.9 | DW4: 9.1 | DX4: 9.1 | DY4: 9.1 | DZ4: 8.4 | EA4: 8.2 | EB4: 8 | EC4: 8.7 | ED4: 8.5 | EE4: 8.3 | EF4: 7.9 | EG4: 7.9 | EH4: 8 | EI4: 8.1 | EJ4: 8.5 | EK4: 8.6 | EL4: 8.6 | EM4: 8.8 | EN4: 8.9 | EO4: 8.9 | EP4: 8.8 | EQ4: 7.1 | ER4: 6.7 | ES4: 6.7 | ET4: 6.8 | EU4: 7.2 | EV4: 7.4 | EW4: 7.2 | EX4: 6.9 | EY4: 7 | EZ4: 6.7 | FA4: 7.1 | FB4: 7.1 | FC4: 6.9 | FD4: 6.7 | FE4: 6.7 | FF4: 7.1 | FG4: 7.5 | FH4: 7.5 | FI4: 7.4 | FJ4: 7.3 | FK4: 7.5 | FL4: 7.7 | FM4: 7.6 | FN4: 7.4 | FO4: 7.9 | FP4: 7.8 | FQ4: 8 | FR4: 7.5 | FS4: 8 | FT4: 8.2 | FU4: 8.1 | FV4: 7.8 | FW4: 7.7 | FX4: 8.2 | FY4: 8.4 | FZ4: 8.1 | GA4: 7.9 | GB4: 7.8 | GC4: 7.5 | GD4: 7.5 | GE4: 7.9 | GF4: 8 | GG4: 8.1 | GH4: 8 | GI4: 7.5 | GJ4: 7.4 | GK4: 7.4 | GL4: 7.4 | GM4: 7.4 | GN4: 7.1 | GO4: 7.7 | GP4: 8.2 | GQ4: 9.2 | GR4: 9.5 | GS4: 9.6 | GT4: 10 | GU4: 9.7 | GV4: 10.9 | GW4: 12.5 | GX4: 12 | GY4: 11.7 | GZ4: 12.2 | HA4: 11.9 | HB4: 14.7 | HC4: 11.8 | HD4: 11.5 | HE4: 12.1 | HF4: 12.4 | HG4: 12.8 | HH4: 13 | HI4: 13.4 | HJ4: 13.9 | HK4: 14.4 | HL4: 14.5 | HM4: 14.9 | HN4: 14.7 | HO4: 14.4 | HP4: 14.4 | HQ4: 14 | HR4: 13.7 | HS4: 13.9 | HT4: 12.6 | HU4: 13.4 | HV4: 12.8 | HW4: 12.6 | HX4: 12 | HY4: 11.4 | HZ4: 11.5 | IA4: 12 | IB4: 12.3 | IC4: 11.9 | ID4: 11.4 | IE4: 11.4 | IF4: 11.4 | IG4: 11.6 | IH4: 11.5 | II4: 11.5 | IJ4: 11.1 | IK4: 11.6 | IL4: 11.5 | IM4: 11.9 | IN4: 11.5 | IO4: 10.4 | IP4: 10.2 | IQ4: 10.3 | IR4: 10.3 | IS4: 10.2 | IT4: 10.1 | IU4: 9.9 | IV4: 9.7 | IW4: 10 | IX4: 10 | IY4: 10.6 | IZ4: 10.7 | JA4: 10.7 | JB4: 10.4 | JC4: 10.9 | JD4: 10.9 | JE4: 11.2 | JF4: 11.1 | JG4: 11.2 | JH4: 10.8 | JI4: 10.9 | JJ4: 11.3
A6: CPI | FB6: 90 | FC6: 93.3 | FD6: 93.7 | FE6: 94.2 | FF6: 94.5 | FG6: 95.2 | FH6: 95 | FI6: 94.8 | FJ6: 94.7 | FK6: 94.8 | FL6: 94.2 | FM6: 94.9 | FN6: 95.7 | FO6: 96.7 | FP6: 98.4 | FQ6: 98.6 | FR6: 98 | FS6: 98 | FT6: 100.5 | FU6: 100.6 | FV6: 100 | FW6: 100.7 | FX6: 100.3 | FY6: 99.5 | FZ6: 99.7 | GA6: 99.9 | GB6: 100.4 | GC6: 98.8 | GD6: 99.6 | GE6: 99.8 | GF6: 100 | GG6: 100.5 | GH6: 100.4 | GI6: 100.9 | GJ6: 100.4 | GK6: 100.7 | GL6: 100.3 | GM6: 100.6 | GN6: 100.8 | GO6: 100 | GP6: 99.6 | GQ6: 98.4 | GR6: 98.9 | GS6: 98.8 | GT6: 99.4 | GU6: 99.3 | GV6: 99.7 | GW6: 98.023641 | GX6: 98.023641 | GY6: 97.207036 | GZ6: 98.893564 | HA6: 99.1441 | HB6: 98.12135 | HC6: 99.612839 | HD6: 99.88718 | HE6: 98.955141 | HF6: 100.00152 | HG6: 101.09825 | HH6: 100.49676 | HI6: 103.55503 | HJ6: 104.22408 | HK6: 105.12191 | HL6: 104.84071 | HM6: 107.97665 | HN6: 107.79655 | HO6: 109.47137 | HP6: 110.60802 | HQ6: 112.12377 | HR6: 114.03745 | HS6: 117.85216 | HT6: 114.68193 | HU6: 116.60489 | HV6: 116.74122 | HW6: 116.69726 | HX6: 116.37802 | HY6: 118.19505 | HZ6: 121.13635 | IA6: 124.46553 | IB6: 123.71518 | IC6: 124.41829 | ID6: 124.91507 | IE6: 125.03037 | IF6: 123.21942 | IG6: 125.29115 | IH6: 126.5903 | II6: 124.79981 | IJ6: 125.18665 | IK6: 126.72398 | IL6: 129.18648 | IM6: 132.41933 | IN6: 128.84887 | IO6: 127.01434 | IP6: 126.22508 | IQ6: 125.46827 | IR6: 129.3 | IS6: 132.85546 | IT6: 133.44605 | IU6: 129.8002 | IV6: 129.05528 | IW6: 129.4115 | IX6: 130.34551 | IY6: 133.79223 | IZ6: 131.17618 | JA6: 130.15206 | JB6: 130.56967 | JC6: 130.5 | JD6: 133.8 | JE6: 136.9 | JF6: 136.1 | JG6: 133 | JH6: 134.9 | JI6: 136.5 | JJ6: 140.7 | JK6: 143.3
A7: Imported (Composition) | JJ7: 68.7 | JK7: =JK6*JL7 -> 69.5 | JL7: 0.48499651
A8: Local (Composition) | JJ8: =JJ6-JJ7 -> 72 | JK8: =JK6-JK7 -> 73.8 | JL8: =1-JL7 -> 0.51500349
A10: Annual Inflation rate | FD10: =IH6/FB6-1 -> 0.4065589 | FN10: =(FN6/FB6-1)*10^2 -> 6.3333333 | FO10: =(FO6/FC6-1)*10^2 -> 3.6441586 | FP10: =(FP6/FD6-1)*10^2 -> 5.0160085 | FQ10: =(FQ6/FE6-1)*10^2 -> 4.670913 | FR10: =(FR6/FF6-1)*10^2 -> 3.7037037 | FS10: =(FS6/FG6-1)*10^2 -> 2.9411765 | FT10: =(FT6/FH6-1)*10^2 -> 5.7894737 | FU10: =(FU6/FI6-1)*10^2 -> 6.1181435 | ... JK10: =(JK6/IY6-1)*10^2 -> 7.1063671
A11: Monthly inflation rate | GX11: =(GX6/GW6-1)*100 -> 0 | GY11: =(GY6/GX6-1)*100 -> -0.83306988 | GZ11: =(GZ6/GY6-1)*100 -> 1.7349859 | HA11: =(HA6/GZ6-1)*100 -> 0.2533394 | HB11: =(HB6/HA6-1)*100 -> -1.0315792 | HC11: =(HC6/HB6-1)*100 -> 1.5200451 | HD11: =(HD6/HC6-1)*100 -> 0.27540721 | HE11: =(HE6/HD6-1)*100 -> -0.93309156 | ... JK11: =(JK6/JJ6-1)*100 -> 1.8479033
A13: Imported inflation (yoy) | GX13: =(GX17/GL17-1)*100 -> -4.7480504 | GY13: =(GY17/GM17-1)*100 -> -3.8701279 | GZ13: =(GZ17/GN17-1)*100 -> -2.685668 | HA13: =(HA17/GO17-1)*100 -> -2.0353906 | HB13: =(HB17/GP17-1)*100 -> -0.67590702 | HC13: =(HC17/GQ17-1)*100 -> 0.63804243 | HD13: =(HD17/GR17-1)*100 -> -1.0955541 | HE13: =(HE17/GS17-1)*100 -> -1.2792243 | ... JK13: =(JK17/IY17-1)*100 -> 13.128696
A14: Local Inflation (yoy) | GX14: =(GX18/GL18-1)*100 -> 0.45012126 | GY14: =(GY18/GM18-1)*100 -> -2.9549981 | GZ14: =(GZ18/GN18-1)*100 -> -0.95903174 | HA14: =(HA18/GO18-1)*100 -> 0.5624969 | HB14: =(HB18/GP18-1)*100 -> -2.4494703 | HC14: =(HC18/GQ18-1)*100 -> 1.8540762 | HD14: =(HD18/GR18-1)*100 -> 3.5098799 | HE14: =(HE18/GS18-1)*100 -> 2.0347597 | ... JK14: =(JK18/IY18-1)*100 -> 1.9408769
A16: Component
A17: Imported | FB17: 88.8 | FC17: 90.4 | FD17: 90.9 | FE17: 90.8 | FF17: 91 | FG17: 91.6 | FH17: 92.9 | FI17: 94.1 | FJ17: 94.9 | FK17: 95.7 | FL17: 95.5 | FM17: 95.9 | FN17: 97 | FO17: 97.7 | FP17: 97.6 | FQ17: 97.4 | FR17: 97.8 | FS17: 98.2 | FT17: 99.2 | FU17: 99.3 | FV17: 100 | FW17: 100.3 | FX17: 99.9 | FY17: 98.7 | FZ17: 97.3 | GA17: 96.8 | GB17: 97.1 | GC17: 97.7 | GD17: 99.5 | GE17: 100.1 | GF17: 100.3 | GG17: 101.1 | GH17: 101.6 | GI17: 101.8 | GJ17: 101 | GK17: 100.7 | GL17: 100.7 | GM17: 100.8 | GN17: 100.9 | GO17: 100.9 | GP17: 99.7 | GQ17: 98.5 | GR17: 100.2 | GS17: 100.9 | GT17: 101.1 | GU17: 101.3 | GV17: 101.3 | GW17: 95.918713 | GX17: 95.918713 | GY17: 96.898911 | GZ17: 98.190161 | HA17: 98.846291 | HB17: 99.026121 | HC17: 99.128472 | HD17: 99.102255 | HE17: 99.609263 | HF17: 100 | HG17: 100.60325 | HH17: 101.75136 | HI17: 102.81623 | HJ17: 102.72151 | HK17: 103.50314 | HL17: 104.7645 | HM17: 107.819 | HN17: 108.79657 | HO17: 109.89632 | HP17: 111.86065 | HQ17: 111.37176 | HR17: 110.54645 | HS17: 109.86353 | HT17: 109.85783 | HU17: 109.75757 | HV17: 109.33471 | HW17: 110.6543 | HX17: 111.08537 | HY17: 111.37781 | HZ17: 111.77172 | IA17: 113.967 | IB17: 113.82744 | IC17: 114.23363 | ID17: 115.72693 | IE17: 115.70226 | IF17: 115.43426 | IG17: 114.63036 | IH17: 114.0552 | II17: 114.57721 | IJ17: 114.89513 | IK17: 115.11907 | IL17: 115.35839 | IM17: 116.02094 | IN17: 115.25291 | IO17: 115.74924 | IP17: 116.41254 | IQ17: 115.62305 | IR17: 116.67692 | IS17: 120.65525 | IT17: 118.01683 | IU17: 118.25464 | IV17: 118.41371 | IW17: 118.75277 | IX17: 119.49674 | IY17: 119.50991 | IZ17: 119.66233 | JA17: 120.30422 | JB17: 120.46506 | JC17: 120.3 | JD17: 126 | JE17: 127.3 | JF17: 125.1 | JG17: 123.8 | JH17: 126.6 | JI17: 129.3 | JJ17: 133.5 | JK17: 135.2 | JM17: 133.5
A18: Local | FB18: 91.7 | FC18: 97.5 | FD18: 97.6 | FE18: 98.9 | FF18: 99.3 | FG18: 100.2 | FH18: 97.8 | FI18: 95.9 | FJ18: 94.6 | FK18: 93.6 | FL18: 92.6 | FM18: 93.6 | FN18: 94.2 | FO18: 95.6 | FP18: 99.3 | FQ18: 100 | FR18: 98.2 | FS18: 97.8 | FT18: 102.1 | FU18: 102.2 | FV18: 100 | FW18: 101.1 | FX18: 100.8 | FY18: 100.3 | FZ18: 102.8 | GA18: 103.7 | GB18: 104.3 | GC18: 99.9 | GD18: 99.7 | GE18: 99.4 | GF18: 99.6 | GG18: 99.6 | GH18: 98.9 | GI18: 99.8 | GJ18: 99.7 | GK18: 100.4 | GL18: 99.8 | GM18: 100.5 | GN18: 100.6 | GO18: 98.9 | GP18: 99.6 | GQ18: 98.3 | GR18: 97.3 | GS18: 96.3 | GT18: 97.4 | GU18: 96.9 | GV18: 97.6 | GW18: 100.24922 | GX18: 100.24922 | GY18: 97.530227 | GZ18: 99.635214 | HA18: 99.456309 | HB18: 97.160328 | HC18: 100.12256 | HD18: 100.71511 | HE18: 98.259474 | HF18: 100 | HG18: 101.61917 | HH18: 99.165278 | HI18: 104.33402 | HJ18: 105.8117 | HK18: 106.83254 | HL18: 104.91812 | HM18: 108.14019 | HN18: 106.73438 | HO18: 109.01801 | HP18: 109.27831 | HQ18: 112.91648 | HR18: 117.73008 | HS18: 126.30664 | HT18: 119.78599 | HU18: 123.85103 | HV18: 124.57941 | HW18: 123.09176 | HX18: 121.97811 | HY18: 125.40928 | HZ18: 131.04761 | IA18: 135.57724 | IB18: 134.18021 | IC18: 135.19768 | ID18: 134.63934 | IE18: 134.90286 | IF18: 131.45831 | IG18: 136.57463 | IH18: 139.85822 | II18: 135.61935 | IJ18: 136.07916 | IK18: 139.00703 | IL18: 136.07916 | IM18: 149.77742 | IN18: 143.23993 | IO18: 138.93759 | IP18: 136.61043 | IQ18: 135.88823 | IR18: 140.56464 | IS18: 145.76859 | IT18: 149.77798 | IU18: 142.03504 | IV18: 140.31828 | IW18: 140.69267 | IX18: 141.82785 | IY18: 148.90984 | IZ18: 143.36267 | JA18: 140.57467 | JB18: 141.26412 | JC18: 141.2 | JD18: 142.4 | JE18: 147.1 | JF18: 146.7 | JG18: 142.7 | JH18: 143.8 | JI18: 144.2 | JJ18: 148.2 | JK18: 151.8 | JO18: 2021
A20: PACCOICOP groups (proportion of all items)
A21: Food and non-alcoholic beverages | FJ21: 94.3 | FK21: 93.9 | FL21: 91.8 | FM21: 92.7 | FN21: 94.1 | FO21: 96.3 | FP21: 100.4 | FQ21: 100.8 | FR21: 98.7 | FS21: 97.6 | FT21: 101.2 | FU21: 100.8 | FV21: 100 | FW21: 101.2 | FX21: 99.8 | FY21: 99 | FZ21: 100.1 | GA21: 101.1 | GB21: 102.2 | GC21: 98.1 | GD21: 99.5 | GE21: 99.6 | GF21: 100.8 | GG21: 102.2 | GH21: 102 | GI21: 102.8 | GJ21: 100.7 | GK21: 101.4 | GL21: 100.5 | GM21: 101.6 | GN21: 102.3 | GO21: 102.8 | GP21: 104 | GQ21: 102.6 | GR21: 103.5 | GS21: 102.1 | GT21: 102.9 | GU21: 102.8 | GV21: 103.2 | GW21: 105.2 | GX21: 42.260865 | GY21: 41.12072 | GZ21: 42.48065 | HA21: 42.451648 | HB21: 41.159528 | HC21: 42.812331 | HD21: 42.756259 | HE21: 41.708855 | HF21: 42.608204 | HG21: 43.637565 | HH21: 42.455233 | HI21: 45.162595 | HJ21: 45.704499 | HK21: 46.298752 | HL21: 45.322759 | HM21: 47.335216 | HN21: 46.409909 | HO21: 47.447362 | HP21: 46.586861 | HQ21: 48.423364 | HR21: 49.308024 | HS21: 52.521679 | HT21: 49.09536 | HU21: 51.001231 | HV21: 52.177176 | HW21: 52.184484 | HX21: 51.840365 | HY21: 52.813362 | HZ21: 53.957741 | IA21: 56.467319 | IB21: 56.043983 | IC21: 56.476214 | ID21: 56.196019 | IE21: 55.060667 | IF21: 53.4413 | IG21: 55.90449 | IH21: 57.168305 | II21: 55.383394 | IJ21: 55.529741 | IK21: 57.670927 | IL21: 59.949124 | IM21: 63.125227 | IN21: 59.858991 | IO21: 58.109036 | IP21: 57.138607 | IQ21: 56.393092 | IR21: 59.621101 | IS21: 61.181108 | IT21: 61.351122 | IU21: 57.206953 | IV21: 56.15904 | IW21: 55.853162 | IX21: 56.495352 | IY21: 59.833206 | IZ21: 57.834474 | JA21: 56.692948 | JB21: 57.228651 | JC21: 56.7 | JD21: 57.4 | JE21: 60 | JF21: 59 | JG21: 56.5 | JH21: 56.9 | JI21: 57 | JJ21: 57.7 | JK21: 59.3 | JM21: =JK21/(JO21/10^2) -> 139.20188 | JO21: 42.6
A22: Alcohol beverages, tobacco and kava | FJ22: 85.1 | FK22: 85.6 | FL22: 85.8 | FM22: 86.2 | FN22: 85.8 | FO22: 85.8 | FP22: 86.2 | FQ22: 87.1 | FR22: 88.4 | FS22: 91 | FT22: 96.7 | FU22: 99.3 | FV22: 100 | FW22: 99.6 | FX22: 99.8 | FY22: 99.6 | FZ22: 100.1 | GA22: 100.2 | GB22: 99.7 | GC22: 98.1 | GD22: 97.7 | GE22: 97.2 | GF22: 97.5 | GG22: 97.3 | GH22: 96.8 | GI22: 96.5 | GJ22: 96.6 | GK22: 95.1 | GL22: 95.5 | GM22: 94.7 | GN22: 94.7 | GO22: 93.9 | GP22: 95.5 | GQ22: 99.4 | GR22: 100.3 | GS22: 100.3 | GT22: 100.4 | GU22: 100 | GV22: 100.1 | GW22: 100.3 | GX22: 5.6918377 | GY22: 5.6901778 | GZ22: 5.6928128 | HA22: 5.6918253 | HB22: 5.6933655 | HC22: 5.5391992 | HD22: 5.5409965 | HE22: 5.5428057 | HF22: 5.5985062 | HG22: 5.4460122 | HH22: 5.443924 | HI22: 5.5286314 | HJ22: 5.4653847 | HK22: 5.4729647 | HL22: 5.5617397 | HM22: 5.5633521 | HN22: 5.6256677 | HO22: 5.6724782 | HP22: 5.734255 | HQ22: 5.731175 | HR22: 5.7279617 | HS22: 5.7203538 | HT22: 5.7324998 | HU22: 5.7430099 | HV22: 5.7309259 | HW22: 5.6444392 | HX22: 5.7029064 | HY22: 5.7068371 | HZ22: 5.6960558 | IA22: 5.7035632 | IB22: 5.7304807 | IC22: 5.7374316 | ID22: 5.7380066 | IE22: 6.0269462 | IF22: 5.9681569 | IG22: 5.9615295 | IH22: 5.9682426 | II22: 5.964834 | IJ22: 5.9626691 | IK22: 5.949148 | IL22: 5.9616725 | IM22: 6.0453964 | IN22: 6.8731412 | IO22: 6.9846158 | IP22: 6.9814198 | IQ22: 7.2495198 | IR22: 7.2312376 | IS22: 7.2372125 | IT22: 7.4035607 | IU22: 7.85072 | IV22: 7.8293764 | IW22: 7.907721 | IX22: 7.9915733 | IY22: 8.2342695 | IZ22: 8.3326599 | JA22: 8.3409728 | JB22: 8.3385842 | JC22: 8.5 | JD22: 8.6 | JE22: 8.8 | JF22: 8.8 | JG22: 8.9 | JH22: 8.9 | JI22: 9 | JJ22: 9 | JK22: 9 | JM22: =JK22/(JO22/10^2) -> 160.71429 | JO22: 5.6
A23: Clothing and footwear | FJ23: 95 | FK23: 96 | FL23: 96.1 | FM23: 96.1 | FN23: 98.2 | FO23: 98.2 | FP23: 98.2 | FQ23: 98.2 | FR23: 98.2 | FS23: 97.8 | FT23: 99.2 | FU23: 99.6 | FV23: 100 | FW23: 100.1 | FX23: 100.3 | FY23: 100.3 | FZ23: 102.6 | GA23: 102.9 | GB23: 101.5 | GC23: 101.5 | GD23: 101.5 | GE23: 101.5 | GF23: 102.1 | GG23: 102.1 | GH23: 103.8 | GI23: 103.8 | GJ23: 103.9 | GK23: 104.3 | GL23: 105.5 | GM23: 106.1 | GN23: 106.1 | GO23: 106.5 | GP23: 108.8 | GQ23: 109.1 | GR23: 109.1 | GS23: 110.5 | GT23: 110.5 | GU23: 112.6 | GV23: 112.6 | GW23: 112.6 | GX23: 2.841289 | GY23: 2.8345268 | GZ23: 2.8363482 | HA23: 2.8363482 | HB23: 2.8389322 | HC23: 2.8389322 | HD23: 2.8389322 | HE23: 2.8394721 | HF23: 2.8449004 | HG23: 2.8449004 | HH23: 2.8449004 | HI23: 2.8449004 | HJ23: 2.853566 | HK23: 2.853566 | HL23: 2.853566 | HM23: 2.853566 | HN23: 2.9064457 | HO23: 2.9120447 | HP23: 2.9169392 | HQ23: 2.9161474 | HR23: 2.9161474 | HS23: 2.8878012 | HT23: 2.8878012 | HU23: 2.8862627 | HV23: 2.8862627 | HW23: 2.8817061 | HX23: 2.8192465 | HY23: 2.8694283 | HZ23: 2.9778651 | IA23: 3.1189158 | IB23: 3.1224656 | IC23: 3.1157212 | ID23: 3.1273942 | IE23: 3.0770363 | IF23: 3.0770363 | IG23: 3.0770363 | IH23: 3.0259074 | II23: 3.0328323 | IJ23: 3.0417509 | IK23: 3.0417509 | IL23: 3.0417509 | IM23: 3.00061 | IN23: 3.1471886 | IO23: 3.1601812 | IP23: 3.1680191 | IQ23: 3.2630289 | IR23: 3.265285 | IS23: 3.3490705 | IT23: 3.4705854 | IU23: 3.455129 | IV23: 3.4183149 | IW23: 3.4221561 | IX23: 3.6215561 | IY23: 3.6734886 | IZ23: 3.6802206 | JA23: 3.6859602 | JB23: 3.6790747 | JC23: 3.7 | JD23: 3.7 | JE23: 3.7 | JF23: 3.7 | JG23: 3.7 | JH23: 3.7 | JI23: 3.7 | JJ23: 3.7 | JK23: 2.8 | JM23: =JK23/(JO23/10^2) -> 100 | JO23: 2.8
A24: Housing, water, electricity and gas | FJ24: 98.1 | FK24: 97.6 | FL24: 97.7 | FM24: 98.3 | FN24: 98.6 | FO24: 99.9 | FP24: 99.9 | FQ24: 99.8 | FR24: 99.4 | FS24: 99.4 | FT24: 99.4 | FU24: 99.5 | FV24: 100 | FW24: 100.5 | FX24: 100.2 | FY24: 100.5 | FZ24: 101 | GA24: 101.5 | GB24: 100.9 | GC24: 98.9 | GD24: 98.9 | GE24: 100.2 | GF24: 100.3 | GG24: 100.3 | GH24: 99 | GI24: 100 | GJ24: 100.4 | GK24: 100.8 | GL24: 100.5 | GM24: 100.6 | GN24: 102.6 | GO24: 98.9 | GP24: 99.2 | GQ24: 96.9 | GR24: 89.7 | GS24: 89.2 | GT24: 89.2 | GU24: 89.1 | GV24: 90.6 | GW24: 93.8 | GX24: 5.7983162 | GY24: 5.8517267 | GZ24: 5.9634479 | HA24: 5.9856916 | HB24: 6.1685255 | HC24: 6.1787632 | HD24: 6.5743021 | HE24: 6.6417412 | HF24: 6.6275093 | HG24: 6.6931389 | HH24: 7.0419333 | HI24: 7.0127598 | HJ24: 7.2770332 | HK24: 7.4241708 | HL24: 7.5592827 | HM24: 7.9110405 | HN24: 8.1830022 | HO24: 8.3611228 | HP24: 9.4284189 | HQ24: 9.157157 | HR24: 9.1099395 | HS24: 9.3185951 | HT24: 9.3450114 | HU24: 9.266582 | HV24: 8.3001372 | HW24: 8.3211567 | HX24: 8.2526946 | HY24: 7.6914538 | HZ24: 7.7122163 | IA24: 7.6023917 | IB24: 7.4008001 | IC24: 7.5418449 | ID24: 7.797685 | IE24: 8.402139 | IF24: 8.2825805 | IG24: 8.1586326 | IH24: 8.3922841 | II24: 8.4301944 | IJ24: 8.4648011 | IK24: 7.741501 | IL24: 7.741501 | IM24: 7.6879338 | IN24: 7.9334737 | IO24: 7.9474304 | IP24: 7.9144016 | IQ24: 7.7317224 | IR24: 7.5841352 | IS24: 7.5533323 | IT24: 7.4973035 | IU24: 7.5148195 | IV24: 7.5638017 | IW24: 7.952124 | IX24: 7.9312841 | IY24: 7.846248 | IZ24: 7.2040623 | JA24: 7.2215792 | JB24: 7.2497337 | JC24: 7.6 | JD24: 7.6 | JE24: 7.6 | JF24: 7.5 | JG24: 7.5 | JH24: 7.4 | JI24: 7.9 | JJ24: 9.9 | JK24: 10.3 | JM24: =JK24/(JO24/10^2) -> 156.06061 | JO24: 6.6
A25: Furnishing, household equipment and hosehold maintenance | FJ25: 99.7 | FK25: 98 | FL25: 99.2 | FM25: 99 | FN25: 99 | FO25: 99.1 | FP25: 99.5 | FQ25: 99.1 | FR25: 99.1 | FS25: 98.9 | FT25: 99.3 | FU25: 99.5 | FV25: 100 | FW25: 99.7 | FX25: 99.7 | FY25: 99.5 | FZ25: 99.8 | GA25: 100.1 | GB25: 100.5 | GC25: 100.6 | GD25: 100.7 | GE25: 100.8 | GF25: 101.7 | GG25: 101.7 | GH25: 102 | GI25: 102 | GJ25: 102.1 | GK25: 100.5 | GL25: 100.5 | GM25: 100.2 | GN25: 100.3 | GO25: 102.2 | GP25: 103.3 | GQ25: 103.3 | GR25: 102.5 | GS25: 102.5 | GT25: 102.7 | GU25: 103.4 | GV25: 104.1 | GW25: 104.4 | GX25: 3.1275623 | GY25: 3.1275623 | GZ25: 3.1275623 | HA25: 3.1275623 | HB25: 3.1284488 | HC25: 3.1284488 | HD25: 3.1543384 | HE25: 3.160267 | HF25: 3.1671874 | HG25: 3.1671874 | HH25: 3.1671874 | HI25: 3.202811 | HJ25: 3.2204244 | HK25: 3.2301986 | HL25: 3.231427 | HM25: 3.3193132 | HN25: 3.3239982 | HO25: 3.3239982 | HP25: 3.3084324 | HQ25: 3.3036061 | HR25: 3.3036061 | HS25: 3.3036061 | HT25: 3.3171271 | HU25: 3.329075 | HV25: 3.3232195 | HW25: 3.3475704 | HX25: 3.3687442 | HY25: 3.3678663 | HZ25: 3.3684822 | IA25: 3.4551445 | IB25: 3.4519756 | IC25: 3.5181295 | ID25: 3.593063 | IE25: 3.5875302 | IF25: 3.5843442 | IG25: 3.58494 | IH25: 3.6173872 | II25: 3.6158102 | IJ25: 3.5934891 | IK25: 3.5914033 | IL25: 3.6263285 | IM25: 3.6855669 | IN25: 3.7329362 | IO25: 3.7322236 | IP25: 3.7794175 | IQ25: 3.9233831 | IR25: 4.0405841 | IS25: 4.0876048 | IT25: 4.0814972 | IU25: 4.0831056 | IV25: 4.1224019 | IW25: 4.1595872 | IX25: 4.2103995 | IY25: 4.2364268 | IZ25: 4.2141864 | JA25: 4.2002369 | JB25: 4.1741671 | JC25: 4.2 | JD25: 4.3 | JE25: 4.3 | JF25: 4.3 | JG25: 4.2 | JH25: 4.2 | JI25: 4.2 | JJ25: 4.2 | JK25: 4.2 | JM25: =JK25/(JO25/10^2) -> 131.25 | JO25: 3.2
A26: Health | FJ26: 99.3 | FK26: 99.3 | FL26: 99.3 | FM26: 99.3 | FN26: 101.7 | FO26: 101.7 | FP26: 101.7 | FQ26: 101.7 | FR26: 101.7 | FS26: 101.7 | FT26: 101.7 | FU26: 100 | FV26: 100 | FW26: 100 | FX26: 100 | FY26: 100 | FZ26: 100 | GA26: 100 | GB26: 100 | GC26: 100 | GD26: 100 | GE26: 100 | GF26: 100 | GG26: 100 | GH26: 100 | GI26: 100 | GJ26: 100 | GK26: 100 | GL26: 100 | GM26: 100 | GN26: 100 | GO26: 100 | GP26: 100 | GQ26: 100 | GR26: 100 | GS26: 100 | GT26: 100 | GU26: 100 | GV26: 100 | GW26: 100 | GX26: 0.16781668 | GY26: 0.16781668 | GZ26: 0.16781668 | HA26: 0.16781668 | HB26: 0.16781668 | HC26: 0.16781668 | HD26: 0.16781668 | HE26: 0.16781668 | HF26: 0.16781668 | HG26: 0.16781668 | HH26: 0.16781668 | HI26: 0.16781668 | HJ26: 0.16781668 | HK26: 0.16781668 | HL26: 0.16781668 | HM26: 0.16781668 | HN26: 0.16781668 | HO26: 0.16781668 | HP26: 0.16781668 | HQ26: 0.19474225 | HR26: 0.21744155 | HS26: 0.21744155 | HT26: 0.21744155 | HU26: 0.21744155 | HV26: 0.21744155 | HW26: 0.21744155 | HX26: 0.21744155 | HY26: 0.21744155 | HZ26: 0.21744155 | IA26: 0.21744155 | IB26: 0.21744155 | IC26: 0.21744155 | ID26: 0.21744155 | IE26: 0.21744155 | IF26: 0.21744155 | IG26: 0.21744155 | IH26: 0.21744155 | II26: 0.21744155 | IJ26: 0.21744155 | IK26: 0.21744155 | IL26: 0.21744155 | IM26: 0.21744155 | IN26: 0.21744155 | IO26: 0.21493152 | IP26: 0.21493152 | IQ26: 0.21493152 | IR26: 0.21493152 | IS26: 0.21493152 | IT26: 0.21493152 | IU26: 0.21493152 | IV26: 0.21597602 | IW26: 0.21597602 | IX26: 0.21597602 | IY26: 0.21597602 | IZ26: 0.21597602 | JA26: 0.21597602 | JB26: 0.21493152 | JC26: 0.2 | JD26: 0.2 | JE26: 0.2 | JF26: 0.2 | JG26: 0.2 | JH26: 0.2 | JI26: 0.2 | JJ26: 0.2 | JK26: 0.2 | JM26: =JK26/(JO26/10^2) -> 100 | JO26: 0.2
A27: Transportation | FJ27: 90.6 | FK27: 92 | FL27: 93.1 | FM27: 94.6 | FN27: 96 | FO27: 96.1 | FP27: 96.3 | FQ27: 96.1 | FR27: 97 | FS27: 98.1 | FT27: 100.4 | FU27: 99.8 | FV27: 100 | FW27: 101.1 | FX27: 102.2 | FY27: 98.5 | FZ27: 94.4 | GA27: 92.4 | GB27: 93.9 | GC27: 96.3 | GD27: 98.5 | GE27: 99 | GF27: 97.1 | GG27: 96.4 | GH27: 97.4 | GI27: 98.3 | GJ27: 99.4 | GK27: 99.7 | GL27: 99.7 | GM27: 99.6 | GN27: 97.4 | GO27: 94.7 | GP27: 87.6 | GQ27: 82.3 | GR27: 87.2 | GS27: 90.2 | GT27: 91.8 | GU27: 91.6 | GV27: 91.3 | GW27: 91.5 | GX27: 12.41416 | GY27: 12.646262 | GZ27: 12.85735 | HA27: 13.044616 | HB27: 13.128057 | HC27: 13.119463 | HD27: 13.033305 | HE27: 13.078559 | HF27: 13.17626 | HG27: 13.226074 | HH27: 13.464128 | HI27: 13.644573 | HJ27: 13.52471 | HK27: 13.602301 | HL27: 14.063187 | HM27: 14.662248 | HN27: 14.965151 | HO27: 15.365363 | HP27: 15.545854 | HQ27: 15.41069 | HR27: 15.361056 | HS27: 15.183885 | HT27: 15.365104 | HU27: 15.410216 | HV27: 15.273609 | HW27: 15.182273 | HX27: 15.251332 | HY27: 15.204879 | HZ27: 15.166296 | IA27: 15.862663 | IB27: 15.69421 | IC27: 15.752046 | ID27: 16.10904 | IE27: 16.525223 | IF27: 16.508204 | IG27: 16.239301 | IH27: 16.008128 | II27: 15.948879 | IJ27: 16.156572 | IK27: 16.291309 | IL27: 16.352698 | IM27: 16.282375 | IN27: 16.081741 | IO27: 16.165965 | IP27: 16.167832 | IQ27: 15.67882 | IR27: 15.670064 | IS27: 17.561518 | IT27: 15.887161 | IU27: 15.933104 | IV27: 16.265499 | IW27: 16.411582 | IX27: 16.341515 | IY27: 16.171763 | IZ27: 15.973533 | JA27: 16.046001 | JB27: 15.817046 | JC27: 15.8 | JD27: 17.9 | JE27: 18.2 | JF27: 16.8 | JG27: 16.5 | JH27: 18 | JI27: 18.9 | JJ27: 20.2 | JK27: 20.6 | JM27: =JK27/(JO27/10^2) -> 156.06061 | JO27: 13.2
A28: Communications | FJ28: 111.6 | FK28: 111.6 | FL28: 111.6 | FM28: 111.6 | FN28: 111.6 | FO28: 111.6 | FP28: 109.3 | FQ28: 109.3 | FR28: 109.3 | FS28: 109.3 | FT28: 109.3 | FU28: 109.3 | FV28: 100 | FW28: 100 | FX28: 100 | FY28: 100 | FZ28: 100 | GA28: 100 | GB28: 100 | GC28: 100 | GD28: 100 | GE28: 100 | GF28: 100 | GG28: 100 | GH28: 100 | GI28: 100 | GJ28: 101.6 | GK28: 101.6 | GL28: 101.6 | GM28: 101.6 | GN28: 101.6 | GO28: 99.9 | GP28: 99.9 | GQ28: 99.9 | GR28: 99.9 | GS28: 99.9 | GT28: 99.9 | GU28: 99.9 | GV28: 99.9 | GW28: 99.9 | GX28: 3.6946544 | GY28: 3.6997401 | GZ28: 3.6949957 | HA28: 3.6931064 | HB28: 3.6916981 | HC28: 3.6765056 | HD28: 3.6664698 | HE28: 3.659714 | HF28: 3.6552832 | HG28: 3.6599417 | HH28: 3.656026 | HI28: 3.651455 | HJ28: 3.654308 | HK28: 3.6527552 | HL28: 3.6615468 | HM28: 3.6645991 | HN28: 3.6529318 | HO28: 3.6533524 | HP28: 3.6462075 | HQ28: 3.6509208 | HR28: 3.6476797 | HS28: 4.2496462 | HT28: 4.2565556 | HU28: 4.2569751 | HV28: 4.2674799 | HW28: 4.2676402 | HX28: 4.2553998 | HY28: 4.2561623 | HZ28: 4.2532776 | IA28: 4.2554758 | IB28: 4.2547104 | IC28: 4.2434413 | ID28: 4.2497211 | IE28: 4.2457143 | IF28: 4.2526781 | IG28: 4.2607953 | IH28: 4.2594928 | II28: 4.2530833 | IJ28: 4.2545137 | IK28: 4.2555667 | IL28: 4.2555667 | IM28: 4.251768 | IN28: 4.251768 | IO28: 4.237208 | IP28: 4.237208 | IQ28: 4.2709286 | IR28: 4.2709286 | IS28: 4.2447525 | IT28: 4.2420342 | IU28: 4.2420342 | IV28: 4.2270764 | IW28: 4.2270764 | IX28: 4.2419868 | IY28: 4.2419868 | IZ28: 4.2419868 | JA28: 4.2419868 | JB28: 4.2419868 | JC28: 4.2 | JD28: 4.2 | JE28: 4.2 | JF28: 4.2 | JG28: 4.2 | JH28: 4.2 | JI28: 4.2 | JJ28: 4.2 | JK28: 4.2 | JM28: =JK28/(JO28/10^2) -> 113.51351 | JO28: 3.7
A29: Recreation and culture | FJ29: 99.9 | FK29: 99.9 | FL29: 99.9 | FM29: 99.9 | FN29: 100 | FO29: 100 | FP29: 100 | FQ29: 100 | FR29: 100 | FS29: 100 | FT29: 100 | FU29: 100 | FV29: 100 | FW29: 100 | FX29: 100 | FY29: 100 | FZ29: 103.6 | GA29: 103.6 | GB29: 103.6 | GC29: 103.6 | GD29: 103.6 | GE29: 103.6 | GF29: 103.6 | GG29: 103.6 | GH29: 103.6 | GI29: 103.6 | GJ29: 103.6 | GK29: 103.6 | GL29: 103.6 | GM29: 103.6 | GN29: 103.6 | GO29: 103.6 | GP29: 103.6 | GQ29: 103.6 | GR29: 103.6 | GS29: 103.6 | GT29: 103.6 | GU29: 103.6 | GV29: 103.6 | GW29: 103.6 | GX29: 0.64037914 | GY29: 0.64651885 | GZ29: 0.64709269 | HA29: 0.64709269 | HB29: 0.64658535 | HC29: 0.64698949 | HD29: 0.64854284 | HE29: 0.64969391 | HF29: 0.64963755 | HG29: 0.64963755 | HH29: 0.64963755 | HI29: 0.66379559 | HJ29: 0.66422639 | HK29: 0.66422639 | HL29: 0.66422639 | HM29: 0.67767266 | HN29: 0.67761722 | HO29: 0.67986613 | HP29: 0.68391648 | HQ29: 0.68485115 | HR29: 0.68559754 | HS29: 0.68559754 | HT29: 0.68495723 | HU29: 0.68365712 | HV29: 0.6860363 | HW29: 0.68686828 | HX29: 0.68686828 | HY29: 0.68729324 | HZ29: 0.72637162 | IA29: 0.72550996 | IB29: 0.72397927 | IC29: 0.72682262 | ID29: 0.72682262 | IE29: 0.72758636 | IF29: 0.72758636 | IG29: 0.72689776 | IH29: 0.72492395 | II29: 0.72492395 | IJ29: 0.73429921 | IK29: 0.73553735 | IL29: 0.73596493 | IM29: 0.73708552 | IN29: 0.73708552 | IO29: 0.73708552 | IP29: 0.73708552 | IQ29: 0.78062159 | IR29: 0.78062159 | IS29: 0.78062159 | IT29: 0.79224163 | IU29: 0.79224163 | IV29: 0.80080157 | IW29: 0.78884683 | IX29: 0.87757909 | IY29: 0.88875337 | IZ29: 0.85334877 | JA29: 0.82196845 | JB29: 0.80216057 | JC29: 0.8 | JD29: 0.8 | JE29: 0.8 | JF29: 0.8 | JG29: 0.8 | JH29: 0.8 | JI29: 0.8 | JJ29: 0.8 | JK29: 0.8 | JM29: =JK29/(JO29/10^2) -> 133.33333 | JO29: 0.6
