Workbook

Sheet Charts
A1: Revenue | I1: Outturn (R)
A2: Projection vintages - level | I2: Projection vintages - % of GDP | Q2: Budget-Year Forecast Errors:
T3: 7-yr avg | U3: 4-yr avg | W3: Min | X3: Max
Q5: % of Outturn | T5: =Lookup!R117 -> -0.10094511 | U5: =Lookup!U117 -> -0.021419577 | W5: =MIN(Lookup!F117:L117) -> -0.26793075 | X5: =MAX(Lookup!F117:L117) -> 0.0071622145
Q7: % of GDP | T7: =Lookup!R145 -> -0.071401612 | U7: =Lookup!U145 -> -0.037469924 | W7: =MIN(Lookup!F145:L145) -> -0.17024153 | X7: =MAX(Lookup!F152:L152) -> 0.17024153
Q9: Growth rate | T9: =Lookup!R131 -> -0.16639734 | U9: =Lookup!U131 -> -0.12373188 | W9: =MIN(Lookup!F131:L131) -> -0.31319912 | X9: =MAX(Lookup!F131:L131) -> -0.084477542
A18: Budget-year forecast - level | I18: Budget-year forecast - growth rate | Q18: Forecast error analysis - budget and forward estimates as share of GDP

Sheet Lookup
A1: Level ($T million)
A2: =Charts!A1 -> Revenue | B2: FY2014 | C2: FY2015 | D2: FY2016 | E2: FY2017 | F2: FY2018 | G2: FY2019 | H2: FY2020 | I2: FY2021 | J2: FY2022 | K2: FY2023 | L2: FY2024 | M2: FY2025 | N2: FY2026 | O2: FY2027 | P2: FY2028
A3: Budget 2018 | D3: {=_xlfn.XLOOKUP(Charts!$A$1,'FY2018'!$A$4:$A$51,'FY2018'!$B$4:$F$51)} -> 360.6 | E3: 418.8 | F3: 541.1 | G3: 562 | H3: 565.5
A4: Budget 2019 | E4: {=_xlfn.XLOOKUP(Charts!$A$1,'FY2019'!$A$4:$A$51,'FY2019'!$B$4:$F$51)} -> 439.8 | F4: 447.6 | G4: 615.2 | H4: 624.1 | I4: 562.2
A5: Budget 2020 | F5: {=_xlfn.XLOOKUP(Charts!$A$1,'FY2020'!$A$2:$A$46,'FY2020'!$B$2:$F$46)} -> 457.2 | G5: 514.8 | H5: 578.2 | I5: 554.2 | J5: 529.8
A6: Budget 2021 | G6: {=_xlfn.XLOOKUP(Charts!$A$1,'FY2021'!$A$2:$A$55,'FY2021'!$B$2:$F$55)} -> 485.2 | H6: 435.2 | I6: 512.9 | J6: 502.8 | K6: 556.5
A7: Budget 2022 | H7: {=_xlfn.XLOOKUP(Charts!$A$1,'FY2022'!$A$2:$A$100,'FY2022'!$B$2:$F$100)} -> 494.4 | I7: 469.7 | J7: 572.2 | K7: 496.7 | L7: 472
A8: Budget 2023 | I8: {=_xlfn.XLOOKUP(Charts!$A$1,'FY2023'!$A$2:$A$100,'FY2023'!$B$2:$F$100)} -> 516.6 | J8: 531.7 | K8: 695.2 | L8: 604.1 | M8: 612.2
A9: Budget 2024 | J9: {=_xlfn.XLOOKUP(Charts!$A$1,'FY2024'!$A$2:$A$101,'FY2024'!$B$2:$F$101)} -> 562 | K9: 612.6 | L9: 741.9 | M9: 699.6 | N9: 714
A10: Budget 2025 | K10: {=_xlfn.XLOOKUP(Charts!$A$1,'FY2025'!$A$2:$A$100,'FY2025'!$B$2:$F$100)} -> 652.5 | L10: 681.4 | M10: 870.7 | N10: 820.1 | O10: 787.5
A11: Budget 2026 | L11: {=_xlfn.XLOOKUP(Charts!$A$1,'FY2026'!$A$2:$A$100,'FY2026'!$B$2:$F$100)} -> 735.1 | M11: 840 | N11: 929.7 | O11: 911.5 | P11: 900.4
A14: Outturn | E14: =E4 -> 439.8 | F14: =F5 -> 457.2 | G14: =G6 -> 485.2 | H14: =H7 -> 494.4 | I14: =I8 -> 516.6 | J14: =J9 -> 562 | K14: =K10 -> 652.5 | L14: =L11 -> 735.1
B16: =B2 -> FY2014 | C16: =C2 -> FY2015 | D16: =D2 -> FY2016 | E16: =E2 -> FY2017 | F16: =F2 -> FY2018 | G16: =G2 -> FY2019 | H16: =H2 -> FY2020 | I16: =I2 -> FY2021 | ... P16: =P2 -> FY2028
A17: Budget year forecast | F17: =F3 -> 541.1 | G17: =G4 -> 615.2 | H17: =H5 -> 578.2 | I17: =I6 -> 512.9 | J17: =J7 -> 572.2 | K17: =K8 -> 695.2 | L17: =L9 -> 741.9 | M17: =M10 -> 870.7 | N17: =N11 -> 929.7
A18: Outturn | F18: =F14 -> 457.2 | G18: =G14 -> 485.2 | H18: =H14 -> 494.4 | I18: =I14 -> 516.6 | J18: =J14 -> 562 | K18: =K14 -> 652.5 | L18: =L14 -> 735.1
A20: Error | F20: =(F18-F17)/F18 -> -0.18350831 | G20: =(G18-G17)/G18 -> -0.26793075 | H20: =(H18-H17)/H18 -> -0.16949838 | I20: =(I18-I17)/I18 -> 0.0071622145 | J20: =(J18-J17)/J18 -> -0.018149466 | K20: =(K18-K17)/K18 -> -0.065440613 | L20: =(L18-L17)/L18 -> -0.0092504421
A25: Growth rate (% p.a.)
A26: =Charts!A1 -> Revenue | B26: =B2 -> FY2014 | C26: =C2 -> FY2015 | D26: =D2 -> FY2016 | E26: =E2 -> FY2017 | F26: =F2 -> FY2018 | G26: =G2 -> FY2019 | H26: =H2 -> FY2020 | I26: =I2 -> FY2021 | ... P26: =P2 -> FY2028
A27: =A3 -> Budget 2018 | F27: =F3/E3-1 -> 0.29202483 | G27: =G3/F3-1 -> 0.038625023 | H27: =H3/G3-1 -> 0.006227758
A28: =A4 -> Budget 2019 | G28: =G4/F4-1 -> 0.37444147 | H28: =H4/G4-1 -> 0.01446684 | I28: =I4/H4-1 -> -0.099182823
A29: =A5 -> Budget 2020 | H29: =H5/G5-1 -> 0.12315462 | I29: =I5/H5-1 -> -0.041508129 | J29: =J5/I5-1 -> -0.044027427
A30: =A6 -> Budget 2021 | I30: =I6/H6-1 -> 0.1785386 | J30: =J6/I6-1 -> -0.019691948 | K30: =K6/J6-1 -> 0.10680191
A31: =A7 -> Budget 2022 | J31: =J7/I7-1 -> 0.2182244 | K31: =K7/J7-1 -> -0.13194687 | L31: =L7/K7-1 -> -0.049728206
A32: =A8 -> Budget 2023 | K32: =K8/J8-1 -> 0.30750423 | L32: =L8/K8-1 -> -0.13104143 | M32: =M8/L8-1 -> 0.013408376
A33: =A9 -> Budget 2024 | L33: =L9/K9-1 -> 0.21106758 | M33: =M9/L9-1 -> -0.05701577 | N33: =N9/M9-1 -> 0.02058319
A34: =A10 -> Budget 2025 | M34: =M10/L10-1 -> 0.27781039 | N34: =N10/M10-1 -> -0.058114161 | O34: =O10/N10-1 -> -0.03975125
A35: =A11 -> Budget 2026 | N35: =N11/M11-1 -> 0.10678571 | O35: =O11/N11-1 -> -0.019576207 | P35: =P11/O11-1 -> -0.012177729
A38: =A14 -> Outturn | F38: =F14/E14-1 -> 0.039563438 | G38: =G14/F14-1 -> 0.061242345 | H38: =H14/G14-1 -> 0.018961253 | I38: =I14/H14-1 -> 0.044902913 | J38: =J14/I14-1 -> 0.087882307 | K38: =K14/J14-1 -> 0.16103203 | L38: =L14/K14-1 -> 0.12659004
B40: =B26 -> FY2014 | C40: =C26 -> FY2015 | D40: =D26 -> FY2016 | E40: =E26 -> FY2017 | F40: =F26 -> FY2018 | G40: =G26 -> FY2019 | H40: =H26 -> FY2020 | I40: =I26 -> FY2021 | ... P40: =P26 -> FY2028
A41: Budget year forecast | F41: =F27 -> 0.29202483 | G41: =G28 -> 0.37444147 | H41: =H29 -> 0.12315462 | I41: =I30 -> 0.1785386 | J41: =J31 -> 0.2182244 | K41: =K32 -> 0.30750423 | L41: =L33 -> 0.21106758 | M41: =M34 -> 0.27781039 | N41: =N35 -> 0.10678571
A42: Outturn | F42: =F38 -> 0.039563438 | G42: =G38 -> 0.061242345 | H42: =H38 -> 0.018961253 | I42: =I38 -> 0.044902913 | J42: =J38 -> 0.087882307 | K42: =K38 -> 0.16103203 | L42: =L38 -> 0.12659004
A44: Error | F44: =(F42-F41) -> -0.25246139 | G44: =(G42-G41) -> -0.31319912 | H44: =(H42-H41) -> -0.10419337 | I44: =(I42-I41) -> -0.13363569 | J44: =(J42-J41) -> -0.13034209 | K44: =(K42-K41) -> -0.1464722 | L44: =(L42-L41) -> -0.084477542
A50: Chart data
A51: =Charts!A1 -> Revenue | B51: =B2 -> FY2014 | C51: =C2 -> FY2015 | D51: =D2 -> FY2016 | E51: =E2 -> FY2017 | F51: =F2 -> FY2018 | G51: =G2 -> FY2019 | H51: =H2 -> FY2020 | I51: =I2 -> FY2021 | ... P51: =P2 -> FY2028
A52: =A3 -> Budget 2018 | F52: =F3 -> 541.1 | G52: =G3 -> 562 | H52: =H3 -> 565.5
A53: =A4 -> Budget 2019 | G53: =G4 -> 615.2 | H53: =H4 -> 624.1 | I53: =I4 -> 562.2
A54: =A5 -> Budget 2020 | H54: =H5 -> 578.2 | I54: =I5 -> 554.2 | J54: =J5 -> 529.8
A55: =A6 -> Budget 2021 | I55: =I6 -> 512.9 | J55: =J6 -> 502.8 | K55: =K6 -> 556.5
A56: =A7 -> Budget 2022 | J56: =J7 -> 572.2 | K56: =K7 -> 496.7 | L56: =L7 -> 472
A57: =A8 -> Budget 2023 | K57: =K8 -> 695.2 | L57: =L8 -> 604.1 | M57: =M8 -> 612.2
...

Sheet FY2018
A1: Column2 | B1: GOVERNMENT OF TONGA BUDGET STATEMENT FOR YEAR ENDING 30TH JUNE 2018 | C1: Column6 | D1: Column7 | E1: [image]^{/18} 2017 | F1: Column9 | G1: Column10
B2: ANNEX 6-19: GFS PRESENTATION
B3: Actual | C3: Revised | D3: Budget | E3: Projection | F3: Projection
A4: Revenue | B4: 360.6 | C4: 418.8 | D4: 541.1 | E4: 562 | F4: 565.5
A5: Taxes | B5: 184.6 | C5: 200.8 | D5: 247.4 | E5: 252.9 | F5: 261.2
A6: Taxes on income, profits, and capital gains | B6: 35.8 | C6: 34.7 | D6: 38.1 | E6: 38.1 | F6: 38.1
A7: Taxes on property | B7: 0.3 | C7: 0.3 | D7: 0.9 | E7: 0.9 | F7: 0.9
A8: Taxes on goods and services | B8: 128.6 | C8: 139.4 | D8: 171.9 | E8: 176.3 | F8: 183.3
A9: Taxes on international trade and transactions | B9: 19.9 | C9: 26.4 | D9: 36.6 | E9: 37.6 | F9: 38.9
A10: Other taxes | B10: - | C10: - | D10: - | E10: - | F10: -
A11: Grants | B11: 146 | C11: 179.4 | D11: 251.4 | E11: 267.5 | F11: 260.2
A12: Current | B12: 87.4 | C12: 84.7 | D12: 114.3 | E12: 116.6 | F12: 69.5
A13: Capital | B13: 58.6 | C13: 94.7 | D13: 137.1 | E13: 150.9 | F13: 190.7
A14: Other revenue | B14: 30.1 | C14: 38.5 | D14: 42.2 | E14: 41.7 | F14: 44.2
A15: Property income [GFS] | B15: 10.9 | C15: 15.7 | D15: 20.2 | E15: 20.2 | F15: 21.1
A16: Sales of goods and services | B16: 13.3 | C16: 17.4 | D16: 17.9 | E16: 18.1 | F16: 19.2
A17: Fines, penalties, and forfeits | B17: 0.7 | C17: 0.7 | D17: 1.3 | E17: 1.3 | F17: 1.3
A18: Voluntary transfers other than grants | B18: 0 | C18: 0.1 | D18: - | E18: - | F18: -
A19: Miscellaneous and unidentified revenue | B19: 5.1 | C19: 4.6 | D19: 2.7 | E19: 2.1 | F19: 2.6
A20: Expense | B20: 284.6 | C20: 320.7 | D20: 407.8 | E20: 408 | F20: 419.4
A21: Compensation of employees | B21: 127.3 | C21: 138.1 | D21: 148.7 | E21: 143 | F21: 148
A22: Wages and salaries | B22: 108.6 | C22: 123.6 | D22: 135.9 | E22: 131.4 | F22: 136.2
A23: Social contributions | B23: 18.7 | C23: 14.5 | D23: 12.7 | E23: 11.7 | F23: 11.8
A24: Use of goods and services | B24: 107.3 | C24: 122.7 | D24: 171.6 | E24: 198.8 | F24: 199.7
A25: Interest | B25: 7.9 | C25: 8.1 | D25: 8.1 | E25: 8 | F25: 7.7
A26: To nonresidents | B26: 6.4 | C26: 6.7 | D26: 6.3 | E26: 6.2 | F26: 5.9
A27: To residents other than general government | B27: 1.4 | C27: 1.4 | D27: 1.8 | E27: 1.8 | F27: 1.8
A28: Subsidies | B28: 0.6 | C28: 0.9 | D28: 0.9 | E28: 0.9 | F28: 0.9
A29: Subsidies to public corporations | B29: - | C29: - | D29: - | E29: - | F29: -
A30: Subsidies to private enterprises | B30: 0.6 | C30: 0.9 | D30: 0.9 | E30: 0.9 | F30: 0.9
A31: Grants | B31: 3.7 | C31: 3.7 | D31: 2.5 | E31: 2.2 | F31: 5.2
A32: Social benefits | B32: 20.8 | C32: 22.1 | D32: 24.5 | E32: 24.9 | F32: 28.2
A33: Other expense | B33: 16.9 | C33: 25.1 | D33: 51.6 | E33: 30.2 | F33: 29.7
A34: Gross Operating Balance | B34: 76.1 | C34: 98.1 | D34: 133.3 | E34: 154 | F34: 146.1
A35: Net Acquisition Of Nonfinancial Assets | B35: 62.4 | C35: 101.9 | D35: 146.6 | E35: 154.9 | F35: 194.8
A36: Fixed assets | B36: 62.3 | C36: 101.8 | D36: 146.4 | E36: 154.7 | F36: 194.6
A37: Buildings and structures | B37: 41.1 | C37: 71 | D37: 92.6 | E37: 67.2 | F37: 98.8
A38: Machinery and equipment | B38: 14.8 | C38: 25.5 | D38: 42.5 | E38: 44.6 | F38: 38.7
A39: Other fixed assets | B39: 6.4 | C39: 5.3 | D39: 11.3 | E39: 43 | F39: 57.1
A40: Nonproduced assets | B40: 0.1 | C40: 0.1 | D40: 0.2 | E40: 0.2 | F40: 0.2
...

Sheet FY2019
A1: Goverment of Tonga Budget Statement for year ending 30th June 2019 | B1: Column15 | C1: Column19 | D1: Column22 | E1: Column24 | F1: 2018/19
A2: Statement of Government Operations ($m)
B3: Actual | C3: Revised | D3: Budget | E3: Projection | F3: Projection
A4: Revenue | B4: 439.8 | C4: 447.6 | D4: 615.2 | E4: 624.1 | F4: 562.2
A5: Taxes | B5: 213.3 | C5: 221.4 | D5: 247.8 | E5: 248.1 | F5: 256
A6: Taxes on income, profits, and capital gains | B6: 46.1 | C6: 40 | D6: 45.4 | E6: 43.4 | F6: 45.4
A7: Taxes on property | B7: 0.3 | C7: 0.8 | D7: 1.1 | E7: 0.9 | F7: 1.1
A8: Taxes on goods and services | B8: 142.9 | C8: 155.2 | D8: 166.5 | E8: 168.4 | F8: 173.1
A9: Taxes on international trade and transactions | B9: 24 | C9: 25.3 | D9: 34.8 | E9: 35.5 | F9: 36.5
A10: Other taxes | B10: - | C10: - | D10: - | E10: - | F10: -
A11: Grants | B11: 196.4 | C11: 185.9 | D11: 323.3 | E11: 331.6 | F11: 255.4
A12: Current | B12: 97.7 | C12: 100.4 | D12: 139.4 | E12: 142.6 | F12: 129.2
A13: Capital | B13: 98.7 | C13: 85.5 | D13: 183.9 | E13: 189.1 | F13: 126.2
A14: Other revenue | B14: 30.1 | C14: 40.2 | D14: 44.2 | E14: 44.4 | F14: 50.7
A15: Property income [GFS] | B15: 11.2 | C15: 19.3 | D15: 21.8 | E15: 20.7 | F15: 22.2
A16: Sales of goods and services | B16: 14.1 | C16: 15.6 | D16: 17.7 | E16: 17.5 | F16: 19.2
A17: Fines, penalties, and forfeits | B17: 0.7 | C17: 1 | D17: 1.2 | E17: 1.2 | F17: 1.3
A18: Voluntary transfers other than grants | B18: 0.1 | C18: 0 | D18: - | E18: - | F18: -
A19: Miscellaneous and unidentified revenue | B19: 4.1 | C19: 4.3 | D19: 3.4 | E19: 4.9 | F19: 8
A20: Expense | B20: 298.6 | C20: 335 | D20: 422 | E20: 417.9 | F20: 404.8
A21: Compensation of employees | B21: 129.6 | C21: 137.8 | D21: 154.7 | E21: 154.5 | F21: 154
A22: Wages and salaries | B22: 115 | C22: 126.5 | D22: 142.1 | E22: 141.6 | F22: 141
A23: Social contributions | B23: 14.6 | C23: 11.3 | D23: 12.6 | E23: 12.9 | F23: 12.9
A24: Use of goods and services | B24: 116.9 | C24: 146.5 | D24: 194.9 | E24: 194.3 | F24: 185.6
A25: Interest | B25: 8.3 | C25: 7.8 | D25: 8.1 | E25: 8.1 | F25: 8.1
A26: To nonresidents | B26: 6.5 | C26: 6.1 | D26: 6.3 | E26: 6.3 | F26: 6.3
A27: To residents other than general government | B27: 1.8 | C27: 1.7 | D27: 1.8 | E27: 1.8 | F27: 1.8
A28: Subsidies | B28: 0.8 | C28: 0.7 | D28: 0.9 | E28: 0.9 | F28: 0.9
A29: Subsidies to public corporations | B29: - | C29: - | D29: - | E29: - | F29: -
A30: Subsidies to private enterprises | B30: 0.8 | C30: 0.7 | D30: 0.9 | E30: 0.9 | F30: 0.9
A31: Grants | B31: 3.2 | C31: 2.9 | D31: 2.5 | E31: 3.7 | F31: 3.7
A32: Social benefits | B32: 21.8 | C32: 20.9 | D32: 26.9 | E32: 26 | F32: 24.3
A33: Other expense | B33: 18 | C33: 18.5 | D33: 34.1 | E33: 30.4 | F33: 28.3
A34: Gross Operating Balance | B34: 141.2 | C34: 112.6 | D34: 193.3 | E34: 206.3 | F34: 157.4
A35: Net Acquisition Of Nonfinancial Assets | B35: 104.9 | C35: 96.6 | D35: 191.9 | E35: 196.7 | F35: 133.6
A36: Fixed assets | B36: 104.7 | C36: 96.5 | D36: 194 | E36: 198.9 | F36: 136
A37: Buildings and structures | B37: 69.5 | C37: 61.5 | D37: 88 | E37: 66.5 | F37: 41.8
A38: Machinery and equipment | B38: 28.8 | C38: 25.7 | D38: 90.3 | E38: 79.4 | F38: 38.5
A39: Other fixed assets | B39: 6.4 | C39: 9.3 | D39: 15.7 | E39: 53 | F39: 55.8
A40: Nonproduced assets | B40: 0.2 | C40: 0.1 | D40: -2.1 | E40: -2.1 | F40: -2.4
...

Sheet FY2020
A1: Column1 | B1: 2017/18 Actual | C1: 2018/19 Revised Estimate | D1: Budget Estimate 2019/20 | E1: 2020/21 Projection | F1: 2021/22 Projection
A2: Revenue | B2: 457.2 | C2: 514.8 | D2: 578.2 | E2: 554.2 | F2: 529.8
A3: Taxes | B3: 235.4 | C3: 245.1 | D3: 257.1 | E3: 262.9 | F3: 269.9
A4: Taxes on income, profits, and capital gains | B4: 48.8 | C4: 51.6 | D4: 57.5 | E4: 57.5 | F4: 57.5
A5: Taxes on property | B5: 0.3 | C5: 0.3 | D5: 0.4 | E5: 0.4 | F5: 0.4
A6: Taxes on goods and services | B6: 157.6 | C6: 161.4 | D6: 170.7 | E6: 175.6 | F6: 181.6
A7: Taxes on international trade and transaction | B7: 28.7 | C7: 31.8 | D7: 28.5 | E7: 29.4 | F7: 30.5
A8: Other taxes
A9: Grants | B9: 190.8 | C9: 236.8 | D9: 272.6 | E9: 242.8 | F9: 212.7
A10: Current | B10: 14.4 | C10: 41.3 | D10: 38.5 | E10: 39.3 | F10: 39.3
A11: Capital | B11: 176.4 | C11: 195.5 | D11: 234.1 | E11: 203.5 | F11: 173.4
A12: Other revenue | B12: 31 | C12: 32.8 | D12: 48.5 | E12: 48.5 | F12: 47.2
A13: Property income [GFS] | B13: 10.8 | C13: 14.8 | D13: 20.5 | E13: 24.5 | F13: 23
A14: Sales of goods and services | B14: 13.8 | C14: 14.6 | D14: 17.3 | E14: 17.3 | F14: 17.3
A15: Fines, penalties, and forfeits | B15: 0.8 | C15: 0.8 | D15: 1.2 | E15: 1.2 | F15: 1.2
A16: Voluntary transfers other than grants | B16: 0 | C16: 0 | D16: 1.8 | E16: 1 | F16: 1
A17: Miscellaneous and unidentified revenue | B17: 5.6 | C17: 2.6 | D17: 7.7 | E17: 4.4 | F17: 4.7
A18: Expense | B18: 336.5 | C18: 413 | D18: 456.3 | E18: 433.8 | F18: 433.8
A19: Compensation of employees | B19: 127.5 | C19: 143.5 | D19: 162.2 | E19: 162.4 | F19: 162.4
A20: Wages and salaries | B20: 116.9 | C20: 132.3 | D20: 149.3 | E20: 149.5 | F20: 149.5
... A46: Foreign | B46: -6.5 | C46: -14.9 | D46: -11.5 | E46: -16.2 | F46: -16.2

Sheet FY2021
A1: Column1 | B1: 2018/19 Actual | C1: 2019/20 Estimate Outturn | D1: Budget Estimate 2020 /21 | E1: 2021/22 Projection | F1: 2022/23 Projection
A2: Revenue | B2: 485.2 | C2: 435.2 | D2: 512.9 | E2: 502.8 | F2: 556.5
A3: Taxes | B3: 243 | C3: 220 | D3: 236.7 | E3: 257.8 | F3: 274.8
A4: Taxes on income, profits, and capital
A5: gains | B5: 55.2 | C5: 53 | D5: 54.6 | E5: 57.3 | F5: 58.1
A6: Taxes on property | B6: 0.3 | C6: 0.3 | D6: 0.3 | E6: 0.3 | F6: 0.3
A7: Taxes on goods and services | B7: 155.3 | C7: 142.4 | D7: 157.9 | E7: 170.3 | F7: 183.7
A8: Taxes on international trade and
A9: transactions | B9: 32.2 | C9: 24.3 | D9: 23.8 | E9: 29.9 | F9: 32.7
A10: Other taxes | B10: 0 | C10: 0 | D10: 0 | E10: 0 | F10: 0
A11: Grants | B11: 212.5 | C11: 186.6 | D11: 247.9 | E11: 209.6 | F11: 243.6
A12: Current | B12: 34.9 | C12: 37.2 | D12: 38.5 | E12: 38.5 | F12: 38.5
A13: Capital | B13: 177.6 | C13: 149.4 | D13: 209.4 | E13: 171.1 | F13: 205.1
A14: Other revenue | B14: 29.6 | C14: 28.7 | D14: 28.3 | E14: 35.4 | F14: 38.1
A15: Property income [GFS] | B15: 10.1 | C15: 10.1 | D15: 9.3 | E15: 13.4 | F15: 14.9
A16: Sales of goods and services | B16: 15.3 | C16: 11 | D16: 14.9 | E16: 16 | F16: 17.1
A17: Fines, penalties, and forfeits | B17: 0.7 | C17: 0.5 | D17: 1.2 | E17: 1.2 | F17: 1.2
A18: Voluntary transfers other than grants | B18: 0 | C18: 0.1 | D18: 0.1 | E18: 0.1 | F18: 0.1
A19: Miscellaneous and unidentified revenue | B19: 3.4 | C19: 6.9 | D19: 2.8 | E19: 4.7 | F19: 4.7
A20: Expense | B20: 352.2 | C20: 396.9 | D20: 495.8 | E20: 423.5 | F20: 431.5
... A41: Net Lending/Borrowing Requirement | B41: 36.3 | C41: -16.9 | D41: -37.4 | E41: 7.4 | F41: 27.9
A42: Net Acquisition Of Financial Assets And
A43: Liabilities (Financing) | B43: 36.3 | C43: -16.9 | D43: -37.4 | E43: 7.4 | F43: 27.9
A44: Financial Assets | B44: 22.9 | C44: -14.6 | D44: -20.1 | E44: 5.7 | F44: 25.9
A45: Domestic | B45: 22.9 | C45: -14.6 | D45: -20.1 | E45: -5.7 | F45: -25.9
A46: Currency and deposits | B46: 15.8 | C46: -14.3 | D46: -19.8 | E46: -5.4 | F46: -25.6
A47: Loans | B47: 7.1 | C47: -0.3 | D47: -0.7 | E47: -0.7 | F47: -0.7
A48: Shares and other equity | B48: 0 | C48: 0 | D48: 0.4 | E48: 0.4 | F48: 0.4
A49: Financial Liabilities | B49: 13.4 | C49: -2.3 | D49: -17.2 | E49: 1.7 | F49: 2
A50: Domestic | B50: 0 | C50: 13.5 | D50: 20.9 | E50: 20.9 | F50: 20.9
A51: Loans | B51: 15.2 | C51: 32.5 | D51: 35.9 | E51: 31.8 | F51: 30.9
A52: Repayments | B52: 15.2 | C52: 19 | D52: 15 | E52: 10.9 | F52: 10
A53: Foreign | B53: -13.4 | C53: -11.2 | D53: -3.7 | E53: -22.6 | F53: -22.9
A54: Loans | B54: 0 | C54: 0 | D54: 19 | E54: 0 | F54: 0
A55: Repayments | B55: -13.4 | C55: -11.2 | D55: -22.7 | E55: -22.6 | F55: -22.9

Sheet FY2022
A1: Column1 | B1: 2019/20 | C1: Estimated Outturn 2020 /21 | D1: Budget Estimate 2021/22 | E1: 2022/23 | F1: 2023/24
A2: Revenue | B2: 494.4 | C2: 469.7 | D2: 572.2 | E2: 496.7 | F2: 472
A3: Tax and Non-tax Revenue | B3: 280.8 | C3: 256.6 | D3: 277.8 | E3: 279.8 | F3: 281.4
A4: Grants | B4: 213.7 | C4: 213.1 | D4: 294.4 | E4: 216.8 | F4: 190.6
A5: Current | B5: 37.6 | C5: 27.2 | D5: 45.5 | E5: 38.5 | F5: 38.5
A6: Capital | B6: 176.1 | C6: 186 | D6: 249 | E6: 178.4 | F6: 152.2
A7: Expense | B7: 376.9 | C7: 417.8 | D7: 515.9 | E7: 436.8 | F7: 432.3
A8: Compensation of employees | B8: 148.7 | C8: 155.4 | D8: 178.5 | E8: 176.9 | F8: 176.3
A9: Use of goods and services | B9: 169.7 | C9: 209.7 | D9: 263.6 | E9: 191.6 | F9: 188.1
A10: Interest | B10: 8.2 | C10: 6.4 | D10: 8.8 | E10: 8.5 | F10: 8
A11: Subsidies | B11: 0.8 | C11: 0.8 | D11: 1.3 | E11: 1 | F11: 1
A12: Grants | B12: 3.7 | C12: 4.7 | D12: 4.3 | E12: 4.3 | F12: 4.3
A13: Social benefits | B13: 22.3 | C13: 17 | D13: 28.8 | E13: 27.9 | F13: 27.9
... A17: Net Lending/Borrowing Requirement | B17: 59.7 | C17: -11.2 | D17: -18.8 | E17: -35.2 | F17: -34.5
A18: Net Acquisition Of Financial Assets And
A19: Liabilities (Financing) | B19: -59.7 | C19: 11.2 | D19: 18.8 | E19: 35.2 | F19: 34.5
A20: Financial Assets | B20: -61.5 | C20: -4.8 | D20: 5.5 | E20: 54.9 | F20: 73.2
A21: Domestic | B21: -61.5 | C21: -4.8 | D21: 5.5 | E21: 54.9 | F21: 73.2
A22: Currency and deposits | B22: -61.7 | C22: -5 | D22: 5.8 | E22: 55.2 | F22: 73.5
A23: Loans | B23: 0.2 | C23: -0.2 | D23: -0.7 | E23: -0.7 | F23: -0.7
A24: Shares and other equity | B24: - | C24: 0.4 | D24: 0.4 | E24: 0.4 | F24: 0.4
A25: Financial Liabilities | B25: 1.9 | C25: 15.6 | D25: 13.3 | E25: -19.6 | F25: -38.7
A26: Domestic | B26: 12.9 | C26: 0.1 | D26: 0.9 | E26: 0.9 | F26: 8.9
A27: Loans | B27: 31.9 | C27: 15.1 | D27: 15.9 | E27: 15.9 | F27: 15.9
A28: Repayments | B28: 19 | C28: 15 | D28: 15 | E28: 15 | F28: 7
A29: Foreign | B29: -10.9 | C29: 15.5 | D29: 12.4 | E29: -20.6 | F29: -47.7
A30: Loans | B30: - | C30: 22.6 | D30: 30 | E30: - | F30: -
A31: Repayments | B31: 10.9 | C31: 7.1 | D31: 17.6 | E31: 20.6 | F31: 47.7
A36: Column1 | B36: Column3 | C36: Column5 | D36: Column6 | E36: Column7 | F36: Column8
A37: Tax Revenue
B38: 2019/20 | C38: Estimated | D38: Budget | E38: 2022/23 | F38: 2023/24
A40: Taxes on income, profits, and capital gain | B40: 52.5 | C40: 45.6 | D40: 50.4 | E40: 52.3 | F40: 53.4
A41: Taxes on property | B41: 0.4 | C41: 0.3 | D41: 0.3 | E41: 0.3 | F41: 0.3
A42: Taxes on goods and services | B42: 160.7 | C42: 156.1 | D42: 167.9 | E42: 171.1 | F42: 171.1
A43: Taxes on international trade and transact | B43: 25 | C43: 24.6 | D43: 25.7 | E43: 25.9 | F43: 26.1
A44: Other taxes | B44: 0 | C44: 0 | D44: 0 | E44: 0 | F44: 0
A45: Taxes | B45: 238.6 | C45: 226.6 | D45: 244.3 | E45: 249.6 | F45: 251
A50: Column1 | B50: Column3 | C50: Column5 | D50: Column6 | E50: Column7 | F50: Column8
A51: Non-tax Revenue Component
B52: 2019/20 Actual | C52: Estimated Outturn 2020 /21 | D52: Budget Estimate 2021/22 | E52: 2022/23 Projection | F52: 2023/24 Projection
...

Sheet FY2023
A1: Column1 | B1: 2020/21 | C1: Est. | D1: Budget Est. 2022/23 | E1: 2023/24 | F1: 2024/25
A2: Revenue | B2: 516.6 | C2: 531.7 | D2: 695.2 | E2: 604.1 | F2: 612.2
A3: Tax and Non-tax Revenue | B3: 277 | C3: 250 | D3: 286.3 | E3: 287 | F3: 294.5
A4: Grants | B4: 239.5 | C4: 281.8 | D4: 408.9 | E4: 317.2 | F4: 317.8
A5: Current | B5: 27.2 | C5: 45.1 | D5: 81.5 | E5: 38.5 | F5: 38.5
A6: Capital | B6: 212.3 | C6: 236.7 | D6: 327.5 | E6: 278.7 | F6: 279.3
A7: Expense | B7: 446.7 | C7: 484.5 | D7: 604.4 | E7: 489 | F7: 470
A8: Gross Operating Balance | B8: 69.8 | C8: 47.2 | D8: 90.9 | E8: 115.1 | F8: 142.2
A9: Net Acquisition Of Nonfinancial | B9: 80.1 | C9: 60.7 | D9: 113.7 | E9: 150.3 | F9: 163.2
A10: Assets
A11: Net Lending/Borrowing Requirement | B11: -10.3 | C11: -13.5 | D11: -22.9 | E11: -35.2 | F11: -21
A12: Net Acquisition Of Financial Assets And
A13: Liabilities (Financing) | B13: 10.3 | C13: 13.5 | D13: 22.9 | E13: 35.2 | F13: 21
A14: Financial Assets | B14: -4.1 | C14: 7.6 | D14: 20 | E14: 74.3 | F14: 58.2
A15: Domestic | B15: -4.1 | C15: 7.6 | D15: 20 | E15: 74.3 | F15: 58.2
A16: Currency and deposits | B16: -3.9 | C16: 7.6 | D16: 19.7 | E16: 74 | F16: 57.9
A17: Loans | B17: -0.2 | C17: - | D17: -0.7 | E17: -0.7 | F17: -0.7
A18: Shares and other equity | B18: - | C18: - | D18: 1 | E18: 1 | F18: 1
A19: Financial Liabilities | B19: 14.4 | C19: 5.9 | D19: 2.9 | E19: -39.2 | F19: -37.3
A20: Domestic | B20: -2.3 | C20: 9.6 | D20: 0.9 | E20: 8.9 | F20: 0.1
A21: Loans | B21: 12.7 | C21: 21.1 | D21: 16 | E21: 15.9 | F21: 15.9
A22: Repayments | B22: 15 | C22: 11.6 | D22: 15.1 | E22: 7 | F22: 15.8
A23: Foreign | B23: 16.7 | C23: -3.7 | D23: 2 | E23: -48.1 | F23: -37.4
A24: Loans | B24: 22.9 | C24: - | D24: 22 | E24: - | F24: -
A25: Repayments | B25: 6.3 | C25: 3.7 | D25: 20 | E25: 48.1 | F25: 37.4
A26: Source:
A34: Column1 | B34: 2020/21 Actual | C34: Est. outturn 2021/22 | D34: Budget 2022/23 | E34: 2023/24 | F34: 2024/25
A35: Taxes on income, profits, and | B35: 48.6 | C35: 42.8 | D35: 48.2 | E35: 49.2 | F35: 52
A36: capital gains
A37: Taxes on property | B37: 0.3 | C37: 0.3 | D37: 0.3 | E37: 0.3 | F37: 0.3
A38: Taxes on goods and services | B38: 173.4 | C38: 159.6 | D38: 176.4 | E38: 177 | F38: 181.7
A39: Taxes on international trade | B39: 22.6 | C39: 24.8 | D39: 28.5 | E39: 28.7 | F39: 28.7
A40: and transactions
A41: Other taxes | B41: 0 | C41: 0 | D41: 0 | E41: 0 | F41: 0
A42: Total | B42: 244.8 | C42: 227.4 | D42: 253.3 | E42: 255.2 | F42: 262.6
A44: Column1 | B44: 2020/21 Actual | C44: 2021/22 Est. | D44: Budget 2022-23 | E44: 2023/24 Projection | F44: 2024/25 Projection
A45: Expense
A46: Compensation of employees | B46: 160.2 | C46: 166.1 | D46: 177.3 | E46: 177.2 | F46: 176.5
A47: Use of goods and services | B47: 233.6 | C47: 251.9 | D47: 356 | E47: 253.7 | F47: 236.3
A48: Interest | B48: 4.1 | C48: 7.2 | D48: 7.9 | E48: 7.6 | F48: 6.8
...

Sheet FY2024
A1: Column1 | B1: 2021/22 | C1: Estimate Outturn 2022/23 | D1: Budget | E1: 2024/25 | F1: 2025/26
A2: Revenue | B2: 562 | C2: 612.6 | D2: 741.9 | E2: 699.6 | F2: 714
A3: Tax and Non-tax Revenue | B3: 282.2 | C3: 299.4 | D3: 326.5 | E3: 333.2 | F3: 344.4
A4: Grants | B4: 279.8 | C4: 313.2 | D4: 415.4 | E4: 366.4 | F4: 369.5
A5: Current | B5: 52.1 | C5: 58.2 | D5: 50.5 | E5: 38.5 | F5: 38.5
A6: Capital | B6: 227.7 | C6: 255 | D6: 364.9 | E6: 327.9 | F6: 331.1
A7: Expense | B7: 505.1 | C7: 514.5 | D7: 514.8 | E7: 444.9 | F7: 435.3
A8: Gross Operating Balance | B8: 56.8 | C8: 98 | D8: 227.1 | E8: 254.7 | F8: 278.7
A9: Net Acquisition Of Nonfinancial Assets | B9: 67.2 | C9: 92.9 | D9: 201.8 | E9: 233 | F9: 244
A10: Net Lending/Borrowing Requirement | B10: -10.3 | C10: 5.1 | D10: 25.3 | E10: 21.7 | F10: 34.7
A11: Net Acquisition Of Financial Assets And
A12: Liabilities (Financing) | B12: 10.3 | C12: -5.1 | D12: -25.3 | E12: -21.7 | F12: -34.7
A13: Financial Assets | B13: 22.7 | C13: -6.8 | D13: 19 | E13: 20.9 | F13: 11.5
A14: Domestic | B14: 22.7 | C14: -6.8 | D14: 19 | E14: 20.9 | F14: 11.5
A15: Currency and deposits | B15: 22.9 | C15: -7.6 | D15: 27 | E15: 21 | F15: 11.5
A16: Loans | B16: -0.2 | C16: -0.2 | D16: 0.3 | E16: -0.3 | F16: -0.3
A17: Shares and other equity | B17: - | C17: 1 | D17: -8.2 | E17: 0.2 | F17: 0.2
A18: Financial Liabilities | B18: -12.4 | C18: 1.7 | D18: -44.3 | E18: -42.5 | F18: -46.2
A19: Domestic | B19: 0.1 | C19: 0.1 | D19: 3.1 | E19: 4.8 | F19: 5
A20: Loans | B20: 15.9 | C20: 15.2 | D20: 15.1 | E20: 20.1 | F20: 20.1
A21: Repayments | B21: 15.8 | C21: 15.1 | D21: 12 | E21: 15.3 | F21: 15.1
A22: Foreign | B22: -12.5 | C22: 1.6 | D22: -47.3 | E22: -47.3 | F22: -51.2
A23: Loans | B23: - | C23: 21 | D23: - | E23: - | F23: -
A24: Repayments | B24: 12.5 | C24: 19.4 | D24: 47.3 | E24: 47.3 | F24: 51.2
A30: Column1 | B30: 2021/22 | C30: Estimate Outturn 2022/23 | D30: Budget Estimate 2023/24 | E30: 2024/25 | F30: 2025/26
A31: Expense
A32: Compensation of employees | B32: 189.3 | C32: 162.8 | D32: 173.4 | E32: 173.3 | F32: 171.1
A33: Use of goods and services | B33: 221.5 | C33: 249 | D33: 239.5 | E33: 189.6 | F33: 183
A34: Interest | B34: 6.3 | C34: 7.8 | D34: 7.5 | E34: 6.9 | F34: 6.3
A35: Subsidies | B35: 1 | C35: 1.3 | D35: 1.3 | E35: 1.3 | F35: 1.3
A36: Grants | B36: 34.6 | C36: 22.6 | D36: 36.9 | E36: 18.8 | F36: 18.7
A37: Social benefits | B37: 25.8 | C37: 31.5 | D37: 26.5 | E37: 25.4 | F37: 25.4
A38: Other expense | B38: 26.6 | C38: 39.7 | D38: 29.6 | E38: 29.6 | F38: 29.5
A39: Total | B39: 505.1 | C39: 514.5 | D39: 514.8 | E39: 444.9 | F39: 435.3
A40: Source: Ministry of Finance (MOF)
A41: Compensation | B41: “Compensation | D41: remains | E41: second | F41: {=-largest} -> #NAME?
A45: Column1 | B45: Column2 | C45: Column4 | D45: Column5 | E45: Column6 | F45: Column7
A46: A-Table 9: Tax Revenue by main category
B47: 2021/22 | C47: Estimate | D47: Budget | E47: 2024/25 | F47: 2025/26
A49: Taxes on income, profits, and capital | B49: 55.6 | C49: 51.1 | D49: 55.4 | E49: 56.5 | F49: 58.6
...

Sheet FY2025
A1: Category | B1: Actual 2022/23 | C1: Revised Estimate 2023/24 | D1: 2024/25 Estimate | E1: 2025/26 Estimate | F1: 2026/27 Estimate
A2: Revenue | B2: 652.5 | C2: 681.4 | D2: 870.7 | E2: 820.1 | F2: 787.5
A3: Taxes | B3: 285.5 | C3: 291.8 | D3: 327.7 | E3: 333.3 | F3: 335.6
A4: Taxes on income, profits, and capital gains | B4: 58 | C4: 63.8 | D4: 68.8 | E4: 72.9 | F4: 71.9
A5: Taxes on property | B5: 0.4 | C5: 0.5 | D5: 0.5 | E5: 0.5 | F5: 0.6
A6: Taxes on goods and services | B6: 195.6 | C6: 196.6 | D6: 215.7 | E6: 223.4 | F6: 225
A7: Taxes on international trade and transactions | B7: 31.6 | C7: 31 | D7: 42.7 | E7: 36.5 | F7: 38.2
A8: Other taxes | B8: 0 | C8: - | D8: - | E8: - | F8: -
A9: Grants | B9: 336.4 | C9: 347.2 | D9: 488.5 | E9: 425.8 | F9: 391.9
A10: Current | B10: 53.7 | C10: 48.2 | D10: 72.35 | E10: 63.5 | F10: 67.5
A11: Capital | B11: 282.7 | C11: 299 | D11: 416.1 | E11: 362.3 | F11: 324.4
A12: Other revenue | B12: 30.5 | C12: 42.3 | D12: 54.5 | E12: 61 | F12: 60
A13: Property income [GFS] | B13: 11.4 | C13: 9.8 | D13: 12.7 | E13: 15.1 | F13: 14.5
A14: Sales of goods and services | B14: 16.4 | C14: 15.6 | D14: 21.2 | E14: 23.1 | F14: 24
A15: Fines, penalties, and forfeits | B15: 0.8 | C15: 0.9 | D15: 1.1 | E15: 1.2 | F15: 1.3
A16: Voluntary transfers other than grants | B16: 0.1 | C16: 0.4 | D16: 0 | E16: - | F16: -
A17: Miscellaneous and unidentified revenue | B17: 1.9 | C17: 15.6 | D17: 19.6 | E17: 21.6 | F17: 20.1
A18: Expense | B18: 483.8 | C18: 484.3 | D18: 595.2 | E18: 515.2 | F18: 500.7
A19: Compensation of employees | B19: 163.5 | C19: 164.6 | D19: 189.4 | E19: 188.4 | F19: 187.8
A20: Wages and salaries | B20: 151.4 | C20: 152.9 | D20: 175.1 | E20: 174.1 | F20: 173.6
A21: Social contributions | B21: 12.1 | C21: 11.7 | D21: 14.3 | E21: 14.3 | F21: 14.3
A22: Use of goods and services | B22: 225.1 | C22: 224.9 | D22: 278.7 | E22: 233.2 | F22: 217.3
A23: Interest | B23: 8.2 | C23: 7.4 | D23: 6.9 | E23: 6.1 | F23: 5.4
A24: To nonresidents | B24: 6.2 | C24: 5.7 | D24: 4.8 | E24: 3.9 | F24: 3.2
A25: To residents other than general government | B25: 2 | C25: 1.7 | D25: 2.1 | E25: 2.1 | F25: 2.1
A26: Subsidies | B26: 1.2 | C26: 1.1 | D26: 1.3 | E26: 1.3 | F26: 1.3
A27: Subsidies to public corporations | B27: 0 | C27: - | D27: - | E27: - | F27: -
A28: Subsidies to private enterprises | B28: 1.2 | C28: 1.1 | D28: 1.3 | E28: 1.3 | F28: 1.3
A29: Grants | B29: 21.9 | C29: 29.9 | D29: 43.1 | E29: 21.8 | F29: 24.1
A30: Social benefits | B30: 28.2 | C30: 26.2 | D30: 28.4 | E30: 29.3 | F30: 30.3
A31: Other expense | B31: 35.7 | C31: 30.2 | D31: 47.4 | E31: 35.2 | F31: 34.5
A32: Gross Operating Balance | B32: 168.7 | C32: 197.1 | D32: 275.5 | E32: 304.9 | F32: 286.9
A33: Net Acquisition Of Nonfinancial Assets | B33: 95.3 | C33: 153.6 | D33: 232.8 | E33: 250.2 | F33: 224.6
A34: Fixed assets | B34: 95.1 | C34: 152 | D34: 229.3 | E34: 248.5 | F34: 222.9
A35: Buildings and structures | B35: 47.6 | C35: 107.7 | D35: 162.9 | E35: 203.1 | F35: 186.1
A36: Machinery and equipment | B36: 43.7 | C36: 37.8 | D36: 33 | E36: 33.9 | F36: 26.3
A37: Other fixed assets | B37: 3.7 | C37: 6.5 | D37: 33.4 | E37: 11.4 | F37: 10.4
A38: Nonproduced assets | B38: 0.2 | C38: 1.6 | D38: 3.5 | E38: 1.7 | F38: 1.7
A39: Land | B39: 0.2 | C39: 1.6 | D39: 3.5 | E39: 1.7 | F39: 1.7
... A51: Foreign | B51: 0.7 | C51: -47.8 | D51: -46.1 | E51: -50.1 | F51: -50.1
...

Sheet FY2026
A1: Column1 | B1: Column2 | C1: Column4 | D1: Column5 | E1: Column6 | F1: Column7
A2: Revenue | B2: 735.1 | C2: 840 | D2: 929.7 | E2: 911.5 | F2: 900.4 | H2: =Table140__Page_96[[#This Row],[Column4]]/Table140__Page_96[[#This Row],[Column2]]-1 -> 0.14270167 | I2: =Table140__Page_96[[#This Row],[Column5]]/Table140__Page_96[[#This Row],[Column4]]-1 -> 0.10678571 | J2: =Table140__Page_96[[#This Row],[Column6]]/Table140__Page_96[[#This Row],[Column5]]-1 -> -0.019576207 | K2: =Table140__Page_96[[#This Row],[Column7]]/Table140__Page_96[[#This Row],[Column6]]-1 -> -0.012177729
A3: Taxes | B3: 300 | C3: 335.2 | D3: 347.1 | E3: 379.3 | F3: 390.9 | H3: =Table140__Page_96[[#This Row],[Column4]]/Table140__Page_96[[#This Row],[Column2]]-1 -> 0.11733333 | I3: =Table140__Page_96[[#This Row],[Column5]]/Table140__Page_96[[#This Row],[Column4]]-1 -> 0.035501193 | J3: =Table140__Page_96[[#This Row],[Column6]]/Table140__Page_96[[#This Row],[Column5]]-1 -> 0.092768655 | K3: =Table140__Page_96[[#This Row],[Column7]]/Table140__Page_96[[#This Row],[Column6]]-1 -> 0.030582652
A4: Taxes on income, profits, and capital gains | B4: 66.3 | C4: 76.6 | D4: 78.7 | E4: 92.7 | F4: 97.5 | H4: =Table140__Page_96[[#This Row],[Column4]]/Table140__Page_96[[#This Row],[Column2]]-1 -> 0.15535445 | I4: =Table140__Page_96[[#This Row],[Column5]]/Table140__Page_96[[#This Row],[Column4]]-1 -> 0.027415144 | J4: =Table140__Page_96[[#This Row],[Column6]]/Table140__Page_96[[#This Row],[Column5]]-1 -> 0.17789072 | K4: =Table140__Page_96[[#This Row],[Column7]]/Table140__Page_96[[#This Row],[Column6]]-1 -> 0.051779935
A5: Taxes on property | B5: 0.5 | C5: 0.4 | D5: 0.4 | E5: 0.5 | F5: 0.5 | H5: =Table140__Page_96[[#This Row],[Column4]]/Table140__Page_96[[#This Row],[Column2]]-1 -> -0.2 | I5: =Table140__Page_96[[#This Row],[Column5]]/Table140__Page_96[[#This Row],[Column4]]-1 -> 0 | J5: =Table140__Page_96[[#This Row],[Column6]]/Table140__Page_96[[#This Row],[Column5]]-1 -> 0.25 | K5: =Table140__Page_96[[#This Row],[Column7]]/Table140__Page_96[[#This Row],[Column6]]-1 -> 0
A6: Taxes on goods and services | B6: 202.7 | C6: 216.9 | D6: 228.3 | E6: 240.6 | F6: 245.2 | H6: =Table140__Page_96[[#This Row],[Column4]]/Table140__Page_96[[#This Row],[Column2]]-1 -> 0.070054267 | I6: =Table140__Page_96[[#This Row],[Column5]]/Table140__Page_96[[#This Row],[Column4]]-1 -> 0.052558783 | J6: =Table140__Page_96[[#This Row],[Column6]]/Table140__Page_96[[#This Row],[Column5]]-1 -> 0.053876478 | K6: =Table140__Page_96[[#This Row],[Column7]]/Table140__Page_96[[#This Row],[Column6]]-1 -> 0.019118869
A7: Taxes on international trade and transactions | B7: 30.6 | C7: 41.3 | D7: 39.7 | E7: 45.5 | F7: 47.7 | H7: =Table140__Page_96[[#This Row],[Column4]]/Table140__Page_96[[#This Row],[Column2]]-1 -> 0.3496732 | I7: =Table140__Page_96[[#This Row],[Column5]]/Table140__Page_96[[#This Row],[Column4]]-1 -> -0.03874092 | J7: =Table140__Page_96[[#This Row],[Column6]]/Table140__Page_96[[#This Row],[Column5]]-1 -> 0.14609572 | K7: =Table140__Page_96[[#This Row],[Column7]]/Table140__Page_96[[#This Row],[Column6]]-1 -> 0.048351648
A8: Other taxes | B8: 0 | C8: - | D8: - | E8: - | F8: - | H8: . | I8: =Table140__Page_96[[#This Row],[Column5]]/Table140__Page_96[[#This Row],[Column4]]-1 -> #VALUE! | J8: =Table140__Page_96[[#This Row],[Column6]]/Table140__Page_96[[#This Row],[Column5]]-1 -> #VALUE! | K8: =Table140__Page_96[[#This Row],[Column7]]/Table140__Page_96[[#This Row],[Column6]]-1 -> #VALUE!
A9: Grants | B9: 386.9 | C9: 447.7 | D9: 509.2 | E9: 449.5 | F9: 427.5 | H9: =Table140__Page_96[[#This Row],[Column4]]/Table140__Page_96[[#This Row],[Column2]]-1 -> 0.15714655 | I9: =Table140__Page_96[[#This Row],[Column5]]/Table140__Page_96[[#This Row],[Column4]]-1 -> 0.13736877 | J9: =Table140__Page_96[[#This Row],[Column6]]/Table140__Page_96[[#This Row],[Column5]]-1 -> -0.11724273 | K9: =Table140__Page_96[[#This Row],[Column7]]/Table140__Page_96[[#This Row],[Column6]]-1 -> -0.04894327
A10: Current | B10: 70.7 | C10: 99.5 | D10: 120.2 | E10: 82.2 | F10: 81.3 | H10: =Table140__Page_96[[#This Row],[Column4]]/Table140__Page_96[[#This Row],[Column2]]-1 -> 0.40735502 | I10: =Table140__Page_96[[#This Row],[Column5]]/Table140__Page_96[[#This Row],[Column4]]-1 -> 0.2080402 | J10: =Table140__Page_96[[#This Row],[Column6]]/Table140__Page_96[[#This Row],[Column5]]-1 -> -0.31613977 | K10: =Table140__Page_96[[#This Row],[Column7]]/Table140__Page_96[[#This Row],[Column6]]-1 -> -0.010948905
A11: Capital | B11: 316.2 | C11: 348.2 | D11: 389 | E11: 367.3 | F11: 346.2 | H11: =Table140__Page_96[[#This Row],[Column4]]/Table140__Page_96[[#This Row],[Column2]]-1 -> 0.10120177 | I11: =Table140__Page_96[[#This Row],[Column5]]/Table140__Page_96[[#This Row],[Column4]]-1 -> 0.11717404 | J11: =Table140__Page_96[[#This Row],[Column6]]/Table140__Page_96[[#This Row],[Column5]]-1 -> -0.055784062 | K11: =Table140__Page_96[[#This Row],[Column7]]/Table140__Page_96[[#This Row],[Column6]]-1 -> -0.057446229
A12: Other revenue | B12: 48.2 | C12: 57.1 | D12: 73.4 | E12: 82.7 | F12: 82 | H12: =Table140__Page_96[[#This Row],[Column4]]/Table140__Page_96[[#This Row],[Column2]]-1 -> 0.1846473 | I12: =Table140__Page_96[[#This Row],[Column5]]/Table140__Page_96[[#This Row],[Column4]]-1 -> 0.2854641 | J12: =Table140__Page_96[[#This Row],[Column6]]/Table140__Page_96[[#This Row],[Column5]]-1 -> 0.126703 | K12: =Table140__Page_96[[#This Row],[Column7]]/Table140__Page_96[[#This Row],[Column6]]-1 -> -0.0084643289
A13: Expense | B13: 492 | C13: 526.2 | D13: 621.9 | E13: 545.3 | F13: 555.7 | H13: =Table140__Page_96[[#This Row],[Column4]]/Table140__Page_96[[#This Row],[Column2]]-1 -> 0.069512195 | I13: =Table140__Page_96[[#This Row],[Column5]]/Table140__Page_96[[#This Row],[Column4]]-1 -> 0.18187001 | J13: =Table140__Page_96[[#This Row],[Column6]]/Table140__Page_96[[#This Row],[Column5]]-1 -> -0.12317093 | K13: =Table140__Page_96[[#This Row],[Column7]]/Table140__Page_96[[#This Row],[Column6]]-1 -> 0.01907207
A14: Compensation of employees | B14: 164.7 | C14: 180.4 | D14: 192.9 | E14: 193.2 | F14: 193.7 | H14: =Table140__Page_96[[#This Row],[Column4]]/Table140__Page_96[[#This Row],[Column2]]-1 -> 0.095324833 | I14: =Table140__Page_96[[#This Row],[Column5]]/Table140__Page_96[[#This Row],[Column4]]-1 -> 0.069290466 | J14: =Table140__Page_96[[#This Row],[Column6]]/Table140__Page_96[[#This Row],[Column5]]-1 -> 0.00155521 | K14: =Table140__Page_96[[#This Row],[Column7]]/Table140__Page_96[[#This Row],[Column6]]-1 -> 0.0025879917
A15: Wages and salaries | B15: 152.9 | C15: 167.4 | D15: 178 | E15: 178.3 | F15: 178.8 | H15: =Table140__Page_96[[#This Row],[Column4]]/Table140__Page_96[[#This Row],[Column2]]-1 -> 0.094833224 | I15: =Table140__Page_96[[#This Row],[Column5]]/Table140__Page_96[[#This Row],[Column4]]-1 -> 0.063321386 | J15: =Table140__Page_96[[#This Row],[Column6]]/Table140__Page_96[[#This Row],[Column5]]-1 -> 0.0016853933 | K15: =Table140__Page_96[[#This Row],[Column7]]/Table140__Page_96[[#This Row],[Column6]]-1 -> 0.0028042625
A16: Social contributions | B16: 11.7 | C16: 13 | D16: 14.9 | E16: 14.9 | F16: 14.9 | H16: =Table140__Page_96[[#This Row],[Column4]]/Table140__Page_96[[#This Row],[Column2]]-1 -> 0.11111111 | I16: =Table140__Page_96[[#This Row],[Column5]]/Table140__Page_96[[#This Row],[Column4]]-1 -> 0.14615385 | J16: =Table140__Page_96[[#This Row],[Column6]]/Table140__Page_96[[#This Row],[Column5]]-1 -> 0 | K16: =Table140__Page_96[[#This Row],[Column7]]/Table140__Page_96[[#This Row],[Column6]]-1 -> 0
A17: Use of goods and services | B17: 235.6 | C17: 228.7 | D17: 314.3 | E17: 248.8 | F17: 251.6 | H17: =Table140__Page_96[[#This Row],[Column4]]/Table140__Page_96[[#This Row],[Column2]]-1 -> -0.029286927 | I17: =Table140__Page_96[[#This Row],[Column5]]/Table140__Page_96[[#This Row],[Column4]]-1 -> 0.37428946 | J17: =Table140__Page_96[[#This Row],[Column6]]/Table140__Page_96[[#This Row],[Column5]]-1 -> -0.20839962 | K17: =Table140__Page_96[[#This Row],[Column7]]/Table140__Page_96[[#This Row],[Column6]]-1 -> 0.011254019
A18: Interest | B18: 7.4 | C18: 6.9 | D18: 5.9 | E18: 5.1 | F18: 4.3 | H18: =Table140__Page_96[[#This Row],[Column4]]/Table140__Page_96[[#This Row],[Column2]]-1 -> -0.067567568 | I18: =Table140__Page_96[[#This Row],[Column5]]/Table140__Page_96[[#This Row],[Column4]]-1 -> -0.14492754 | J18: =Table140__Page_96[[#This Row],[Column6]]/Table140__Page_96[[#This Row],[Column5]]-1 -> -0.13559322 | K18: =Table140__Page_96[[#This Row],[Column7]]/Table140__Page_96[[#This Row],[Column6]]-1 -> -0.15686275
A19: To nonresidents | B19: 5.6 | C19: 4.9 | D19: 4 | E19: 3.2 | F19: 2.4 | H19: =Table140__Page_96[[#This Row],[Column4]]/Table140__Page_96[[#This Row],[Column2]]-1 -> -0.125 | I19: =Table140__Page_96[[#This Row],[Column5]]/Table140__Page_96[[#This Row],[Column4]]-1 -> -0.18367347 | J19: =Table140__Page_96[[#This Row],[Column6]]/Table140__Page_96[[#This Row],[Column5]]-1 -> -0.2 | K19: =Table140__Page_96[[#This Row],[Column7]]/Table140__Page_96[[#This Row],[Column6]]-1 -> -0.25
A20: To residents other than general government | B20: 1.7 | C20: 2.1 | D20: 1.9 | E20: 1.9 | F20: 1.9 | H20: =Table140__Page_96[[#This Row],[Column4]]/Table140__Page_96[[#This Row],[Column2]]-1 -> 0.23529412 | I20: =Table140__Page_96[[#This Row],[Column5]]/Table140__Page_96[[#This Row],[Column4]]-1 -> -0.095238095 | J20: =Table140__Page_96[[#This Row],[Column6]]/Table140__Page_96[[#This Row],[Column5]]-1 -> 0 | K20: =Table140__Page_96[[#This Row],[Column7]]/Table140__Page_96[[#This Row],[Column6]]-1 -> 0
A21: Subsidies | B21: 1.1 | C21: 1.7 | D21: 1.3 | E21: 1.3 | F21: 1.3 | H21: =Table140__Page_96[[#This Row],[Column4]]/Table140__Page_96[[#This Row],[Column2]]-1 -> 0.54545455 | I21: =Table140__Page_96[[#This Row],[Column5]]/Table140__Page_96[[#This Row],[Column4]]-1 -> -0.23529412 | J21: =Table140__Page_96[[#This Row],[Column6]]/Table140__Page_96[[#This Row],[Column5]]-1 -> 0 | K21: =Table140__Page_96[[#This Row],[Column7]]/Table140__Page_96[[#This Row],[Column6]]-1 -> 0
A22: Subsidies to public corporations | B22: 0 | C22: - | D22: - | E22: - | F22: - | H22: =Table140__Page_96[[#This Row],[Column4]]/Table140__Page_96[[#This Row],[Column2]]-1 -> #VALUE! | I22: =Table140__Page_96[[#This Row],[Column5]]/Table140__Page_96[[#This Row],[Column4]]-1 -> #VALUE! | J22: =Table140__Page_96[[#This Row],[Column6]]/Table140__Page_96[[#This Row],[Column5]]-1 -> #VALUE! | K22: =Table140__Page_96[[#This Row],[Column7]]/Table140__Page_96[[#This Row],[Column6]]-1 -> #VALUE!
A23: Subsidies to private enterprises | B23: 1.1 | C23: 1.7 | D23: 1.3 | E23: 1.3 | F23: 1.3 | H23: =Table140__Page_96[[#This Row],[Column4]]/Table140__Page_96[[#This Row],[Column2]]-1 -> 0.54545455 | I23: =Table140__Page_96[[#This Row],[Column5]]/Table140__Page_96[[#This Row],[Column4]]-1 -> -0.23529412 | J23: =Table140__Page_96[[#This Row],[Column6]]/Table140__Page_96[[#This Row],[Column5]]-1 -> 0 | K23: =Table140__Page_96[[#This Row],[Column7]]/Table140__Page_96[[#This Row],[Column6]]-1 -> 0
A24: Grants | B24: 26.4 | C24: 43.6 | D24: 38.4 | E24: 28.3 | F24: 21.7 | H24: =Table140__Page_96[[#This Row],[Column4]]/Table140__Page_96[[#This Row],[Column2]]-1 -> 0.65151515 | I24: =Table140__Page_96[[#This Row],[Column5]]/Table140__Page_96[[#This Row],[Column4]]-1 -> -0.11926606 | J24: =Table140__Page_96[[#This Row],[Column6]]/Table140__Page_96[[#This Row],[Column5]]-1 -> -0.26302083 | K24: =Table140__Page_96[[#This Row],[Column7]]/Table140__Page_96[[#This Row],[Column6]]-1 -> -0.23321555
A25: Social benefits | B25: 29.4 | C25: 30.7 | D25: 33.1 | E25: 30.1 | F25: 30.1 | H25: =Table140__Page_96[[#This Row],[Column4]]/Table140__Page_96[[#This Row],[Column2]]-1 -> 0.044217687 | I25: =Table140__Page_96[[#This Row],[Column5]]/Table140__Page_96[[#This Row],[Column4]]-1 -> 0.078175896 | J25: =Table140__Page_96[[#This Row],[Column6]]/Table140__Page_96[[#This Row],[Column5]]-1 -> -0.090634441 | K25: =Table140__Page_96[[#This Row],[Column7]]/Table140__Page_96[[#This Row],[Column6]]-1 -> 0
A26: Other expense | B26: 27.4 | C26: 34.1 | D26: 35.9 | E26: 38.4 | F26: 52.9 | H26: =Table140__Page_96[[#This Row],[Column4]]/Table140__Page_96[[#This Row],[Column2]]-1 -> 0.24452555 | I26: =Table140__Page_96[[#This Row],[Column5]]/Table140__Page_96[[#This Row],[Column4]]-1 -> 0.052785924 | J26: =Table140__Page_96[[#This Row],[Column6]]/Table140__Page_96[[#This Row],[Column5]]-1 -> 0.069637883 | K26: =Table140__Page_96[[#This Row],[Column7]]/Table140__Page_96[[#This Row],[Column6]]-1 -> 0.37760417
A27: Gross Operating Balance | B27: 243.1 | C27: 313.8 | D27: 307.8 | E27: 366.2 | F27: 344.7
A28: Net Acquisition Of Nonfinancial Assets | B28: 189.3 | C28: 236 | D28: 252.4 | E28: 285.9 | F28: 265.2
A29: Fixed assets | B29: 188.1 | C29: 232.4 | D29: 248.3 | E29: 261.6 | F29: 245.9
A30: Buildings and structures | B30: 124.7 | C30: 121.4 | D30: 145.3 | E30: 197.9 | F30: 203.8
A31: Machinery and equipment | B31: 57.2 | C31: 83.6 | D31: 102.5 | E31: 59.8 | F31: 34.6
A32: Other fixed assets | B32: 6.3 | C32: 27.4 | D32: 0.5 | E32: 3.8 | F32: 7.5
A33: Nonproduced assets | B33: 1.2 | C33: 3.6 | D33: 4.1 | E33: 24.3 | F33: 19.3
A34: Land | B34: 1.2 | C34: 3.6 | D34: 4.1 | E34: 24.3 | F34: 19.3
A35: Net Lending/Borrowing Requirement | B35: 53.9 | C35: 78 | D35: 55.5 | E35: 80.4 | F35: 79.6
A36: Net Acquisition Of Financial Assets And Liabilities (Financing) | B36: -53.9 | C36: -78 | D36: -55.5 | E36: -80.4 | F36: -79.6
A37: Financial Assets | B37: -10.4 | C37: -29.4 | D37: -37.1 | E37: -30.7 | F37: -28
A38: Domestic | B38: -10.4 | C38: -29.4 | D38: -37.1 | E38: -30.7 | F38: -28
... A46: Foreign | B46: -46.4 | C46: -46.7 | D46: -48.4 | E46: -49.7 | F46: -51.6
A47: Loans | B47: - | C47: 0 | D47: - | E47: 0 | F47: 0
...

Sheet Non-Grant Revenue
A1: Non-grant revenue calculations
A3: Taxes | B3: =Lookup!B72 -> FY2014 | C3: =Lookup!C72 -> FY2015 | D3: =Lookup!D72 -> FY2016 | E3: =Lookup!E72 -> FY2017 | F3: =Lookup!F72 -> FY2018 | G3: =Lookup!G72 -> FY2019 | H3: =Lookup!H72 -> FY2020 | I3: =Lookup!I72 -> FY2021 | ... P3: =Lookup!P72 -> FY2028
A4: =Lookup!A73 -> Budget 2018 | D4: {=_xlfn.XLOOKUP("Taxes",'FY2018'!$A$4:$A$51,'FY2018'!$B$4:$F$51)} -> 184.6 | E4: 200.8 | F4: 247.4 | G4: 252.9 | H4: 261.2
A5: =Lookup!A74 -> Budget 2019 | E5: {=_xlfn.XLOOKUP("Taxes",'FY2019'!$A$4:$A$51,'FY2019'!$B$4:$F$51)} -> 213.3 | F5: 221.4 | G5: 247.8 | H5: 248.1 | I5: 256
A6: =Lookup!A75 -> Budget 2020 | F6: {=_xlfn.XLOOKUP("Taxes",'FY2020'!$A$2:$A$46,'FY2020'!$B$2:$F$46)} -> 235.4 | G6: 245.1 | H6: 257.1 | I6: 262.9 | J6: 269.9
A7: =Lookup!A76 -> Budget 2021 | G7: {=_xlfn.XLOOKUP("Taxes",'FY2021'!$A$2:$A$55,'FY2021'!$B$2:$F$55)} -> 243 | H7: 220 | I7: 236.7 | J7: 257.8 | K7: 274.8
A8: =Lookup!A77 -> Budget 2022 | H8: {=_xlfn.XLOOKUP("Taxes",'FY2022'!$A$2:$A$100,'FY2022'!$B$2:$F$100)} -> 238.6 | I8: 226.6 | J8: 244.3 | K8: 249.6 | L8: 251
A9: =Lookup!A78 -> Budget 2023 | I9: {=_xlfn.XLOOKUP("Taxes",'FY2023'!$A$2:$A$100,'FY2023'!$B$2:$F$100)} -> 244.8 | J9: 227.4 | K9: 253.3 | L9: 255.2 | M9: 262.6
A10: =Lookup!A79 -> Budget 2024 | J10: {=_xlfn.XLOOKUP("Taxes",'FY2024'!$A$2:$A$101,'FY2024'!$B$2:$F$101)} -> 257.9 | K10: 270.7 | L10: 283 | M10: 297.3 | N10: 306.7
A11: =Lookup!A80 -> Budget 2025 | K11: {=_xlfn.XLOOKUP("Taxes",'FY2025'!$A$2:$A$100,'FY2025'!$B$2:$F$100)} -> 285.5 | L11: 291.8 | M11: 327.7 | N11: 333.3 | O11: 335.6
A12: =Lookup!A81 -> Budget 2026 | L12: {=_xlfn.XLOOKUP("Taxes",'FY2026'!$A$2:$A$100,'FY2026'!$B$2:$F$100)} -> 300 | M12: 335.2 | N12: 347.1 | O12: 379.3 | P12: 390.9
A15: Outturn | E15: =E5 -> 213.3 | F15: =F6 -> 235.4 | G15: =G7 -> 243 | H15: =H8 -> 238.6 | I15: =I9 -> 244.8 | J15: =J10 -> 257.9 | K15: =K11 -> 285.5 | L15: =L12 -> 300
A18: Other revenue | B18: FY2014 | C18: FY2015 | D18: FY2016 | E18: FY2017 | F18: FY2018 | G18: FY2019 | H18: FY2020 | I18: FY2021 | J18: FY2022 | K18: FY2023 | L18: FY2024 | M18: FY2025 | N18: FY2026 | O18: FY2027 | P18: FY2028
A19: =A4 -> Budget 2018 | D19: {=_xlfn.XLOOKUP($A$18,'FY2018'!$A$4:$A$51,'FY2018'!$B$4:$F$51)} -> 30.1 | E19: 38.5 | F19: 42.2 | G19: 41.7 | H19: 44.2
A20: =A5 -> Budget 2019 | E20: {=_xlfn.XLOOKUP($A$18,'FY2019'!$A$4:$A$51,'FY2019'!$B$4:$F$51)} -> 30.1 | F20: 40.2 | G20: 44.2 | H20: 44.4 | I20: 50.7
A21: =A6 -> Budget 2020 | F21: {=_xlfn.XLOOKUP($A$18,'FY2020'!$A$2:$A$46,'FY2020'!$B$2:$F$46)} -> 31 | G21: 32.8 | H21: 48.5 | I21: 48.5 | J21: 47.2
A22: =A7 -> Budget 2021 | G22: {=_xlfn.XLOOKUP($A$18,'FY2021'!$A$2:$A$55,'FY2021'!$B$2:$F$55)} -> 29.6 | H22: 28.7 | I22: 28.3 | J22: 35.4 | K22: 38.1
A23: =A8 -> Budget 2022 | H23: {=_xlfn.XLOOKUP($A$18,'FY2022'!$A$2:$A$100,'FY2022'!$B$2:$F$100)} -> 42.2 | I23: 30 | J23: 33.5 | K23: 30.3 | L23: 30.4
A24: =A9 -> Budget 2023 | I24: {=_xlfn.XLOOKUP($A$18,'FY2023'!$A$2:$A$100,'FY2023'!$B$2:$F$100)} -> 32.2 | J24: 22.5 | K24: 33 | L24: 31.8 | M24: 31.8
A25: =A10 -> Budget 2024 | J25: {=_xlfn.XLOOKUP($A$18,'FY2024'!$A$2:$A$101,'FY2024'!$B$2:$F$101)} -> 24.3 | K25: 28.7 | L25: 43.4 | M25: 35.8 | N25: 37.7
A26: =A11 -> Budget 2025 | K26: {=_xlfn.XLOOKUP($A$18,'FY2025'!$A$2:$A$100,'FY2025'!$B$2:$F$100)} -> 30.5 | L26: 42.3 | M26: 54.5 | N26: 61 | O26: 60
A27: =A12 -> Budget 2026 | L27: {=_xlfn.XLOOKUP($A$18,'FY2026'!$A$2:$A$100,'FY2026'!$B$2:$F$100)} -> 48.2 | M27: 57.1 | N27: 73.4 | O27: 82.7 | P27: 82
A30: =A15 -> Outturn | E30: =E20 -> 30.1 | F30: =F21 -> 31 | G30: =G22 -> 29.6 | H30: =H23 -> 42.2 | I30: =I24 -> 32.2 | J30: =J25 -> 24.3 | K30: =K26 -> 30.5 | L30: =L27 -> 48.2
A32: Level
A33: Non-grant revenue | B33: FY2014 | C33: FY2015 | D33: FY2016 | E33: FY2017 | F33: FY2018 | G33: FY2019 | H33: FY2020 | I33: FY2021 | J33: FY2022 | K33: FY2023 | L33: FY2024 | M33: FY2025 | N33: FY2026 | O33: FY2027 | P33: FY2028
A34: =A19 -> Budget 2018 | D34: =SUM(D4,D19) -> 214.7 | E34: =SUM(E4,E19) -> 239.3 | F34: =SUM(F4,F19) -> 289.6 | G34: =SUM(G4,G19) -> 294.6 | H34: =SUM(H4,H19) -> 305.4
A35: =A20 -> Budget 2019 | E35: =SUM(E5,E20) -> 243.4 | F35: =SUM(F5,F20) -> 261.6 | G35: =SUM(G5,G20) -> 292 | H35: =SUM(H5,H20) -> 292.5 | I35: =SUM(I5,I20) -> 306.7
A36: =A21 -> Budget 2020 | F36: =SUM(F6,F21) -> 266.4 | G36: =SUM(G6,G21) -> 277.9 | H36: =SUM(H6,H21) -> 305.6 | I36: =SUM(I6,I21) -> 311.4 | J36: =SUM(J6,J21) -> 317.1
A37: =A22 -> Budget 2021 | G37: =SUM(G7,G22) -> 272.6 | H37: =SUM(H7,H22) -> 248.7 | I37: =SUM(I7,I22) -> 265 | J37: =SUM(J7,J22) -> 293.2 | K37: =SUM(K7,K22) -> 312.9
A38: =A23 -> Budget 2022 | H38: =SUM(H8,H23) -> 280.8 | I38: =SUM(I8,I23) -> 256.6 | J38: =SUM(J8,J23) -> 277.8 | K38: =SUM(K8,K23) -> 279.9 | L38: =SUM(L8,L23) -> 281.4
A39: =A24 -> Budget 2023 | I39: =SUM(I9,I24) -> 277 | J39: =SUM(J9,J24) -> 249.9 | K39: =SUM(K9,K24) -> 286.3 | L39: =SUM(L9,L24) -> 287 | M39: =SUM(M9,M24) -> 294.4
A40: =A25 -> Budget 2024 | J40: =SUM(J10,J25) -> 282.2 | K40: =SUM(K10,K25) -> 299.4 | L40: =SUM(L10,L25) -> 326.4 | M40: =SUM(M10,M25) -> 333.1 | N40: =SUM(N10,N25) -> 344.4
A41: =A26 -> Budget 2025 | K41: =SUM(K11,K26) -> 316 | L41: =SUM(L11,L26) -> 334.1 | M41: =SUM(M11,M26) -> 382.2 | N41: =SUM(N11,N26) -> 394.3 | O41: =SUM(O11,O26) -> 395.6
A42: =A27 -> Budget 2026 | L42: =SUM(L12,L27) -> 348.2 | M42: =SUM(M12,M27) -> 392.3 | N42: =SUM(N12,N27) -> 420.5 | O42: =SUM(O12,O27) -> 462 | P42: =SUM(P12,P27) -> 472.9
A45: =A30 -> Outturn | E45: =SUM(E15,E30) -> 243.4 | F45: =SUM(F15,F30) -> 266.4 | G45: =SUM(G15,G30) -> 272.6 | H45: =SUM(H15,H30) -> 280.8 | I45: =SUM(I15,I30) -> 277 | J45: =SUM(J15,J30) -> 282.2 | K45: =SUM(K15,K30) -> 316 | L45: =SUM(L15,L30) -> 348.2
A47: Share of GDP
A48: =A33 -> Non-grant revenue | B48: FY2014 | C48: FY2015 | D48: FY2016 | E48: FY2017 | F48: FY2018 | G48: FY2019 | H48: FY2020 | I48: FY2021 | J48: FY2022 | K48: FY2023 | L48: FY2024 | M48: FY2025 | N48: FY2026 | O48: FY2027 | P48: FY2028
A49: Budget 2018 | F49: =F34/GDP!B2 -> 0.28095522 | G49: =G34/GDP!C2 -> 0.32733333 | H49: =H34/GDP!D2 -> 0.28219713
A50: Budget 2019 | G50: =G35/GDP!C3 -> 0.28112063 | H50: =H35/GDP!D3 -> 0.26820099 | I50: =I35/GDP!E3 -> 0.26861097
A51: Budget 2020 | H51: =H36/GDP!D4 -> 0.264 | I51: =I36/GDP!E4 -> 0.255 | J51: =J36/GDP!F4 -> 0.24492276
...

Sheet GDP
B1: FY 2018 | C1: FY 2019 | D1: FY 2020 | E1: FY 2021 | F1: FY 2022 | G1: FY 2023 | H1: FY 2024 | I1: FY 2025 | J1: FY 2026 | K1: FY 2027 | L1: FY 2028
A2: Budget Statement FY 2018 | B2: =13.4/0.013 -> 1030.7692 | C2: =0.9/0.001 -> 900 | D2: =48.7/0.045 -> 1082.2222
A3: Budget Statement FY 2019 | B3: 987.7 | C3: 1038.7 | D3: 1090.6 | E3: 1141.8
A4: Budget Statement FY 2020 | B4: =266.4/0.251 -> 1061.3546 | C4: =278/0.252 -> 1103.1746 | D4: =305.6/0.264 -> 1157.5758 | E4: =311.4/0.255 -> 1221.1765 | F4: =317.2/0.245 -> 1294.6939
A5: Budget Statement FY 2021 | C5: 1086.3 | D5: 1074.4 | E5: 1031 | F5: 1088.4 | G5: 1159.3
A6: Budget Statement FY 2022 | D6: 1208.7 | E6: 1234.1 | F6: 1317.6 | G6: 1429.1 | H6: 1530
A7: Budget Statement FY 2023 | E7: =59.7/0.053 -> 1126.4151 | F7: =13.5/0.011 -> 1227.2727 | G7: =22.9/0.018 -> 1272.2222 | H7: =35.2/0.025 -> 1408 | I7: =21/0.014 -> 1500
A8: Budget Statement FY 2024 | F8: 1144.4 | G8: 1275 | H8: 1488.2 | I8: 1669.2 | J8: =34.7/0.02 -> 1735
A9: Budget Statement FY 2025 | G9: 1213.9 | H9: 1234.5 | I9: 1260 | J9: 1330.5 | K9: 1388.4
A10: Budget Statement FY 2026 | H10: 1225 | I10: 1258.1 | J10: 1290.7 | K10: 1362.7 | L10: 1421.4
A13: Outturn | B13: 1064.5 | C13: 1164 | D13: 1129.2 | E13: 1068.9 | F13: 1086.3 | G13: 1201.44 | H13: 1537.2
A15: Outturn FY2024 | B15: 1082.6999 | C15: 1149.6615 | D15: 1170.2546 | E15: 1182.9357 | F15: 1264.2625 | G15: 1396.0486 | H15: 1537.1863
