Workbook

Sheet DQAF_Input
A1: Navigation: Use the + / – buttons in the left margin to expand/collapse each indicator section. Tip: Expand one indicator at a time. | S1: SCORE_NUM | T1: TARGET_SCORE_NUM | U1: ADJ_WEIGHT | V1: TOTAL_WEIGHT | W1: WEIGHT_SHARE | X1: WEIGHTED_SCORE | Y1: NR_FLAG | Z1: NR_SEQ | AA1: ADJ_WEIGHT_TGT | AB1: TOTAL_WEIGHT_TGT | AC1: WEIGHT_SHARE_TGT | AD1: WEIGHTED_SCORE_TGT | AE1: NR_FLAG_TGT | AF1: DIFF_FLAG | AG1: DIFF_SEQ
A2: Quality Indicator | B2: DIM_ID | C2: ELEM_ID | D2: QIND_ID | E2: RBP_ID | F2: Standards and Codes (S&C) | G2: WEIGHT | H2: Current Observance | J2: Target Observance | K2: COMMENT | L2: REFERENCES | M2: SCORE | N2: TARGET_SCORE | O2: KEY_TYPE | P2: STANDARD | Q2: E_DESC | R2: SORT_ORDER
F3: The responsibility for collecting, processing, and disseminating official statistics is clearly specified in law
A4: The responsibility for collecting, processing, and disseminating official statistics is clearly specified in law | B4: 1 | C4: 1_1 | D4: 1_1_1 | E4: 1_1_1_1 | F4: Does a law, such as a statistical law or other relevant law, establish a clear legal framework for the development, production, and dissemination of official statistics? | G4: 50 | H4: Highly - This recommendation / best practice is implemented but minor gaps exist in coverage and/or the consistency of its application across the program / organization | J4: Fully - This recommendation / best practice is fully implemented | K4: The Tonga Strategy for Development of Statistics (TSDS) 2019-2023 aims to manage the production and dissessmination of accessible, quality, and accurate statistical information efficiently and effectively | L4: Explicit statement of objective and scope of the national statistical system, covering all key statistical activities (Articles 1–2 GLOS). European Statistical Code of Practice Principle 1 | M4: =IFERROR(INDEX(__key!$D:$D,MATCH(O4&"|"&SUBSTITUTE(H4,",",";"), __key!$E:$E, 0)), "") -> 4 | N4: =IFERROR(INDEX(__key!$D:$D,MATCH(O4&"|"&SUBSTITUTE(J4,",",";"), __key!$E:$E, 0)), "") -> 5 | O4: BP | Q4: The legal framework defining the national statistical system is comprehensive | R4: 1111 | S4: =IFERROR(1*M4,0) -> 4 | T4: =IFERROR(1*N4,0) -> 5 | U4: =IFERROR(IF(ISNUMBER(SEARCH("Not Relevant",H4)),0,VALUE(G4)),"") -> 50 | V4: =IFERROR(SUMIF($D:$D,D4,$U:$U),"") -> 150 | W4: =IF(OR(V4=0,V4=""),"",U4/V4) -> 0.33333333 | X4: =IF(OR(M4="",W4=""),"",VALUE(M4)*W4) -> 1.3333333 | Y4: =IFERROR(ISNUMBER(SEARCH("Not Relevant",H4)),FALSE) -> FALSE | Z4: =IF(Y4, COUNTIF($Y$2:Y4, TRUE), "") | AA4: =IFERROR(IF(ISNUMBER(SEARCH("Not Relevant",J4)),0,VALUE(G4)),"") -> 50 | AB4: =IFERROR(SUMIF($D:$D,D4,$AA:$AA),"") -> 150 | AC4: =IF(OR(AB4=0,AB4=""),"",AA4/AB4) -> 0.33333333 | AD4: =IF(OR(N4="",AC4=""),"",VALUE(N4)*AC4) -> 1.6666667 | AE4: =IFERROR(ISNUMBER(SEARCH("Not Relevant",J4)),FALSE) -> FALSE | AF4: =IF(OR(H4="",J4=""),FALSE,IF(H4<>J4,TRUE,FALSE)) -> TRUE | AG4: =IF(AF4, COUNTIF($AF$2:AF4, TRUE), "") -> 1
A5: The responsibility for collecting, processing, and disseminating official statistics is clearly specified in law | B5: 1 | C5: 1_1 | D5: 1_1_1 | E5: 1_1_1_2 | F5: Does a law, such as a statistical law or other relevant law, clearly define “official statistics” and distinguish them from other statistics (administrative or private)? | G5: 10 | H5: Highly - This recommendation / best practice is implemented but minor gaps exist in coverage and/or the consistency of its application across the program / organization | J5: Fully - This recommendation / best practice is fully implemented | K5: Official statistics is defined in the Statistics Act revision 2016 as "statistics produced by any department to inform the Government and people of Tonga about the economic, social, cultural and environmental conditions of the Kingdom and the activities, performance and impact of the Government, and to measure economic and social progress of the people of Tonga;" It is clearly defined that the TSD is the principal authority for official statistics. However, its distinction from other types of data is not explicitly mentioned and this could be clarified | L5: Explicit statement of objective and scope of the national statistical system, covering all key statistical activities (Articles 1–2 GLOS). European Statistical Code of Practice Principle 1 | M5: =IFERROR(INDEX(__key!$D:$D,MATCH(O5&"|"&SUBSTITUTE(H5,",",";"), __key!$E:$E, 0)), "") -> 4 | N5: =IFERROR(INDEX(__key!$D:$D,MATCH(O5&"|"&SUBSTITUTE(J5,",",";"), __key!$E:$E, 0)), "") -> 5 | O5: BP | Q5: The legal framework defining the national statistical system is comprehensive | R5: 1112 | S5: =IFERROR(1*M5,0) -> 4 | T5: =IFERROR(1*N5,0) -> 5 | U5: =IFERROR(IF(ISNUMBER(SEARCH("Not Relevant",H5)),0,VALUE(G5)),"") -> 10 | V5: =IFERROR(SUMIF($D:$D,D5,$U:$U),"") -> 150 | W5: =IF(OR(V5=0,V5=""),"",U5/V5) -> 0.066666667 | X5: =IF(OR(M5="",W5=""),"",VALUE(M5)*W5) -> 0.26666667 | Y5: =IFERROR(ISNUMBER(SEARCH("Not Relevant",H5)),FALSE) -> FALSE | Z5: =IF(Y5, COUNTIF($Y$2:Y5, TRUE), "") | AA5: =IFERROR(IF(ISNUMBER(SEARCH("Not Relevant",J5)),0,VALUE(G5)),"") -> 10 | AB5: =IFERROR(SUMIF($D:$D,D5,$AA:$AA),"") -> 150 | AC5: =IF(OR(AB5=0,AB5=""),"",AA5/AB5) -> 0.066666667 | AD5: =IF(OR(N5="",AC5=""),"",VALUE(N5)*AC5) -> 0.33333333 | AE5: =IFERROR(ISNUMBER(SEARCH("Not Relevant",J5)),FALSE) -> FALSE | AF5: =IF(OR(H5="",J5=""),FALSE,IF(H5<>J5,TRUE,FALSE)) -> TRUE | AG5: =IF(AF5, COUNTIF($AF$2:AF5, TRUE), "") -> 2
A6: The responsibility for collecting, processing, and disseminating official statistics is clearly specified in law | B6: 1 | C6: 1_1 | D6: 1_1_1 | E6: 1_1_1_3 | F6: Is the Fundamental Principle of Official Statistics - Relevance, Impartiality and Equal Access embedded in the law, such as a statistical law or other relevant law? | G6: 1 | H6: Highly - This recommendation / best practice is implemented but minor gaps exist in coverage and/or the consistency of its application across the program / organization | J6: =IF(H6="","",H6) -> Highly - This recommendation / best practice is implemented but minor gaps exist in coverage and/or the consistency of its application across the program / organization | K6: Yes, outlined in TSDS and Statistical Act 2020 is commited to providing data with improved accessibility, unbiased, and relevant publication of its statistics. | L6: Core statistical principles are fully recognized and legally binding (Article 3 GLOS). European Statistical Code of Practice Principle 1 | M6: =IFERROR(INDEX(__key!$D:$D,MATCH(O6&"|"&SUBSTITUTE(H6,",",";"), __key!$E:$E, 0)), "") -> 4 | N6: =IFERROR(INDEX(__key!$D:$D,MATCH(O6&"|"&SUBSTITUTE(J6,",",";"), __key!$E:$E, 0)), "") -> 4 | O6: BP | Q6: The legal framework defining the national statistical system is comprehensive | R6: 1113 | S6: =IFERROR(1*M6,0) -> 4 | T6: =IFERROR(1*N6,0) -> 4 | U6: =IFERROR(IF(ISNUMBER(SEARCH("Not Relevant",H6)),0,VALUE(G6)),"") -> 1 | V6: =IFERROR(SUMIF($D:$D,D6,$U:$U),"") -> 150 | W6: =IF(OR(V6=0,V6=""),"",U6/V6) -> 0.0066666667 | X6: =IF(OR(M6="",W6=""),"",VALUE(M6)*W6) -> 0.026666667 | Y6: =IFERROR(ISNUMBER(SEARCH("Not Relevant",H6)),FALSE) -> FALSE | Z6: =IF(Y6, COUNTIF($Y$2:Y6, TRUE), "") | AA6: =IFERROR(IF(ISNUMBER(SEARCH("Not Relevant",J6)),0,VALUE(G6)),"") -> 1 | AB6: =IFERROR(SUMIF($D:$D,D6,$AA:$AA),"") -> 150 | AC6: =IF(OR(AB6=0,AB6=""),"",AA6/AB6) -> 0.0066666667 | AD6: =IF(OR(N6="",AC6=""),"",VALUE(N6)*AC6) -> 0.026666667 | AE6: =IFERROR(ISNUMBER(SEARCH("Not Relevant",J6)),FALSE) -> FALSE | AF6: =IF(OR(H6="",J6=""),FALSE,IF(H6<>J6,TRUE,FALSE)) -> FALSE | AG6: =IF(AF6, COUNTIF($AF$2:AF6, TRUE), "")
A7: The responsibility for collecting, processing, and disseminating official statistics is clearly specified in law | B7: 1 | C7: 1_1 | D7: 1_1_1 | E7: 1_1_1_4 | F7: Does a law, such as a statistical law or other relevant law, provide a clear mandate for producers to collect data (including compulsory surveys when necessary) if such data are not otherwise available? | G7: 50 | H7: Highly - This recommendation / best practice is implemented but minor gaps exist in coverage and/or the consistency of its application across the program / organization | J7: Fully - This recommendation / best practice is fully implemented | K7: Part II of the Statistic Act 2016 outlines the TSD may collect data from people, businesses or organisations for purposes relating to compiling, analyzing and publishing official statistics | L7: National authority is provided legal authority to conduct surveys, define methodologies, and require responses, minimizing duplication and burden (Articles 15–16 GLOS). European Statistical Code of Practice Principle 1 | M7: =IFERROR(INDEX(__key!$D:$D,MATCH(O7&"|"&SUBSTITUTE(H7,",",";"), __key!$E:$E, 0)), "") -> 4 | N7: =IFERROR(INDEX(__key!$D:$D,MATCH(O7&"|"&SUBSTITUTE(J7,",",";"), __key!$E:$E, 0)), "") -> 5 | O7: BP | Q7: The legal framework defining the national statistical system is comprehensive | R7: 1114 | S7: =IFERROR(1*M7,0) -> 4 | T7: =IFERROR(1*N7,0) -> 5 | U7: =IFERROR(IF(ISNUMBER(SEARCH("Not Relevant",H7)),0,VALUE(G7)),"") -> 50 | V7: =IFERROR(SUMIF($D:$D,D7,$U:$U),"") -> 150 | W7: =IF(OR(V7=0,V7=""),"",U7/V7) -> 0.33333333 | X7: =IF(OR(M7="",W7=""),"",VALUE(M7)*W7) -> 1.3333333 | Y7: =IFERROR(ISNUMBER(SEARCH("Not Relevant",H7)),FALSE) -> FALSE | Z7: =IF(Y7, COUNTIF($Y$2:Y7, TRUE), "") | AA7: =IFERROR(IF(ISNUMBER(SEARCH("Not Relevant",J7)),0,VALUE(G7)),"") -> 50 | AB7: =IFERROR(SUMIF($D:$D,D7,$AA:$AA),"") -> 150 | AC7: =IF(OR(AB7=0,AB7=""),"",AA7/AB7) -> 0.33333333 | AD7: =IF(OR(N7="",AC7=""),"",VALUE(N7)*AC7) -> 1.6666667 | AE7: =IFERROR(ISNUMBER(SEARCH("Not Relevant",J7)),FALSE) -> FALSE | AF7: =IF(OR(H7="",J7=""),FALSE,IF(H7<>J7,TRUE,FALSE)) -> TRUE | AG7: =IF(AF7, COUNTIF($AF$2:AF7, TRUE), "") -> 3
A8: The responsibility for collecting, processing, and disseminating official statistics is clearly specified in law | B8: 1 | C8: 1_1 | D8: 1_1_1 | E8: 1_1_1_5 | F8: Does the law, such as a statistical law or other relevant law, override conflicting provisions in other legislation, or require that other laws comply with statistical requirements where needed? | G8: 30 | J8: =IF(H8="","",H8) | K8: Not sure | L8: The law must prevail over secrecy or confidentiality rules that impede statistical work, unless explicitly exempt (Articles 17, 37 GLOS). European Statistical Code of Practice Principle 1 | M8: =IFERROR(INDEX(__key!$D:$D,MATCH(O8&"|"&SUBSTITUTE(H8,",",";"), __key!$E:$E, 0)), "") | N8: =IFERROR(INDEX(__key!$D:$D,MATCH(O8&"|"&SUBSTITUTE(J8,",",";"), __key!$E:$E, 0)), "") | O8: BP | Q8: The legal framework defining the national statistical system is comprehensive | R8: 1115 | S8: =IFERROR(1*M8,0) -> 0 | T8: =IFERROR(1*N8,0) -> 0 | U8: =IFERROR(IF(ISNUMBER(SEARCH("Not Relevant",H8)),0,VALUE(G8)),"") -> 30 | V8: =IFERROR(SUMIF($D:$D,D8,$U:$U),"") -> 150 | W8: =IF(OR(V8=0,V8=""),"",U8/V8) -> 0.2 | X8: =IF(OR(M8="",W8=""),"",VALUE(M8)*W8) | Y8: =IFERROR(ISNUMBER(SEARCH("Not Relevant",H8)),FALSE) -> FALSE | Z8: =IF(Y8, COUNTIF($Y$2:Y8, TRUE), "") | AA8: =IFERROR(IF(ISNUMBER(SEARCH("Not Relevant",J8)),0,VALUE(G8)),"") -> 30 | AB8: =IFERROR(SUMIF($D:$D,D8,$AA:$AA),"") -> 150 | AC8: =IF(OR(AB8=0,AB8=""),"",AA8/AB8) -> 0.2 | AD8: =IF(OR(N8="",AC8=""),"",VALUE(N8)*AC8) | AE8: =IFERROR(ISNUMBER(SEARCH("Not Relevant",J8)),FALSE) -> FALSE | AF8: =IF(OR(H8="",J8=""),FALSE,IF(H8<>J8,TRUE,FALSE)) -> FALSE | AG8: =IF(AF8, COUNTIF($AF$2:AF8, TRUE), "")
A9: The responsibility for collecting, processing, and disseminating official statistics is clearly specified in law | B9: 1 | C9: 1_1 | D9: 1_1_1 | E9: 1_1_1_6 | F9: When was the statistical law or other relevant law last updated? | H9: Highly - Between the last 6 and 10 years | J9: Fully - Within the last five years | K9: The Statistical Act in 2020 is referenced as the latest revision of the 2015 Act, however, only the 2016 revision of the Statistical Act 2015 is found online- and is referenced throughout this document | L9: European Statistical Code of Practice Principle 1 | M9: =IFERROR(INDEX(__key!$D:$D,MATCH(O9&"|"&SUBSTITUTE(H9,",",";"), __key!$E:$E, 0)), "") -> 4 | N9: =IFERROR(INDEX(__key!$D:$D,MATCH(O9&"|"&SUBSTITUTE(J9,",",";"), __key!$E:$E, 0)), "") -> 5 | O9: TP | Q9: The legal framework defining the national statistical system is comprehensive | R9: 1116 | S9: =IFERROR(1*M9,0) -> 4 | T9: =IFERROR(1*N9,0) -> 5 | U9: =IFERROR(IF(ISNUMBER(SEARCH("Not Relevant",H9)),0,VALUE(G9)),"") -> 0 | V9: =IFERROR(SUMIF($D:$D,D9,$U:$U),"") -> 150 | W9: =IF(OR(V9=0,V9=""),"",U9/V9) -> 0 | X9: =IF(OR(M9="",W9=""),"",VALUE(M9)*W9) -> 0 | Y9: =IFERROR(ISNUMBER(SEARCH("Not Relevant",H9)),FALSE) -> FALSE | Z9: =IF(Y9, COUNTIF($Y$2:Y9, TRUE), "") | AA9: =IFERROR(IF(ISNUMBER(SEARCH("Not Relevant",J9)),0,VALUE(G9)),"") -> 0 | AB9: =IFERROR(SUMIF($D:$D,D9,$AA:$AA),"") -> 150 | AC9: =IF(OR(AB9=0,AB9=""),"",AA9/AB9) -> 0 | AD9: =IF(OR(N9="",AC9=""),"",VALUE(N9)*AC9) -> 0 | AE9: =IFERROR(ISNUMBER(SEARCH("Not Relevant",J9)),FALSE) -> FALSE | AF9: =IF(OR(H9="",J9=""),FALSE,IF(H9<>J9,TRUE,FALSE)) -> TRUE | AG9: =IF(AF9, COUNTIF($AF$2:AF9, TRUE), "") -> 4
A10: The responsibility for collecting, processing, and disseminating official statistics is clearly specified in law | B10: 1 | C10: 1_1 | D10: 1_1_1 | E10: 1_1_1_7 | F10: Is the Fundamental Principle of Official Statistics - Professional Standards, Scientific Principles, and Professional Ethics embedded in the law, such as a statistical law or other relevant law? | G10: 1 | H10: Highly - This recommendation / best practice is implemented but minor gaps exist in coverage and/or the consistency of its application across the program / organization | J10: Fully - This recommendation / best practice is fully implemented | K10: Part II Section 5(1) of the Statistical Act inculcates the scientific integrity of methods used, the protection against disclosing identifiable information and other professional standards | L10: European Statistical Code of Practice Principle 1 | M10: =IFERROR(INDEX(__key!$D:$D,MATCH(O10&"|"&SUBSTITUTE(H10,",",";"), __key!$E:$E, 0)), "") -> 4 | N10: =IFERROR(INDEX(__key!$D:$D,MATCH(O10&"|"&SUBSTITUTE(J10,",",";"), __key!$E:$E, 0)), "") -> 5 | O10: BP | Q10: The legal framework defining the national statistical system is comprehensive | R10: 1117 | S10: =IFERROR(1*M10,0) -> 4 | T10: =IFERROR(1*N10,0) -> 5 | U10: =IFERROR(IF(ISNUMBER(SEARCH("Not Relevant",H10)),0,VALUE(G10)),"") -> 1 | V10: =IFERROR(SUMIF($D:$D,D10,$U:$U),"") -> 150 | W10: =IF(OR(V10=0,V10=""),"",U10/V10) -> 0.0066666667 | X10: =IF(OR(M10="",W10=""),"",VALUE(M10)*W10) -> 0.026666667 | Y10: =IFERROR(ISNUMBER(SEARCH("Not Relevant",H10)),FALSE) -> FALSE | Z10: =IF(Y10, COUNTIF($Y$2:Y10, TRUE), "") | AA10: =IFERROR(IF(ISNUMBER(SEARCH("Not Relevant",J10)),0,VALUE(G10)),"") -> 1 | AB10: =IFERROR(SUMIF($D:$D,D10,$AA:$AA),"") -> 150 | AC10: =IF(OR(AB10=0,AB10=""),"",AA10/AB10) -> 0.0066666667 | AD10: =IF(OR(N10="",AC10=""),"",VALUE(N10)*AC10) -> 0.033333333 | AE10: =IFERROR(ISNUMBER(SEARCH("Not Relevant",J10)),FALSE) -> FALSE | AF10: =IF(OR(H10="",J10=""),FALSE,IF(H10<>J10,TRUE,FALSE)) -> TRUE | AG10: =IF(AF10, COUNTIF($AF$2:AF10, TRUE), "") -> 5
A11: The responsibility for collecting, processing, and disseminating official statistics is clearly specified in law | B11: 1 | C11: 1_1 | D11: 1_1_1 | E11: 1_1_1_8 | F11: Is the Fundamental Principle of Official Statistics - Accountability and Transparency embedded in the law, such as a statistical law or other relevant law? | G11: 1 | J11: =IF(H11="","",H11) | L11: European Statistical Code of Practice Principle 1 | M11: =IFERROR(INDEX(__key!$D:$D,MATCH(O11&"|"&SUBSTITUTE(H11,",",";"), __key!$E:$E, 0)), "") | N11: =IFERROR(INDEX(__key!$D:$D,MATCH(O11&"|"&SUBSTITUTE(J11,",",";"), __key!$E:$E, 0)), "") | O11: BP | Q11: The legal framework defining the national statistical system is comprehensive | R11: 1118 | S11: =IFERROR(1*M11,0) -> 0 | T11: =IFERROR(1*N11,0) -> 0 | U11: =IFERROR(IF(ISNUMBER(SEARCH("Not Relevant",H11)),0,VALUE(G11)),"") -> 1 | V11: =IFERROR(SUMIF($D:$D,D11,$U:$U),"") -> 150 | W11: =IF(OR(V11=0,V11=""),"",U11/V11) -> 0.0066666667 | X11: =IF(OR(M11="",W11=""),"",VALUE(M11)*W11) | Y11: =IFERROR(ISNUMBER(SEARCH("Not Relevant",H11)),FALSE) -> FALSE | Z11: =IF(Y11, COUNTIF($Y$2:Y11, TRUE), "") | AA11: =IFERROR(IF(ISNUMBER(SEARCH("Not Relevant",J11)),0,VALUE(G11)),"") -> 1 | AB11: =IFERROR(SUMIF($D:$D,D11,$AA:$AA),"") -> 150 | AC11: =IF(OR(AB11=0,AB11=""),"",AA11/AB11) -> 0.0066666667 | AD11: =IF(OR(N11="",AC11=""),"",VALUE(N11)*AC11) | AE11: =IFERROR(ISNUMBER(SEARCH("Not Relevant",J11)),FALSE) -> FALSE | AF11: =IF(OR(H11="",J11=""),FALSE,IF(H11<>J11,TRUE,FALSE)) -> FALSE | AG11: =IF(AF11, COUNTIF($AF$2:AF11, TRUE), "")
A12: The responsibility for collecting, processing, and disseminating official statistics is clearly specified in law | B12: 1 | C12: 1_1 | D12: 1_1_1 | E12: 1_1_1_9 | F12: Is the Fundamental Principle of Official Statistics - Prevention of Misuse embedded in the law, such as a statistical law or other relevant law? | G12: 1 | H12: Fully - This recommendation / best practice is fully implemented | J12: =IF(H12="","",H12) -> Fully - This recommendation / best practice is fully implemented | K12: Part IV of the Statistical Act, Section 10, describes the legal oath required by all employees to protect the use of information and its confidentiality. Part VIII reveals the penalties and imprisonment punishment for those who commit offences against misuse of data. | L12: European Statistical Code of Practice Principle 1 | M12: =IFERROR(INDEX(__key!$D:$D,MATCH(O12&"|"&SUBSTITUTE(H12,",",";"), __key!$E:$E, 0)), "") -> 5 | N12: =IFERROR(INDEX(__key!$D:$D,MATCH(O12&"|"&SUBSTITUTE(J12,",",";"), __key!$E:$E, 0)), "") -> 5 | O12: BP | Q12: The legal framework defining the national statistical system is comprehensive | R12: 1119 | S12: =IFERROR(1*M12,0) -> 5 | T12: =IFERROR(1*N12,0) -> 5 | U12: =IFERROR(IF(ISNUMBER(SEARCH("Not Relevant",H12)),0,VALUE(G12)),"") -> 1 | V12: =IFERROR(SUMIF($D:$D,D12,$U:$U),"") -> 150 | W12: =IF(OR(V12=0,V12=""),"",U12/V12) -> 0.0066666667 | X12: =IF(OR(M12="",W12=""),"",VALUE(M12)*W12) -> 0.033333333 | Y12: =IFERROR(ISNUMBER(SEARCH("Not Relevant",H12)),FALSE) -> FALSE | Z12: =IF(Y12, COUNTIF($Y$2:Y12, TRUE), "") | AA12: =IFERROR(IF(ISNUMBER(SEARCH("Not Relevant",J12)),0,VALUE(G12)),"") -> 1 | AB12: =IFERROR(SUMIF($D:$D,D12,$AA:$AA),"") -> 150 | AC12: =IF(OR(AB12=0,AB12=""),"",AA12/AB12) -> 0.0066666667 | AD12: =IF(OR(N12="",AC12=""),"",VALUE(N12)*AC12) -> 0.033333333 | AE12: =IFERROR(ISNUMBER(SEARCH("Not Relevant",J12)),FALSE) -> FALSE | AF12: =IF(OR(H12="",J12=""),FALSE,IF(H12<>J12,TRUE,FALSE)) -> FALSE | AG12: =IF(AF12, COUNTIF($AF$2:AF12, TRUE), "")
A13: The responsibility for collecting, processing, and disseminating official statistics is clearly specified in law | B13: 1 | C13: 1_1 | D13: 1_1_1 | E13: 1_1_1_10 | F13: Is the Fundamental Principle of Official Statistics - Sources of Official Statistics embedded in the law, such as a statistical law or other relevant law? | G13: 1 | H13: Highly - This recommendation / best practice is implemented but minor gaps exist in coverage and/or the consistency of its application across the program / organization | J13: =IF(H13="","",H13) -> Highly - This recommendation / best practice is implemented but minor gaps exist in coverage and/or the consistency of its application across the program / organization | K13: Again, the sources of official statistics may be collected from respondents including persons, businesses or organisations. | L13: European Statistical Code of Practice Principle 1 | M13: =IFERROR(INDEX(__key!$D:$D,MATCH(O13&"|"&SUBSTITUTE(H13,",",";"), __key!$E:$E, 0)), "") -> 4 | N13: =IFERROR(INDEX(__key!$D:$D,MATCH(O13&"|"&SUBSTITUTE(J13,",",";"), __key!$E:$E, 0)), "") -> 4 | O13: BP | Q13: The legal framework defining the national statistical system is comprehensive | R13: 11110 | S13: =IFERROR(1*M13,0) -> 4 | T13: =IFERROR(1*N13,0) -> 4 | U13: =IFERROR(IF(ISNUMBER(SEARCH("Not Relevant",H13)),0,VALUE(G13)),"") -> 1 | V13: =IFERROR(SUMIF($D:$D,D13,$U:$U),"") -> 150 | W13: =IF(OR(V13=0,V13=""),"",U13/V13) -> 0.0066666667 | X13: =IF(OR(M13="",W13=""),"",VALUE(M13)*W13) -> 0.026666667 | Y13: =IFERROR(ISNUMBER(SEARCH("Not Relevant",H13)),FALSE) -> FALSE | Z13: =IF(Y13, COUNTIF($Y$2:Y13, TRUE), "") | AA13: =IFERROR(IF(ISNUMBER(SEARCH("Not Relevant",J13)),0,VALUE(G13)),"") -> 1 | AB13: =IFERROR(SUMIF($D:$D,D13,$AA:$AA),"") -> 150 | AC13: =IF(OR(AB13=0,AB13=""),"",AA13/AB13) -> 0.0066666667 | AD13: =IF(OR(N13="",AC13=""),"",VALUE(N13)*AC13) -> 0.026666667 | AE13: =IFERROR(ISNUMBER(SEARCH("Not Relevant",J13)),FALSE) -> FALSE | AF13: =IF(OR(H13="",J13=""),FALSE,IF(H13<>J13,TRUE,FALSE)) -> FALSE | AG13: =IF(AF13, COUNTIF($AF$2:AF13, TRUE), "")
A14: The responsibility for collecting, processing, and disseminating official statistics is clearly specified in law | B14: 1 | C14: 1_1 | D14: 1_1_1 | E14: 1_1_1_11 | F14: Is the Fundamental Principle of Official Statistics - Confidentiality embedded in the law, such as a statistical law or other relevant law? | G14: 1 | H14: Fully - This recommendation / best practice is fully implemented | J14: Fully - This recommendation / best practice is fully implemented | K14: Part IV Section 11 clearly outlines protection measures against the disclosure of respondent information, with data being used only for statistical purposes and to prevent identification of any person. | L14: European Statistical Code of Practice Principle 1 | M14: =IFERROR(INDEX(__key!$D:$D,MATCH(O14&"|"&SUBSTITUTE(H14,",",";"), __key!$E:$E, 0)), "") -> 5 | N14: =IFERROR(INDEX(__key!$D:$D,MATCH(O14&"|"&SUBSTITUTE(J14,",",";"), __key!$E:$E, 0)), "") -> 5 | O14: BP | Q14: The legal framework defining the national statistical system is comprehensive | R14: 11111 | S14: =IFERROR(1*M14,0) -> 5 | T14: =IFERROR(1*N14,0) -> 5 | U14: =IFERROR(IF(ISNUMBER(SEARCH("Not Relevant",H14)),0,VALUE(G14)),"") -> 1 | V14: =IFERROR(SUMIF($D:$D,D14,$U:$U),"") -> 150 | W14: =IF(OR(V14=0,V14=""),"",U14/V14) -> 0.0066666667 | X14: =IF(OR(M14="",W14=""),"",VALUE(M14)*W14) -> 0.033333333 | Y14: =IFERROR(ISNUMBER(SEARCH("Not Relevant",H14)),FALSE) -> FALSE | Z14: =IF(Y14, COUNTIF($Y$2:Y14, TRUE), "") | AA14: =IFERROR(IF(ISNUMBER(SEARCH("Not Relevant",J14)),0,VALUE(G14)),"") -> 1 | AB14: =IFERROR(SUMIF($D:$D,D14,$AA:$AA),"") -> 150 | AC14: =IF(OR(AB14=0,AB14=""),"",AA14/AB14) -> 0.0066666667 | AD14: =IF(OR(N14="",AC14=""),"",VALUE(N14)*AC14) -> 0.033333333 | AE14: =IFERROR(ISNUMBER(SEARCH("Not Relevant",J14)),FALSE) -> FALSE | AF14: =IF(OR(H14="",J14=""),FALSE,IF(H14<>J14,TRUE,FALSE)) -> FALSE | AG14: =IF(AF14, COUNTIF($AF$2:AF14, TRUE), "")
A15: The responsibility for collecting, processing, and disseminating official statistics is clearly specified in law | B15: 1 | C15: 1_1 | D15: 1_1_1 | E15: 1_1_1_12 | F15: Is the Fundamental Principle of Official Statistics - Legislation embedded in the law, such as a statistical law or other relevant law? | G15: 1 | J15: =IF(H15="","",H15) | L15: European Statistical Code of Practice Principle 1 | M15: =IFERROR(INDEX(__key!$D:$D,MATCH(O15&"|"&SUBSTITUTE(H15,",",";"), __key!$E:$E, 0)), "") | N15: =IFERROR(INDEX(__key!$D:$D,MATCH(O15&"|"&SUBSTITUTE(J15,",",";"), __key!$E:$E, 0)), "") | O15: BP | Q15: The legal framework defining the national statistical system is comprehensive | R15: 11112 | S15: =IFERROR(1*M15,0) -> 0 | T15: =IFERROR(1*N15,0) -> 0 | U15: =IFERROR(IF(ISNUMBER(SEARCH("Not Relevant",H15)),0,VALUE(G15)),"") -> 1 | V15: =IFERROR(SUMIF($D:$D,D15,$U:$U),"") -> 150 | W15: =IF(OR(V15=0,V15=""),"",U15/V15) -> 0.0066666667 | X15: =IF(OR(M15="",W15=""),"",VALUE(M15)*W15) | Y15: =IFERROR(ISNUMBER(SEARCH("Not Relevant",H15)),FALSE) -> FALSE | Z15: =IF(Y15, COUNTIF($Y$2:Y15, TRUE), "") | AA15: =IFERROR(IF(ISNUMBER(SEARCH("Not Relevant",J15)),0,VALUE(G15)),"") -> 1 | AB15: =IFERROR(SUMIF($D:$D,D15,$AA:$AA),"") -> 150 | AC15: =IF(OR(AB15=0,AB15=""),"",AA15/AB15) -> 0.0066666667 | AD15: =IF(OR(N15="",AC15=""),"",VALUE(N15)*AC15) | AE15: =IFERROR(ISNUMBER(SEARCH("Not Relevant",J15)),FALSE) -> FALSE | AF15: =IF(OR(H15="",J15=""),FALSE,IF(H15<>J15,TRUE,FALSE)) -> FALSE | AG15: =IF(AF15, COUNTIF($AF$2:AF15, TRUE), "")
A16: The responsibility for collecting, processing, and disseminating official statistics is clearly specified in law | B16: 1 | C16: 1_1 | D16: 1_1_1 | E16: 1_1_1_13 | F16: Is the Fundamental Principle of Official Statistics - National Coordination embedded in the law, such as a statistical law or other relevant law? | G16: 1 | J16: =IF(H16="","",H16) | L16: European Statistical Code of Practice Principle 1 | M16: =IFERROR(INDEX(__key!$D:$D,MATCH(O16&"|"&SUBSTITUTE(H16,",",";"), __key!$E:$E, 0)), "") | N16: =IFERROR(INDEX(__key!$D:$D,MATCH(O16&"|"&SUBSTITUTE(J16,",",";"), __key!$E:$E, 0)), "") | O16: BP | Q16: The legal framework defining the national statistical system is comprehensive | R16: 11113 | S16: =IFERROR(1*M16,0) -> 0 | T16: =IFERROR(1*N16,0) -> 0 | U16: =IFERROR(IF(ISNUMBER(SEARCH("Not Relevant",H16)),0,VALUE(G16)),"") -> 1 | V16: =IFERROR(SUMIF($D:$D,D16,$U:$U),"") -> 150 | W16: =IF(OR(V16=0,V16=""),"",U16/V16) -> 0.0066666667 | X16: =IF(OR(M16="",W16=""),"",VALUE(M16)*W16) | Y16: =IFERROR(ISNUMBER(SEARCH("Not Relevant",H16)),FALSE) -> FALSE | Z16: =IF(Y16, COUNTIF($Y$2:Y16, TRUE), "") | AA16: =IFERROR(IF(ISNUMBER(SEARCH("Not Relevant",J16)),0,VALUE(G16)),"") -> 1 | AB16: =IFERROR(SUMIF($D:$D,D16,$AA:$AA),"") -> 150 | AC16: =IF(OR(AB16=0,AB16=""),"",AA16/AB16) -> 0.0066666667 | AD16: =IF(OR(N16="",AC16=""),"",VALUE(N16)*AC16) | AE16: =IFERROR(ISNUMBER(SEARCH("Not Relevant",J16)),FALSE) -> FALSE | AF16: =IF(OR(H16="",J16=""),FALSE,IF(H16<>J16,TRUE,FALSE)) -> FALSE | AG16: =IF(AF16, COUNTIF($AF$2:AF16, TRUE), "")
A17: The responsibility for collecting, processing, and disseminating official statistics is clearly specified in law | B17: 1 | C17: 1_1 | D17: 1_1_1 | E17: 1_1_1_14 | F17: Is the Fundamental Principle of Official Statistics - Use of International Standards embedded in the law, such as a statistical law or other relevant law? | G17: 1 | H17: Highly - This recommendation / best practice is implemented but minor gaps exist in coverage and/or the consistency of its application across the program / organization | J17: Fully - This recommendation / best practice is fully implemented | L17: European Statistical Code of Practice Principle 1 | M17: =IFERROR(INDEX(__key!$D:$D,MATCH(O17&"|"&SUBSTITUTE(H17,",",";"), __key!$E:$E, 0)), "") -> 4 | N17: =IFERROR(INDEX(__key!$D:$D,MATCH(O17&"|"&SUBSTITUTE(J17,",",";"), __key!$E:$E, 0)), "") -> 5 | O17: BP | Q17: The legal framework defining the national statistical system is comprehensive | R17: 11114 | S17: =IFERROR(1*M17,0) -> 4 | T17: =IFERROR(1*N17,0) -> 5 | U17: =IFERROR(IF(ISNUMBER(SEARCH("Not Relevant",H17)),0,VALUE(G17)),"") -> 1 | V17: =IFERROR(SUMIF($D:$D,D17,$U:$U),"") -> 150 | W17: =IF(OR(V17=0,V17=""),"",U17/V17) -> 0.0066666667 | X17: =IF(OR(M17="",W17=""),"",VALUE(M17)*W17) -> 0.026666667 | Y17: =IFERROR(ISNUMBER(SEARCH("Not Relevant",H17)),FALSE) -> FALSE | Z17: =IF(Y17, COUNTIF($Y$2:Y17, TRUE), "") | AA17: =IFERROR(IF(ISNUMBER(SEARCH("Not Relevant",J17)),0,VALUE(G17)),"") -> 1 | AB17: =IFERROR(SUMIF($D:$D,D17,$AA:$AA),"") -> 150 | AC17: =IF(OR(AB17=0,AB17=""),"",AA17/AB17) -> 0.0066666667 | AD17: =IF(OR(N17="",AC17=""),"",VALUE(N17)*AC17) -> 0.033333333 | AE17: =IFERROR(ISNUMBER(SEARCH("Not Relevant",J17)),FALSE) -> FALSE | AF17: =IF(OR(H17="",J17=""),FALSE,IF(H17<>J17,TRUE,FALSE)) -> TRUE | AG17: =IF(AF17, COUNTIF($AF$2:AF17, TRUE), "") -> 6
A18: The responsibility for collecting, processing, and disseminating official statistics is clearly specified in law | B18: 1 | C18: 1_1 | D18: 1_1_1 | E18: 1_1_1_15 | F18: Is the Fundamental Principle of Official Statistics - International Cooperation embedded in the law, such as a statistical law or other relevant law? | G18: 1 | H18: Highly - This recommendation / best practice is implemented but minor gaps exist in coverage and/or the consistency of its application across the program / organization | J18: Fully - This recommendation / best practice is fully implemented | K18: Part II Section 5(3d) outlines the coordination of international cooperation including Pacific regional collaboration on standards and information management | L18: European Statistical Code of Practice Principle 1 | M18: =IFERROR(INDEX(__key!$D:$D,MATCH(O18&"|"&SUBSTITUTE(H18,",",";"), __key!$E:$E, 0)), "") -> 4 | N18: =IFERROR(INDEX(__key!$D:$D,MATCH(O18&"|"&SUBSTITUTE(J18,",",";"), __key!$E:$E, 0)), "") -> 5 | O18: BP | Q18: The legal framework defining the national statistical system is comprehensive | R18: 11115 | S18: =IFERROR(1*M18,0) -> 4 | T18: =IFERROR(1*N18,0) -> 5 | U18: =IFERROR(IF(ISNUMBER(SEARCH("Not Relevant",H18)),0,VALUE(G18)),"") -> 1 | V18: =IFERROR(SUMIF($D:$D,D18,$U:$U),"") -> 150 | W18: =IF(OR(V18=0,V18=""),"",U18/V18) -> 0.0066666667 | X18: =IF(OR(M18="",W18=""),"",VALUE(M18)*W18) -> 0.026666667 | Y18: =IFERROR(ISNUMBER(SEARCH("Not Relevant",H18)),FALSE) -> FALSE | Z18: =IF(Y18, COUNTIF($Y$2:Y18, TRUE), "") | AA18: =IFERROR(IF(ISNUMBER(SEARCH("Not Relevant",J18)),0,VALUE(G18)),"") -> 1 | AB18: =IFERROR(SUMIF($D:$D,D18,$AA:$AA),"") -> 150 | AC18: =IF(OR(AB18=0,AB18=""),"",AA18/AB18) -> 0.0066666667 | AD18: =IF(OR(N18="",AC18=""),"",VALUE(N18)*AC18) -> 0.033333333 | AE18: =IFERROR(ISNUMBER(SEARCH("Not Relevant",J18)),FALSE) -> FALSE | AF18: =IF(OR(H18="",J18=""),FALSE,IF(H18<>J18,TRUE,FALSE)) -> TRUE | AG18: =IF(AF18, COUNTIF($AF$2:AF18, TRUE), "") -> 7
F19: The statistical organization operates independently and is free from political influence
A20: The statistical organization operates independently and is free from political influence | B20: 1 | C20: 1_2 | D20: 1_2_1 | E20: 1_2_1_1 | F20: Is there a National Statistical Office (NSO), department or organizational unit designated as a professionally independent body and the leading authority of the system? | G20: 20 | H20: Fully - This recommendation / best practice is fully implemented | J20: =IF(H20="","",H20) -> Fully - This recommendation / best practice is fully implemented | K20: Yes, the Tonga Statistical Department is the principal authority for the publication of official statistics | L20: NSO is recognized under the highest authority (e.g., Prime Minister, President), with legal independence and a clear coordination mandate (Article 5 GLOS). European Statistical Code of Practice Principle 1 | M20: =IFERROR(INDEX(__key!$D:$D,MATCH(O20&"|"&SUBSTITUTE(H20,",",";"), __key!$E:$E, 0)), "") -> 5 | N20: =IFERROR(INDEX(__key!$D:$D,MATCH(O20&"|"&SUBSTITUTE(J20,",",";"), __key!$E:$E, 0)), "") -> 5 | O20: BP | Q20: Professional independence is ensured | R20: 1211 | S20: =IFERROR(1*M20,0) -> 5 | T20: =IFERROR(1*N20,0) -> 5 | U20: =IFERROR(IF(ISNUMBER(SEARCH("Not Relevant",H20)),0,VALUE(G20)),"") -> 20 | V20: =IFERROR(SUMIF($D:$D,D20,$U:$U),"") -> 200 | W20: =IF(OR(V20=0,V20=""),"",U20/V20) -> 0.1 | X20: =IF(OR(M20="",W20=""),"",VALUE(M20)*W20) -> 0.5 | Y20: =IFERROR(ISNUMBER(SEARCH("Not Relevant",H20)),FALSE) -> FALSE | Z20: =IF(Y20, COUNTIF($Y$2:Y20, TRUE), "") | AA20: =IFERROR(IF(ISNUMBER(SEARCH("Not Relevant",J20)),0,VALUE(G20)),"") -> 20 | AB20: =IFERROR(SUMIF($D:$D,D20,$AA:$AA),"") -> 200 | AC20: =IF(OR(AB20=0,AB20=""),"",AA20/AB20) -> 0.1 | AD20: =IF(OR(N20="",AC20=""),"",VALUE(N20)*AC20) -> 0.5 | AE20: =IFERROR(ISNUMBER(SEARCH("Not Relevant",J20)),FALSE) -> FALSE | AF20: =IF(OR(H20="",J20=""),FALSE,IF(H20<>J20,TRUE,FALSE)) -> FALSE | AG20: =IF(AF20, COUNTIF($AF$2:AF20, TRUE), "")
A21: The statistical organization operates independently and is free from political influence | B21: 1 | C21: 1_2 | D21: 1_2_1 | E21: 1_2_1_2 | F21: Does the National Statistical Office, department, or organizational unit have full autonomy over statistical methods, data sources, content, and timing of releases (free from political/administrative interference)? | G21: 80 | H21: Fully - This recommendation / best practice is fully implemented | J21: =IF(H21="","",H21) -> Fully - This recommendation / best practice is fully implemented | K21: Section 6 of Government Statistician (GS) responsibilities highlihgt the autonomy of the GS over managing statistical methods, content and timing of releases | L21: The law guarantees professional independence in day-to-day operations and releases (Articles 3.1a, 5 GLOS). European Statistical Code of Practice Principle 1 | M21: =IFERROR(INDEX(__key!$D:$D,MATCH(O21&"|"&SUBSTITUTE(H21,",",";"), __key!$E:$E, 0)), "") -> 5 | N21: =IFERROR(INDEX(__key!$D:$D,MATCH(O21&"|"&SUBSTITUTE(J21,",",";"), __key!$E:$E, 0)), "") -> 5 | O21: BP | Q21: Professional independence is ensured | R21: 1212 | S21: =IFERROR(1*M21,0) -> 5 | T21: =IFERROR(1*N21,0) -> 5 | U21: =IFERROR(IF(ISNUMBER(SEARCH("Not Relevant",H21)),0,VALUE(G21)),"") -> 80 | V21: =IFERROR(SUMIF($D:$D,D21,$U:$U),"") -> 200 | W21: =IF(OR(V21=0,V21=""),"",U21/V21) -> 0.4 | X21: =IF(OR(M21="",W21=""),"",VALUE(M21)*W21) -> 2 | Y21: =IFERROR(ISNUMBER(SEARCH("Not Relevant",H21)),FALSE) -> FALSE | Z21: =IF(Y21, COUNTIF($Y$2:Y21, TRUE), "") | AA21: =IFERROR(IF(ISNUMBER(SEARCH("Not Relevant",J21)),0,VALUE(G21)),"") -> 80 | AB21: =IFERROR(SUMIF($D:$D,D21,$AA:$AA),"") -> 200 | AC21: =IF(OR(AB21=0,AB21=""),"",AA21/AB21) -> 0.4 | AD21: =IF(OR(N21="",AC21=""),"",VALUE(N21)*AC21) -> 2 | AE21: =IFERROR(ISNUMBER(SEARCH("Not Relevant",J21)),FALSE) -> FALSE | AF21: =IF(OR(H21="",J21=""),FALSE,IF(H21<>J21,TRUE,FALSE)) -> FALSE | AG21: =IF(AF21, COUNTIF($AF$2:AF21, TRUE), "")
A22: The statistical organization operates independently and is free from political influence | B22: 1 | C22: 1_2 | D22: 1_2_1 | E22: 1_2_1_3 | F22: Is the head of the statistical organization (e.g. Chief Statistician, Departmental Director, Director General, Statistical Unit Head), appointed through an open, merit-based process for a fixed term, with strictly limited grounds for dismissal? | G22: 50 | H22: Highly - This recommendation / best practice is implemented but minor gaps exist in coverage and/or the consistency of its application across the program / organization | J22: Fully - This recommendation / best practice is fully implemented | K22: Section 4 covers the appointment of the Government Statistician, however, its contents arent very detailed in its selection. | L22: Transparent appointment with legal protection of tenure (Article 6 GLOS). European Statistical Code of Practice Principle 1 | M22: =IFERROR(INDEX(__key!$D:$D,MATCH(O22&"|"&SUBSTITUTE(H22,",",";"), __key!$E:$E, 0)), "") -> 4 | N22: =IFERROR(INDEX(__key!$D:$D,MATCH(O22&"|"&SUBSTITUTE(J22,",",";"), __key!$E:$E, 0)), "") -> 5 | O22: BP | Q22: Professional independence is ensured | R22: 1213 | S22: =IFERROR(1*M22,0) -> 4 | T22: =IFERROR(1*N22,0) -> 5 | U22: =IFERROR(IF(ISNUMBER(SEARCH("Not Relevant",H22)),0,VALUE(G22)),"") -> 50 | V22: =IFERROR(SUMIF($D:$D,D22,$U:$U),"") -> 200 | W22: =IF(OR(V22=0,V22=""),"",U22/V22) -> 0.25 | X22: =IF(OR(M22="",W22=""),"",VALUE(M22)*W22) -> 1 | Y22: =IFERROR(ISNUMBER(SEARCH("Not Relevant",H22)),FALSE) -> FALSE | Z22: =IF(Y22, COUNTIF($Y$2:Y22, TRUE), "") | AA22: =IFERROR(IF(ISNUMBER(SEARCH("Not Relevant",J22)),0,VALUE(G22)),"") -> 50 | AB22: =IFERROR(SUMIF($D:$D,D22,$AA:$AA),"") -> 200 | AC22: =IF(OR(AB22=0,AB22=""),"",AA22/AB22) -> 0.25 | AD22: =IF(OR(N22="",AC22=""),"",VALUE(N22)*AC22) -> 1.25 | AE22: =IFERROR(ISNUMBER(SEARCH("Not Relevant",J22)),FALSE) -> FALSE | AF22: =IF(OR(H22="",J22=""),FALSE,IF(H22<>J22,TRUE,FALSE)) -> TRUE | AG22: =IF(AF22, COUNTIF($AF$2:AF22, TRUE), "") -> 8
A23: The statistical organization operates independently and is free from political influence | B23: 1 | C23: 1_2 | D23: 1_2_1 | E23: 1_2_1_4 | F23: Does the head of the statistical organization (e.g., Chief Statistician, Departmental Director, Director General, Statistical Unit Head) have full authority over organizational structure and staffing within the organization? | G23: 50 | J23: =IF(H23="","",H23) | L23: Chief Statistician independently decides on NSO structure, staffing, and statistical standards (Articles 6.3–6.5 GLOS). European Statistical Code of Practice Principle 1 | M23: =IFERROR(INDEX(__key!$D:$D,MATCH(O23&"|"&SUBSTITUTE(H23,",",";"), __key!$E:$E, 0)), "") | N23: =IFERROR(INDEX(__key!$D:$D,MATCH(O23&"|"&SUBSTITUTE(J23,",",";"), __key!$E:$E, 0)), "") | O23: BP | Q23: Professional independence is ensured | R23: 1214 | S23: =IFERROR(1*M23,0) -> 0 | T23: =IFERROR(1*N23,0) -> 0 | U23: =IFERROR(IF(ISNUMBER(SEARCH("Not Relevant",H23)),0,VALUE(G23)),"") -> 50 | V23: =IFERROR(SUMIF($D:$D,D23,$U:$U),"") -> 200 | W23: =IF(OR(V23=0,V23=""),"",U23/V23) -> 0.25 | X23: =IF(OR(M23="",W23=""),"",VALUE(M23)*W23) | Y23: =IFERROR(ISNUMBER(SEARCH("Not Relevant",H23)),FALSE) -> FALSE | Z23: =IF(Y23, COUNTIF($Y$2:Y23, TRUE), "") | AA23: =IFERROR(IF(ISNUMBER(SEARCH("Not Relevant",J23)),0,VALUE(G23)),"") -> 50 | AB23: =IFERROR(SUMIF($D:$D,D23,$AA:$AA),"") -> 200 | AC23: =IF(OR(AB23=0,AB23=""),"",AA23/AB23) -> 0.25 | AD23: =IF(OR(N23="",AC23=""),"",VALUE(N23)*AC23) | AE23: =IFERROR(ISNUMBER(SEARCH("Not Relevant",J23)),FALSE) -> FALSE | AF23: =IF(OR(H23="",J23=""),FALSE,IF(H23<>J23,TRUE,FALSE)) -> FALSE | AG23: =IF(AF23, COUNTIF($AF$2:AF23, TRUE), "")
F24: Data sharing and coordination among data-producing agencies are effective
A25: Data sharing and coordination among data-producing agencies are effective | B25: 1 | C25: 1_3 | D25: 1_3_1 | E25: 1_3_1_1 | F25: Are statistical producers (e.g., national statistical office, line ministries, central bank) clearly identified in the law and required to follow the principles of official statistics? | G25: 20 | J25: =IF(H25="","",H25) | L25: Entities producing official statistics must meet the same standards and be supervised/coordinated by the NSO (Articles 2.1, 7 GLOS). European Statistical Code of Practice Principle 2 | M25: =IFERROR(INDEX(__key!$D:$D,MATCH(O25&"|"&SUBSTITUTE(H25,",",";"), __key!$E:$E, 0)), "") | N25: =IFERROR(INDEX(__key!$D:$D,MATCH(O25&"|"&SUBSTITUTE(J25,",",";"), __key!$E:$E, 0)), "") | O25: BP | Q25: Effective coordination of the national statistical system | R25: 1311 | S25: =IFERROR(1*M25,0) -> 0 | T25: =IFERROR(1*N25,0) -> 0 | U25: =IFERROR(IF(ISNUMBER(SEARCH("Not Relevant",H25)),0,VALUE(G25)),"") -> 20 | V25: =IFERROR(SUMIF($D:$D,D25,$U:$U),"") -> 135 | W25: =IF(OR(V25=0,V25=""),"",U25/V25) -> 0.14814815 | X25: =IF(OR(M25="",W25=""),"",VALUE(M25)*W25) | Y25: =IFERROR(ISNUMBER(SEARCH("Not Relevant",H25)),FALSE) -> FALSE | Z25: =IF(Y25, COUNTIF($Y$2:Y25, TRUE), "") | AA25: =IFERROR(IF(ISNUMBER(SEARCH("Not Relevant",J25)),0,VALUE(G25)),"") -> 20 | AB25: =IFERROR(SUMIF($D:$D,D25,$AA:$AA),"") -> 135 | AC25: =IF(OR(AB25=0,AB25=""),"",AA25/AB25) -> 0.14814815 | AD25: =IF(OR(N25="",AC25=""),"",VALUE(N25)*AC25) | AE25: =IFERROR(ISNUMBER(SEARCH("Not Relevant",J25)),FALSE) -> FALSE | AF25: =IF(OR(H25="",J25=""),FALSE,IF(H25<>J25,TRUE,FALSE)) -> FALSE | AG25: =IF(AF25, COUNTIF($AF$2:AF25, TRUE), "")
A26: Data sharing and coordination among data-producing agencies are effective | B26: 1 | C26: 1_3 | D26: 1_3_1 | E26: 1_3_1_2 | F26: Does a governmental policy exist that assigns a body (e.g., NSO) the authority to coordinate the national statistical system, including issuing common standards, methods, and classifications? | G26: 15 | J26: =IF(H26="","",H26) | L26: NSO is empowered to set standards for official statistics across agencies, ensuring uniformity and avoiding duplication (Articles 5.2, 10 GLOS). European Statistical Code of Practice Principle 2 | M26: =IFERROR(INDEX(__key!$D:$D,MATCH(O26&"|"&SUBSTITUTE(H26,",",";"), __key!$E:$E, 0)), "") | N26: =IFERROR(INDEX(__key!$D:$D,MATCH(O26&"|"&SUBSTITUTE(J26,",",";"), __key!$E:$E, 0)), "") | O26: BP | Q26: Effective coordination of the national statistical system | R26: 1312 | S26: =IFERROR(1*M26,0) -> 0 | T26: =IFERROR(1*N26,0) -> 0 | U26: =IFERROR(IF(ISNUMBER(SEARCH("Not Relevant",H26)),0,VALUE(G26)),"") -> 15 | V26: =IFERROR(SUMIF($D:$D,D26,$U:$U),"") -> 135 | W26: =IF(OR(V26=0,V26=""),"",U26/V26) -> 0.11111111 | X26: =IF(OR(M26="",W26=""),"",VALUE(M26)*W26) | Y26: =IFERROR(ISNUMBER(SEARCH("Not Relevant",H26)),FALSE) -> FALSE | Z26: =IF(Y26, COUNTIF($Y$2:Y26, TRUE), "") | AA26: =IFERROR(IF(ISNUMBER(SEARCH("Not Relevant",J26)),0,VALUE(G26)),"") -> 15 | AB26: =IFERROR(SUMIF($D:$D,D26,$AA:$AA),"") -> 135 | AC26: =IF(OR(AB26=0,AB26=""),"",AA26/AB26) -> 0.11111111 | AD26: =IF(OR(N26="",AC26=""),"",VALUE(N26)*AC26) | AE26: =IFERROR(ISNUMBER(SEARCH("Not Relevant",J26)),FALSE) -> FALSE | AF26: =IF(OR(H26="",J26=""),FALSE,IF(H26<>J26,TRUE,FALSE)) -> FALSE | AG26: =IF(AF26, COUNTIF($AF$2:AF26, TRUE), "")
A27: Data sharing and coordination among data-producing agencies are effective | B27: 1 | C27: 1_3 | D27: 1_3_1 | E27: 1_3_1_3 | F27: Do public administrative data producer(s) have a legal obligation to share data with the NSO and other official producers? | G27: 30 | J27: =IF(H27="","",H27) | L27: Public authorities must give producers access to existing data free of charge; changes in admin data systems should be pre-consulted (Article 17 GLOS). European Statistical Code of Practice Principle 2 | M27: =IFERROR(INDEX(__key!$D:$D,MATCH(O27&"|"&SUBSTITUTE(H27,",",";"), __key!$E:$E, 0)), "") | N27: =IFERROR(INDEX(__key!$D:$D,MATCH(O27&"|"&SUBSTITUTE(J27,",",";"), __key!$E:$E, 0)), "") | O27: DS | Q27: Effective coordination of the national statistical system | R27: 1313 | S27: =IFERROR(1*M27,0) -> 0 | T27: =IFERROR(1*N27,0) -> 0 | U27: =IFERROR(IF(ISNUMBER(SEARCH("Not Relevant",H27)),0,VALUE(G27)),"") -> 30 | V27: =IFERROR(SUMIF($D:$D,D27,$U:$U),"") -> 135 | W27: =IF(OR(V27=0,V27=""),"",U27/V27) -> 0.22222222 | X27: =IF(OR(M27="",W27=""),"",VALUE(M27)*W27) | Y27: =IFERROR(ISNUMBER(SEARCH("Not Relevant",H27)),FALSE) -> FALSE | Z27: =IF(Y27, COUNTIF($Y$2:Y27, TRUE), "") | AA27: =IFERROR(IF(ISNUMBER(SEARCH("Not Relevant",J27)),0,VALUE(G27)),"") -> 30 | AB27: =IFERROR(SUMIF($D:$D,D27,$AA:$AA),"") -> 135 | AC27: =IF(OR(AB27=0,AB27=""),"",AA27/AB27) -> 0.22222222 | AD27: =IF(OR(N27="",AC27=""),"",VALUE(N27)*AC27) | AE27: =IFERROR(ISNUMBER(SEARCH("Not Relevant",J27)),FALSE) -> FALSE | AF27: =IF(OR(H27="",J27=""),FALSE,IF(H27<>J27,TRUE,FALSE)) -> FALSE | AG27: =IF(AF27, COUNTIF($AF$2:AF27, TRUE), "")
A28: Data sharing and coordination among data-producing agencies are effective | B28: 1 | C28: 1_3 | D28: 1_3_1 | E28: 1_3_1_4 | F28: Have MOUs or some other form of data exchange agreements been established with customs authorities? | G28: 5 | J28: =IF(H28="","",H28) | L28: European Statistical Code of Practice Principle 2 | M28: =IFERROR(INDEX(__key!$D:$D,MATCH(O28&"|"&SUBSTITUTE(H28,",",";"), __key!$E:$E, 0)), "") | N28: =IFERROR(INDEX(__key!$D:$D,MATCH(O28&"|"&SUBSTITUTE(J28,",",";"), __key!$E:$E, 0)), "") | O28: BP | Q28: Effective coordination of the national statistical system | R28: 1314 | S28: =IFERROR(1*M28,0) -> 0 | T28: =IFERROR(1*N28,0) -> 0 | U28: =IFERROR(IF(ISNUMBER(SEARCH("Not Relevant",H28)),0,VALUE(G28)),"") -> 5 | V28: =IFERROR(SUMIF($D:$D,D28,$U:$U),"") -> 135 | W28: =IF(OR(V28=0,V28=""),"",U28/V28) -> 0.037037037 | X28: =IF(OR(M28="",W28=""),"",VALUE(M28)*W28) | Y28: =IFERROR(ISNUMBER(SEARCH("Not Relevant",H28)),FALSE) -> FALSE | Z28: =IF(Y28, COUNTIF($Y$2:Y28, TRUE), "") | AA28: =IFERROR(IF(ISNUMBER(SEARCH("Not Relevant",J28)),0,VALUE(G28)),"") -> 5 | AB28: =IFERROR(SUMIF($D:$D,D28,$AA:$AA),"") -> 135 | AC28: =IF(OR(AB28=0,AB28=""),"",AA28/AB28) -> 0.037037037 | AD28: =IF(OR(N28="",AC28=""),"",VALUE(N28)*AC28) | AE28: =IFERROR(ISNUMBER(SEARCH("Not Relevant",J28)),FALSE) -> FALSE | AF28: =IF(OR(H28="",J28=""),FALSE,IF(H28<>J28,TRUE,FALSE)) -> FALSE | AG28: =IF(AF28, COUNTIF($AF$2:AF28, TRUE), "")
A29: Data sharing and coordination among data-producing agencies are effective | B29: 1 | C29: 1_3 | D29: 1_3_1 | E29: 1_3_1_5 | F29: What is the date the most recent data sharing agreement has been signed with customs authorities? | G29: 5 | J29: =IF(H29="","",H29) | L29: European Statistical Code of Practice Principle 2 | M29: =IFERROR(INDEX(__key!$D:$D,MATCH(O29&"|"&SUBSTITUTE(H29,",",";"), __key!$E:$E, 0)), "") | N29: =IFERROR(INDEX(__key!$D:$D,MATCH(O29&"|"&SUBSTITUTE(J29,",",";"), __key!$E:$E, 0)), "") | O29: TP | Q29: Effective coordination of the national statistical system | R29: 1315 | S29: =IFERROR(1*M29,0) -> 0 | T29: =IFERROR(1*N29,0) -> 0 | U29: =IFERROR(IF(ISNUMBER(SEARCH("Not Relevant",H29)),0,VALUE(G29)),"") -> 5 | V29: =IFERROR(SUMIF($D:$D,D29,$U:$U),"") -> 135 | W29: =IF(OR(V29=0,V29=""),"",U29/V29) -> 0.037037037 | X29: =IF(OR(M29="",W29=""),"",VALUE(M29)*W29) | Y29: =IFERROR(ISNUMBER(SEARCH("Not Relevant",H29)),FALSE) -> FALSE | Z29: =IF(Y29, COUNTIF($Y$2:Y29, TRUE), "") | AA29: =IFERROR(IF(ISNUMBER(SEARCH("Not Relevant",J29)),0,VALUE(G29)),"") -> 5 | AB29: =IFERROR(SUMIF($D:$D,D29,$AA:$AA),"") -> 135 | AC29: =IF(OR(AB29=0,AB29=""),"",AA29/AB29) -> 0.037037037 | AD29: =IF(OR(N29="",AC29=""),"",VALUE(N29)*AC29) | AE29: =IFERROR(ISNUMBER(SEARCH("Not Relevant",J29)),FALSE) -> FALSE | AF29: =IF(OR(H29="",J29=""),FALSE,IF(H29<>J29,TRUE,FALSE)) -> FALSE | AG29: =IF(AF29, COUNTIF($AF$2:AF29, TRUE), "")
A30: Data sharing and coordination among data-producing agencies are effective | B30: 1 | C30: 1_3 | D30: 1_3_1 | E30: 1_3_1_6 | F30: Have MOUs or some other form of data exchange agreements have been established with tax authorities? | G30: 5 | J30: =IF(H30="","",H30) | L30: European Statistical Code of Practice Principle 2 | M30: =IFERROR(INDEX(__key!$D:$D,MATCH(O30&"|"&SUBSTITUTE(H30,",",";"), __key!$E:$E, 0)), "") | N30: =IFERROR(INDEX(__key!$D:$D,MATCH(O30&"|"&SUBSTITUTE(J30,",",";"), __key!$E:$E, 0)), "") | O30: BP | Q30: Effective coordination of the national statistical system | R30: 1316 | S30: =IFERROR(1*M30,0) -> 0 | T30: =IFERROR(1*N30,0) -> 0 | U30: =IFERROR(IF(ISNUMBER(SEARCH("Not Relevant",H30)),0,VALUE(G30)),"") -> 5 | V30: =IFERROR(SUMIF($D:$D,D30,$U:$U),"") -> 135 | W30: =IF(OR(V30=0,V30=""),"",U30/V30) -> 0.037037037 | X30: =IF(OR(M30="",W30=""),"",VALUE(M30)*W30) | Y30: =IFERROR(ISNUMBER(SEARCH("Not Relevant",H30)),FALSE) -> FALSE | Z30: =IF(Y30, COUNTIF($Y$2:Y30, TRUE), "") | AA30: =IFERROR(IF(ISNUMBER(SEARCH("Not Relevant",J30)),0,VALUE(G30)),"") -> 5 | AB30: =IFERROR(SUMIF($D:$D,D30,$AA:$AA),"") -> 135 | AC30: =IF(OR(AB30=0,AB30=""),"",AA30/AB30) -> 0.037037037 | AD30: =IF(OR(N30="",AC30=""),"",VALUE(N30)*AC30) | AE30: =IFERROR(ISNUMBER(SEARCH("Not Relevant",J30)),FALSE) -> FALSE | AF30: =IF(OR(H30="",J30=""),FALSE,IF(H30<>J30,TRUE,FALSE)) -> FALSE | AG30: =IF(AF30, COUNTIF($AF$2:AF30, TRUE), "")
A31: Data sharing and coordination among data-producing agencies are effective | B31: 1 | C31: 1_3 | D31: 1_3_1 | E31: 1_3_1_7 | F31: What is the date the most recent data sharing agreement has been signed with tax authorities? | G31: 5 | J31: =IF(H31="","",H31) | L31: European Statistical Code of Practice Principle 2 | M31: =IFERROR(INDEX(__key!$D:$D,MATCH(O31&"|"&SUBSTITUTE(H31,",",";"), __key!$E:$E, 0)), "") | N31: =IFERROR(INDEX(__key!$D:$D,MATCH(O31&"|"&SUBSTITUTE(J31,",",";"), __key!$E:$E, 0)), "") | O31: TP | Q31: Effective coordination of the national statistical system | R31: 1317 | S31: =IFERROR(1*M31,0) -> 0 | T31: =IFERROR(1*N31,0) -> 0 | U31: =IFERROR(IF(ISNUMBER(SEARCH("Not Relevant",H31)),0,VALUE(G31)),"") -> 5 | V31: =IFERROR(SUMIF($D:$D,D31,$U:$U),"") -> 135 | W31: =IF(OR(V31=0,V31=""),"",U31/V31) -> 0.037037037 | X31: =IF(OR(M31="",W31=""),"",VALUE(M31)*W31) | Y31: =IFERROR(ISNUMBER(SEARCH("Not Relevant",H31)),FALSE) -> FALSE | Z31: =IF(Y31, COUNTIF($Y$2:Y31, TRUE), "") | AA31: =IFERROR(IF(ISNUMBER(SEARCH("Not Relevant",J31)),0,VALUE(G31)),"") -> 5 | AB31: =IFERROR(SUMIF($D:$D,D31,$AA:$AA),"") -> 135 | AC31: =IF(OR(AB31=0,AB31=""),"",AA31/AB31) -> 0.037037037 | AD31: =IF(OR(N31="",AC31=""),"",VALUE(N31)*AC31) | AE31: =IFERROR(ISNUMBER(SEARCH("Not Relevant",J31)),FALSE) -> FALSE | AF31: =IF(OR(H31="",J31=""),FALSE,IF(H31<>J31,TRUE,FALSE)) -> FALSE | AG31: =IF(AF31, COUNTIF($AF$2:AF31, TRUE), "")
A32: Data sharing and coordination among data-producing agencies are effective | B32: 1 | C32: 1_3 | D32: 1_3_1 | E32: 1_3_1_8 | F32: Have MOUs or some other form of data exchange agreements been established with social security authorities? | G32: 5 | J32: =IF(H32="","",H32) | L32: European Statistical Code of Practice Principle 2 | M32: =IFERROR(INDEX(__key!$D:$D,MATCH(O32&"|"&SUBSTITUTE(H32,",",";"), __key!$E:$E, 0)), "") | N32: =IFERROR(INDEX(__key!$D:$D,MATCH(O32&"|"&SUBSTITUTE(J32,",",";"), __key!$E:$E, 0)), "") | O32: BP | Q32: Effective coordination of the national statistical system | R32: 1318 | S32: =IFERROR(1*M32,0) -> 0 | T32: =IFERROR(1*N32,0) -> 0 | U32: =IFERROR(IF(ISNUMBER(SEARCH("Not Relevant",H32)),0,VALUE(G32)),"") -> 5 | V32: =IFERROR(SUMIF($D:$D,D32,$U:$U),"") -> 135 | W32: =IF(OR(V32=0,V32=""),"",U32/V32) -> 0.037037037 | X32: =IF(OR(M32="",W32=""),"",VALUE(M32)*W32) | Y32: =IFERROR(ISNUMBER(SEARCH("Not Relevant",H32)),FALSE) -> FALSE | Z32: =IF(Y32, COUNTIF($Y$2:Y32, TRUE), "") | AA32: =IFERROR(IF(ISNUMBER(SEARCH("Not Relevant",J32)),0,VALUE(G32)),"") -> 5 | AB32: =IFERROR(SUMIF($D:$D,D32,$AA:$AA),"") -> 135 | AC32: =IF(OR(AB32=0,AB32=""),"",AA32/AB32) -> 0.037037037 | AD32: =IF(OR(N32="",AC32=""),"",VALUE(N32)*AC32) | AE32: =IFERROR(ISNUMBER(SEARCH("Not Relevant",J32)),FALSE) -> FALSE | AF32: =IF(OR(H32="",J32=""),FALSE,IF(H32<>J32,TRUE,FALSE)) -> FALSE | AG32: =IF(AF32, COUNTIF($AF$2:AF32, TRUE), "")
A33: Data sharing and coordination among data-producing agencies are effective | B33: 1 | C33: 1_3 | D33: 1_3_1 | E33: 1_3_1_9 | F33: What is the date the most recent data sharing agreement has been signed with social security authorities? | G33: 5 | J33: =IF(H33="","",H33) | L33: European Statistical Code of Practice Principle 2 | M33: =IFERROR(INDEX(__key!$D:$D,MATCH(O33&"|"&SUBSTITUTE(H33,",",";"), __key!$E:$E, 0)), "") | N33: =IFERROR(INDEX(__key!$D:$D,MATCH(O33&"|"&SUBSTITUTE(J33,",",";"), __key!$E:$E, 0)), "") | O33: TP | Q33: Effective coordination of the national statistical system | R33: 1319 | S33: =IFERROR(1*M33,0) -> 0 | T33: =IFERROR(1*N33,0) -> 0 | U33: =IFERROR(IF(ISNUMBER(SEARCH("Not Relevant",H33)),0,VALUE(G33)),"") -> 5 | V33: =IFERROR(SUMIF($D:$D,D33,$U:$U),"") -> 135 | W33: =IF(OR(V33=0,V33=""),"",U33/V33) -> 0.037037037 | X33: =IF(OR(M33="",W33=""),"",VALUE(M33)*W33) | Y33: =IFERROR(ISNUMBER(SEARCH("Not Relevant",H33)),FALSE) -> FALSE | Z33: =IF(Y33, COUNTIF($Y$2:Y33, TRUE), "") | AA33: =IFERROR(IF(ISNUMBER(SEARCH("Not Relevant",J33)),0,VALUE(G33)),"") -> 5 | AB33: =IFERROR(SUMIF($D:$D,D33,$AA:$AA),"") -> 135 | AC33: =IF(OR(AB33=0,AB33=""),"",AA33/AB33) -> 0.037037037 | AD33: =IF(OR(N33="",AC33=""),"",VALUE(N33)*AC33) | AE33: =IFERROR(ISNUMBER(SEARCH("Not Relevant",J33)),FALSE) -> FALSE | AF33: =IF(OR(H33="",J33=""),FALSE,IF(H33<>J33,TRUE,FALSE)) -> FALSE | AG33: =IF(AF33, COUNTIF($AF$2:AF33, TRUE), "")
A34: Data sharing and coordination among data-producing agencies are effective | B34: 1 | C34: 1_3 | D34: 1_3_1 | E34: 1_3_1_10 | F34: Have MOUs or some other form of data exchange agreements been established with land registry authorities? | G34: 5 | J34: =IF(H34="","",H34) | L34: European Statistical Code of Practice Principle 2 | M34: =IFERROR(INDEX(__key!$D:$D,MATCH(O34&"|"&SUBSTITUTE(H34,",",";"), __key!$E:$E, 0)), "") | N34: =IFERROR(INDEX(__key!$D:$D,MATCH(O34&"|"&SUBSTITUTE(J34,",",";"), __key!$E:$E, 0)), "") | O34: BP | Q34: Effective coordination of the national statistical system | R34: 13110 | S34: =IFERROR(1*M34,0) -> 0 | T34: =IFERROR(1*N34,0) -> 0 | U34: =IFERROR(IF(ISNUMBER(SEARCH("Not Relevant",H34)),0,VALUE(G34)),"") -> 5 | V34: =IFERROR(SUMIF($D:$D,D34,$U:$U),"") -> 135 | W34: =IF(OR(V34=0,V34=""),"",U34/V34) -> 0.037037037 | X34: =IF(OR(M34="",W34=""),"",VALUE(M34)*W34) | Y34: =IFERROR(ISNUMBER(SEARCH("Not Relevant",H34)),FALSE) -> FALSE | Z34: =IF(Y34, COUNTIF($Y$2:Y34, TRUE), "") | AA34: =IFERROR(IF(ISNUMBER(SEARCH("Not Relevant",J34)),0,VALUE(G34)),"") -> 5 | AB34: =IFERROR(SUMIF($D:$D,D34,$AA:$AA),"") -> 135 | AC34: =IF(OR(AB34=0,AB34=""),"",AA34/AB34) -> 0.037037037 | AD34: =IF(OR(N34="",AC34=""),"",VALUE(N34)*AC34) | AE34: =IFERROR(ISNUMBER(SEARCH("Not Relevant",J34)),FALSE) -> FALSE | AF34: =IF(OR(H34="",J34=""),FALSE,IF(H34<>J34,TRUE,FALSE)) -> FALSE | AG34: =IF(AF34, COUNTIF($AF$2:AF34, TRUE), "")
A35: Data sharing and coordination among data-producing agencies are effective | B35: 1 | C35: 1_3 | D35: 1_3_1 | E35: 1_3_1_11 | F35: What is the date the most recent data sharing agreement has been signed with land registry authorities? | G35: 5 | J35: =IF(H35="","",H35) | L35: European Statistical Code of Practice Principle 2 | M35: =IFERROR(INDEX(__key!$D:$D,MATCH(O35&"|"&SUBSTITUTE(H35,",",";"), __key!$E:$E, 0)), "") | N35: =IFERROR(INDEX(__key!$D:$D,MATCH(O35&"|"&SUBSTITUTE(J35,",",";"), __key!$E:$E, 0)), "") | O35: TP | Q35: Effective coordination of the national statistical system | R35: 13111 | S35: =IFERROR(1*M35,0) -> 0 | T35: =IFERROR(1*N35,0) -> 0 | U35: =IFERROR(IF(ISNUMBER(SEARCH("Not Relevant",H35)),0,VALUE(G35)),"") -> 5 | V35: =IFERROR(SUMIF($D:$D,D35,$U:$U),"") -> 135 | W35: =IF(OR(V35=0,V35=""),"",U35/V35) -> 0.037037037 | X35: =IF(OR(M35="",W35=""),"",VALUE(M35)*W35) | Y35: =IFERROR(ISNUMBER(SEARCH("Not Relevant",H35)),FALSE) -> FALSE | Z35: =IF(Y35, COUNTIF($Y$2:Y35, TRUE), "") | AA35: =IFERROR(IF(ISNUMBER(SEARCH("Not Relevant",J35)),0,VALUE(G35)),"") -> 5 | AB35: =IFERROR(SUMIF($D:$D,D35,$AA:$AA),"") -> 135 | AC35: =IF(OR(AB35=0,AB35=""),"",AA35/AB35) -> 0.037037037 | AD35: =IF(OR(N35="",AC35=""),"",VALUE(N35)*AC35) | AE35: =IFERROR(ISNUMBER(SEARCH("Not Relevant",J35)),FALSE) -> FALSE | AF35: =IF(OR(H35="",J35=""),FALSE,IF(H35<>J35,TRUE,FALSE)) -> FALSE | AG35: =IF(AF35, COUNTIF($AF$2:AF35, TRUE), "")
A36: Data sharing and coordination among data-producing agencies are effective | B36: 1 | C36: 1_3 | D36: 1_3_1 | E36: 1_3_1_12 | F36: Have MOUs or some other form of data exchange agreements been established with private sector entities? | G36: 5 | J36: =IF(H36="","",H36) | L36: European Statistical Code of Practice Principle 2 | M36: =IFERROR(INDEX(__key!$D:$D,MATCH(O36&"|"&SUBSTITUTE(H36,",",";"), __key!$E:$E, 0)), "") | N36: =IFERROR(INDEX(__key!$D:$D,MATCH(O36&"|"&SUBSTITUTE(J36,",",";"), __key!$E:$E, 0)), "") | O36: BP | Q36: Effective coordination of the national statistical system | R36: 13112 | S36: =IFERROR(1*M36,0) -> 0 | T36: =IFERROR(1*N36,0) -> 0 | U36: =IFERROR(IF(ISNUMBER(SEARCH("Not Relevant",H36)),0,VALUE(G36)),"") -> 5 | V36: =IFERROR(SUMIF($D:$D,D36,$U:$U),"") -> 135 | W36: =IF(OR(V36=0,V36=""),"",U36/V36) -> 0.037037037 | X36: =IF(OR(M36="",W36=""),"",VALUE(M36)*W36) | Y36: =IFERROR(ISNUMBER(SEARCH("Not Relevant",H36)),FALSE) -> FALSE | Z36: =IF(Y36, COUNTIF($Y$2:Y36, TRUE), "") | AA36: =IFERROR(IF(ISNUMBER(SEARCH("Not Relevant",J36)),0,VALUE(G36)),"") -> 5 | AB36: =IFERROR(SUMIF($D:$D,D36,$AA:$AA),"") -> 135 | AC36: =IF(OR(AB36=0,AB36=""),"",AA36/AB36) -> 0.037037037 | AD36: =IF(OR(N36="",AC36=""),"",VALUE(N36)*AC36) | AE36: =IFERROR(ISNUMBER(SEARCH("Not Relevant",J36)),FALSE) -> FALSE | AF36: =IF(OR(H36="",J36=""),FALSE,IF(H36<>J36,TRUE,FALSE)) -> FALSE | AG36: =IF(AF36, COUNTIF($AF$2:AF36, TRUE), "")
... A41: Data sharing and coordination among data-producing agencies are effective | B41: 1 | C41: 1_3 | D41: 1_3_1 | E41: 1_3_1_17 | F41: Does the agency seek external expert assistance when needed, for evaluating statistical methodologies and systems? | G41: 5 | J41: =IF(H41="","",H41) | L41: Generally recognized as a good practice: External audits or peer reviews (e.g., from international agencies) can validate and help improve technical methods and compilation systems. European Statistical Code of Practice Principle 2 | M41: =IFERROR(INDEX(__key!$D:$D,MATCH(O41&"|"&SUBSTITUTE(H41,",",";"), __key!$E:$E, 0)), "") | N41: =IFERROR(INDEX(__key!$D:$D,MATCH(O41&"|"&SUBSTITUTE(J41,",",";"), __key!$E:$E, 0)), "") | O41: BP | Q41: Effective coordination of the national statistical system | R41: 13117 | S41: =IFERROR(1*M41,0) -> 0 | T41: =IFERROR(1*N41,0) -> 0 | U41: =IFERROR(IF(ISNUMBER(SEARCH("Not Relevant",H41)),0,VALUE(G41)),"") -> 5 | V41: =IFERROR(SUMIF($D:$D,D41,$U:$U),"") -> 135 | W41: =IF(OR(V41=0,V41=""),"",U41/V41) -> 0.037037037 | X41: =IF(OR(M41="",W41=""),"",VALUE(M41)*W41) | Y41: =IFERROR(ISNUMBER(SEARCH("Not Relevant",H41)),FALSE) -> FALSE | Z41: =IF(Y41, COUNTIF($Y$2:Y41, TRUE), "") | AA41: =IFERROR(IF(ISNUMBER(SEARCH("Not Relevant",J41)),0,VALUE(G41)),"") -> 5 | AB41: =IFERROR(SUMIF($D:$D,D41,$AA:$AA),"") -> 135 | AC41: =IF(OR(AB41=0,AB41=""),"",AA41/AB41) -> 0.037037037 | AD41: =IF(OR(N41="",AC41=""),"",VALUE(N41)*AC41) | AE41: =IFERROR(ISNUMBER(SEARCH("Not Relevant",J41)),FALSE) -> FALSE | AF41: =IF(OR(H41="",J41=""),FALSE,IF(H41<>J41,TRUE,FALSE)) -> FALSE | AG41: =IF(AF41, COUNTIF($AF$2:AF41, TRUE), "")
F42: Individual reporters’ data are kept confidential and used for statistical purposes only
A43: Individual reporters’ data are kept confidential and used for statistical purposes only | B43: 1 | C43: 1_4 | D43: 1_4_1 | E43: 1_4_1_1 | F43: Is the security and integrity of data and their transmission guaranteed by appropriate policies and practices? | G43: 20 | J43: =IF(H43="","",H43) | L43: UN NQAF (7.5) Assuring statistical confidentiality and data security. European Statistical Code of Practice Principle 5 | M43: =IFERROR(INDEX(__key!$D:$D,MATCH(O43&"|"&SUBSTITUTE(H43,",",";"), __key!$E:$E, 0)), "") | N43: =IFERROR(INDEX(__key!$D:$D,MATCH(O43&"|"&SUBSTITUTE(J43,",",";"), __key!$E:$E, 0)), "") | O43: BP | Q43: Statistical confidentiality and data security are assured | R43: 1411 | S43: =IFERROR(1*M43,0) -> 0 | T43: =IFERROR(1*N43,0) -> 0 | U43: =IFERROR(IF(ISNUMBER(SEARCH("Not Relevant",H43)),0,VALUE(G43)),"") -> 20 | V43: =IFERROR(SUMIF($D:$D,D43,$U:$U),"") -> 100 | W43: =IF(OR(V43=0,V43=""),"",U43/V43) -> 0.2 | X43: =IF(OR(M43="",W43=""),"",VALUE(M43)*W43) | Y43: =IFERROR(ISNUMBER(SEARCH("Not Relevant",H43)),FALSE) -> FALSE | Z43: =IF(Y43, COUNTIF($Y$2:Y43, TRUE), "") | AA43: =IFERROR(IF(ISNUMBER(SEARCH("Not Relevant",J43)),0,VALUE(G43)),"") -> 20 | AB43: =IFERROR(SUMIF($D:$D,D43,$AA:$AA),"") -> 100 | AC43: =IF(OR(AB43=0,AB43=""),"",AA43/AB43) -> 0.2 | AD43: =IF(OR(N43="",AC43=""),"",VALUE(N43)*AC43) | AE43: =IFERROR(ISNUMBER(SEARCH("Not Relevant",J43)),FALSE) -> FALSE | AF43: =IF(OR(H43="",J43=""),FALSE,IF(H43<>J43,TRUE,FALSE)) -> FALSE | AG43: =IF(AF43, COUNTIF($AF$2:AF43, TRUE), "")
