Workbook

Sheet Consolidated table
A4: Tonga
A5: GDP at market prices | B5: 872.59546 | C5: 850.81272 | D5: 845.95015 | E5: 846.29491 | F5: 827.99988 | G5: 867.33127 | H5: 822.2378 | I5: 828.8444 | J5: 884.54791 | K5: 892.85834 | L5: 896.23017 | M5: 914.06999 | N5: 924.25039 | O5: 985.23894 | P5: 1016.7894 | Q5: 1022.1563 | R5: 1019.241 | S5: 1037.6504 | T5: 1027.9492 | U5: 1006.0688 | V5: 1034.1396 | W5: 1051.891 | X5: 1080.1183 | Y5: 1105.345 | Z5: 1126.2913 | AA5: 1156.5996 | AB5: 1189.6926
A6: Potential GDP
A7: Linear | B7: 812.56505 | C7: 822.84126 | D7: 833.24742 | E7: 843.78519 | F7: 854.45623 | G7: 865.26222 | H7: 876.20487 | I7: 887.28591 | J7: 898.50708 | K7: 909.87017 | L7: 921.37696 | M7: 933.02927 | N7: 944.82894 | O7: 956.77785 | P7: 968.87786 | Q7: 981.1309 | R7: 993.53889 | S7: 1006.1038 | T7: 1018.8276 | U7: 1031.7124 | V7: 1044.76 | W7: 1057.9727
A8: HP Filter | B8: 863.92782 | C8: 855.17087 | D8: 847.85584 | E8: 842.60389 | F8: 839.72972 | G8: 840.14883 | H8: 842.91173 | I8: 851.40908 | J8: 865.80555 | K8: 882.58696 | L8: 901.0876 | M8: 922.29576 | N8: 946.48301 | O8: 972.56369 | P8: 995.53698 | Q8: 1012.0503 | R8: 1022.095 | S8: 1027.4348 | T8: 1029.4999 | U8: 1031.407 | V8: 1036.0565 | W8: 1042.2598
A9: Bpass Filter | B9: 860.997 | C9: 855.86091 | D9: 849.28489 | E9: 843.32918 | F9: 839.64114 | G9: 839.20486 | H9: 842.46189 | I9: 849.63725 | J9: 861.02025 | K9: 876.98834 | L9: 897.70757 | M9: 922.63163 | N9: 950.07351 | O9: 977.17763 | P9: 1000.5188 | Q9: 1017.2493 | R9: 1026.3046 | S9: 1028.9776 | T9: 1028.4647 | U9: 1028.5985 | V9: 1032.416 | W9: 1041.1744
A10: Output GAP
B12: =(B7-B5)/B5 -> -0.068795238 | C12: =(C7-C5)/C5 -> -0.032876172 | D12: =(D7-D5)/D5 -> -0.015015931 | E12: =(E7-E5)/E5 -> -0.0029655304 | F12: =(F7-F5)/F5 -> 0.031952126 | G12: =(G7-G5)/G5 -> -0.0023855396 | H12: =(H7-H5)/H5 -> 0.065634382 | I12: =(I7-I5)/I5 -> 0.070509628 | ... W12: =(W7-W5)/W5 -> 0.0057817274
B13: =(B8-B5)/B5 -> -0.0099331691 | C13: =(C8-C5)/C5 -> 0.0051223344 | D13: =(D8-D5)/D5 -> 0.0022527135 | E13: =(E8-E5)/E5 -> -0.004361387 | F13: =(F8-F5)/F5 -> 0.014166481 | G13: =(G8-G5)/G5 -> -0.031340331 | H13: =(H8-H5)/H5 -> 0.025143487 | I13: =(I8-I5)/I5 -> 0.027224267 | ... W13: =(W8-W5)/W5 -> -0.0091560332
B14: =(B9-B5)/B5 -> -0.013291907 | C14: =(C9-C5)/C5 -> 0.0059333675 | D14: =(D9-D5)/D5 -> 0.0039419966 | E14: =(E9-E5)/E5 -> -0.003504363 | F14: =(F9-F5)/F5 -> 0.014059495 | G14: =(G9-G5)/G5 -> -0.032428684 | H14: =(H9-H5)/H5 -> 0.024596402 | I14: =(I9-I5)/I5 -> 0.025086559 | ... W14: =(W9-W5)/W5 -> -0.010187926
D19: Linear | E19: HP Filter | F19: Bpass | H19: Linear | I19: HP Filter | J19: Bpass
B20: Real GDP | C20: Ln(Real GDP) | D20: Potential GDP | E20: Potential GDP | F20: Potential GDP | H20: Output Gap | I20: Output Gap | J20: Output Gap
B21: ='Output Gap estimators'!C11 -> 872.59546 | C21: =LN(B21) -> 6.7714721 | D21: {='Output Gap estimators'!J11:J32} -> 812.56505 | E21: {='Output Gap estimators'!O11:O32} -> 863.92782 | F21: {='Output Gap estimators'!V11:V32} -> 860.997 | H21: {='Output Gap estimators'!AC11:AC32} -> 7.387767 | I21: {='Output Gap estimators'!AD11:AD32} -> 1.0032827 | J21: {='Output Gap estimators'!AE11:AE32} -> 1.3470962
B22: ='Output Gap estimators'!C12 -> 850.81272 | C22: =LN(B22) -> 6.746192 | D22: 822.84126 | E22: 855.17087 | F22: 855.86091 | H22: 3.3993756 | I22: -0.50962298 | J22: -0.58983703
B23: ='Output Gap estimators'!C13 -> 845.95015 | C23: =LN(B23) -> 6.7404604 | D23: 833.24742 | E23: 847.85584 | F23: 849.28489 | H23: 1.5244847 | I23: -0.22476502 | J23: -0.39265183
B24: ='Output Gap estimators'!C14 -> 846.29491 | C24: =LN(B24) -> 6.7408679 | D24: 843.78519 | E24: 842.60389 | F24: 843.32918 | H24: 0.2974351 | I24: 0.43804921 | J24: 0.35166867
B25: ='Output Gap estimators'!C15 -> 827.99988 | C25: =LN(B25) -> 6.719013 | D25: 854.45623 | E25: 839.72972 | F25: 839.64114 | H25: -3.0962799 | I25: -1.3968595 | J25: -1.3864567
B26: ='Output Gap estimators'!C16 -> 867.33127 | C26: =LN(B26) -> 6.765421 | D26: 865.26222 | E26: 840.14883 | F26: 839.20486 | H26: 0.2391244 | I26: 3.2354326 | J26: 3.3515549
B27: ='Output Gap estimators'!C17 -> 822.2378 | C27: =LN(B27) -> 6.7120296 | D27: 876.20487 | E27: 842.91173 | F27: 842.46189 | H27: -6.1591839 | I27: -2.4526797 | J27: -2.4005942
B28: ='Output Gap estimators'!C18 -> 828.8444 | C28: =LN(B28) -> 6.7200324 | D28: 887.28591 | E28: 851.40908 | F28: 849.63725 | H28: -6.5865478 | I28: -2.6502749 | J28: -2.4472625
B29: ='Output Gap estimators'!C19 -> 884.54791 | C29: =LN(B29) -> 6.7850767 | D29: 898.50708 | E29: 865.80555 | F29: 861.02025 | H29: -1.553596 | I29: 2.1647318 | J29: 2.7325327
B30: ='Output Gap estimators'!C20 -> 892.85834 | C30: =LN(B30) -> 6.7944279 | D30: 909.87017 | E30: 882.58696 | F30: 876.98834 | H30: -1.8696985 | I30: 1.1637814 | J30: 1.8096018
B31: ='Output Gap estimators'!C21 -> 896.23017 | C31: =LN(B31) -> 6.7981973 | D31: 921.37696 | E31: 901.0876 | F31: 897.70757 | H31: -2.7292622 | I31: -0.53906381 | J31: -0.16457467
B32: ='Output Gap estimators'!C22 -> 914.06999 | C32: =LN(B32) -> 6.8179071 | D32: 933.02927 | E32: 922.29576 | F32: 922.63163 | H32: -2.0320138 | I32: -0.89188003 | J32: -0.92795902
B33: ='Output Gap estimators'!C23 -> 924.25039 | C33: =LN(B33) -> 6.828983 | D33: 944.82894 | E33: 946.48301 | F33: 950.07351 | H33: -2.1780194 | I33: -2.3489722 | J33: -2.7180133
... B42: ='Output Gap estimators'!C32 -> 1051.891 | C42: =LN(B42) -> 6.9583448 | D42: 1057.9727 | E42: 1042.2598 | F42: 1041.1744 | H42: -0.57484912 | I42: 0.92406408 | J42: 1.0292788
C44: Real growth | D44: Linear growth | E44: HP growth | F44: Bpass growth
C45: {='Output Gap estimators'!D12:D32} -> -2.4963159 | D45: {='Output Gap estimators'!K12:K32} -> 1.2646628 | E45: {='Output Gap estimators'!P12:P32} -> -1.013621 | F45: {='Output Gap estimators'!W12:W32} -> -0.59652906
C46: -0.5715204 | D46: 1.2646628 | E46: -0.85538838 | F46: -0.76835152
C47: 0.040753507 | D47: 1.2646628 | E47: -0.61943887 | F47: -0.7012609
C48: -2.1617798 | D48: 1.2646628 | E48: -0.34110551 | F48: -0.43731998
C49: 4.7501698 | D49: 1.2646628 | E49: 0.049909689 | F49: -0.051959435
C50: -5.1991061 | D50: 1.2646628 | E50: 0.32885855 | F50: 0.38810908
C51: 0.80348978 | D51: 1.2646628 | E51: 1.0080952 | F51: 0.85171321
C52: 6.720624 | D52: 1.2646628 | E52: 1.6908988 | F52: 1.3397484 | W52: Notice how HP and Bpass filter smoothen out the fluctuations in real growth
C53: 0.93951117 | D53: 1.2646628 | E53: 1.9382426 | F53: 1.8545545 | W53: Linear growth is constant because we've produced a linear trend that grows at a constant growth rate
C54: 0.37764393 | D54: 1.2646628 | E54: 2.0961839 | F54: 2.3625424
C55: 1.9905402 | D55: 1.2646628 | E55: 2.3536175 | F55: 2.7764125
C56: 1.1137441 | D56: 1.2646628 | E56: 2.6225049 | F56: 2.9743052
C57: 6.5987044 | D57: 1.2646628 | E57: 2.7555363 | F57: 2.8528444
...

Sheet Output Gap estimators
I4: Estimated Linear Trend (OLS) | V4: BP Filter
I5: Intercept | J5: =INTERCEPT(E11:E32,_xlfn.ANCHORARRAY(H11)) -> 6.6876286 | N5: HP FILTER | V5: PL | W5: 2
I6: Slope | J6: =SLOPE(E11:E32,_xlfn.ANCHORARRAY(H11)) -> 0.012567328 | N6: Lambda | O6: =6.25 -> 6.25 | V6: PU | W6: 8
D9: Real GDP | H9: Linear Trend | N9: Hodrick-Prescott Filter | U9: Band-Pass Filter | AC9: Estimated Output Gaps
C10: Real GDP (mils) | D10: Real GDP growth (%\delta, yoy) | E10: Log (ln) of real gdp | H10: Time (t) | I10: Potential GDP (ln) | J10: Potential GDP(mil) | K10: Potential Growth | N10: Potential GDP (ln) | O10: Potential GDP -HP | P10: Potential growth (% yoy) HP | U10: Cyclical Component of GDP | V10: Potential GDP -HP | W10: Potential growth (% yoy) HP | AC10: Linear Trend Ouptut Gap | AD10: HP Filter Output Gap | AE10: BP Filter Gap
B11: 2003 | C11: 872.59546 | E11: =LN(C11) -> 6.7714721 | H11: {=_xlfn.SEQUENCE(22,1)} -> 1 | I11: =$J$5 + $J$6*H11 -> 6.700196 | J11: =EXP(I11) -> 812.56505 | N11: {=[1]!hp(E11:E32,O6)} -> 6.7614892 | O11: =EXP(N11) -> 863.92782 | U11: {=[2]!bpass(E11:E32,W5,W6)} -> 0.013381035 | V11: =EXP(E11-U11) -> 860.997 | AC11: =((C11-J11)/J11)*100 -> 7.387767 | AD11: =(C11/O11-1)*100 -> 1.0032827 | AE11: =(C11/V11-1)*100 -> 1.3470962
B12: 2004 | C12: 850.81272 | D12: =(C12/C11-1)*100 -> -2.4963159 | E12: =LN(C12) -> 6.746192 | H12: 2 | I12: =$J$5 + $J$6*H12 -> 6.7127633 | J12: =EXP(I12) -> 822.84126 | K12: =(J12/J11-1)*100 -> 1.2646628 | N12: 6.7513013 | O12: =EXP(N12) -> 855.17087 | P12: =100*(O12/O11-1) -> -1.013621 | U12: -0.0059158344 | V12: =EXP(E12-U12) -> 855.86091 | W12: =100*(V12/V11-1) -> -0.59652906 | AC12: =((C12-J12)/J12)*100 -> 3.3993756 | AD12: =(C12/O12-1)*100 -> -0.50962298 | AE12: =(C12/V12-1)*100 -> -0.58983703
B13: 2005 | C13: 845.95015 | D13: =(C13/C12-1)*100 -> -0.5715204 | E13: =LN(C13) -> 6.7404604 | H13: 3 | I13: =$J$5 + $J$6*H13 -> 6.7253306 | J13: =EXP(I13) -> 833.24742 | K13: =(J13/J12-1)*100 -> 1.2646628 | N13: 6.7427106 | O13: =EXP(N13) -> 847.85584 | P13: =100*(O13/O12-1) -> -0.85538838 | U13: -0.0039342473 | V13: =EXP(E13-U13) -> 849.28489 | W13: =100*(V13/V12-1) -> -0.76835152 | AC13: =((C13-J13)/J13)*100 -> 1.5244847 | AD13: =(C13/O13-1)*100 -> -0.22476502 | AE13: =(C13/V13-1)*100 -> -0.39265183
B14: 2006 | C14: 846.29491 | D14: =(C14/C13-1)*100 -> 0.040753507 | E14: =LN(C14) -> 6.7408679 | H14: 4 | I14: =$J$5 + $J$6*H14 -> 6.737898 | J14: =EXP(I14) -> 843.78519 | K14: =(J14/J13-1)*100 -> 1.2646628 | N14: 6.736497 | O14: =EXP(N14) -> 842.60389 | P14: =100*(O14/O13-1) -> -0.61943887 | U14: 0.0035105177 | V14: =EXP(E14-U14) -> 843.32918 | W14: =100*(V14/V13-1) -> -0.7012609 | AC14: =((C14-J14)/J14)*100 -> 0.2974351 | AD14: =(C14/O14-1)*100 -> 0.43804921 | AE14: =(C14/V14-1)*100 -> 0.35166867
B15: 2007 | C15: 827.99988 | D15: =(C15/C14-1)*100 -> -2.1617798 | E15: =LN(C15) -> 6.719013 | H15: 5 | I15: =$J$5 + $J$6*H15 -> 6.7504653 | J15: =EXP(I15) -> 854.45623 | K15: =(J15/J14-1)*100 -> 1.2646628 | N15: 6.7330801 | O15: =EXP(N15) -> 839.72972 | P15: =100*(O15/O14-1) -> -0.34110551 | U15: -0.013961577 | V15: =EXP(E15-U15) -> 839.64114 | W15: =100*(V15/V14-1) -> -0.43731998 | AC15: =((C15-J15)/J15)*100 -> -3.0962799 | AD15: =(C15/O15-1)*100 -> -1.3968595 | AE15: =(C15/V15-1)*100 -> -1.3864567
B16: 2008 | C16: 867.33127 | D16: =(C16/C15-1)*100 -> 4.7501698 | E16: =LN(C16) -> 6.765421 | H16: 6 | I16: =$J$5 + $J$6*H16 -> 6.7630326 | J16: =EXP(I16) -> 865.26222 | K16: =(J16/J15-1)*100 -> 1.2646628 | N16: 6.733579 | O16: =EXP(N16) -> 840.14883 | P16: =100*(O16/O15-1) -> 0.049909689 | U16: 0.032966145 | V16: =EXP(E16-U16) -> 839.20486 | W16: =100*(V16/V15-1) -> -0.051959435 | AC16: =((C16-J16)/J16)*100 -> 0.2391244 | AD16: =(C16/O16-1)*100 -> 3.2354326 | AE16: =(C16/V16-1)*100 -> 3.3515549
B17: 2009 | C17: 822.2378 | D17: =(C17/C16-1)*100 -> -5.1991061 | E17: =LN(C17) -> 6.7120296 | H17: 7 | I17: =$J$5 + $J$6*H17 -> 6.7755999 | J17: =EXP(I17) -> 876.20487 | K17: =(J17/J16-1)*100 -> 1.2646628 | N17: 6.7368622 | O17: =EXP(N17) -> 842.91173 | P17: =100*(O17/O16-1) -> 0.32885855 | U17: -0.024298781 | V17: =EXP(E17-U17) -> 842.46189 | W17: =100*(V17/V16-1) -> 0.38810908 | AC17: =((C17-J17)/J17)*100 -> -6.1591839 | AD17: =(C17/O17-1)*100 -> -2.4526797 | AE17: =(C17/V17-1)*100 -> -2.4005942
B18: 2010 | C18: 828.8444 | D18: =(C18/C17-1)*100 -> 0.80348978 | E18: =LN(C18) -> 6.7200324 | H18: 8 | I18: =$J$5 + $J$6*H18 -> 6.7881673 | J18: =EXP(I18) -> 887.28591 | K18: =(J18/J17-1)*100 -> 1.2646628 | N18: 6.7468927 | O18: =EXP(N18) -> 851.40908 | P18: =100*(O18/O17-1) -> 1.0080952 | U18: -0.024777057 | V18: =EXP(E18-U18) -> 849.63725 | W18: =100*(V18/V17-1) -> 0.85171321 | AC18: =((C18-J18)/J18)*100 -> -6.5865478 | AD18: =(C18/O18-1)*100 -> -2.6502749 | AE18: =(C18/V18-1)*100 -> -2.4472625
B19: 2011 | C19: 884.54791 | D19: =(C19/C18-1)*100 -> 6.720624 | E19: =LN(C19) -> 6.7850767 | H19: 9 | I19: =$J$5 + $J$6*H19 -> 6.8007346 | J19: =EXP(I19) -> 898.50708 | K19: =(J19/J18-1)*100 -> 1.2646628 | N19: 6.7636603 | O19: =EXP(N19) -> 865.80555 | P19: =100*(O19/O18-1) -> 1.6908988 | U19: 0.026958655 | V19: =EXP(E19-U19) -> 861.02025 | W19: =100*(V19/V18-1) -> 1.3397484 | AC19: =((C19-J19)/J19)*100 -> -1.553596 | AD19: =(C19/O19-1)*100 -> 2.1647318 | AE19: =(C19/V19-1)*100 -> 2.7325327
B20: 2012 | C20: 892.85834 | D20: =(C20/C19-1)*100 -> 0.93951117 | E20: =LN(C20) -> 6.7944279 | H20: 10 | I20: =$J$5 + $J$6*H20 -> 6.8133019 | J20: =EXP(I20) -> 909.87017 | K20: =(J20/J19-1)*100 -> 1.2646628 | N20: 6.7828573 | O20: =EXP(N20) -> 882.58696 | P20: =100*(O20/O19-1) -> 1.9382426 | U20: 0.017934234 | V20: =EXP(E20-U20) -> 876.98834 | W20: =100*(V20/V19-1) -> 1.8545545 | AC20: =((C20-J20)/J20)*100 -> -1.8696985 | AD20: =(C20/O20-1)*100 -> 1.1637814 | AE20: =(C20/V20-1)*100 -> 1.8096018
B21: 2013 | C21: 896.23017 | D21: =(C21/C20-1)*100 -> 0.37764393 | E21: =LN(C21) -> 6.7981973 | H21: 11 | I21: =$J$5 + $J$6*H21 -> 6.8258692 | J21: =EXP(I21) -> 921.37696 | K21: =(J21/J20-1)*100 -> 1.2646628 | N21: 6.8036025 | O21: =EXP(N21) -> 901.0876 | P21: =100*(O21/O20-1) -> 2.0961839 | U21: -0.0016471025 | V21: =EXP(E21-U21) -> 897.70757 | W21: =100*(V21/V20-1) -> 2.3625424 | AC21: =((C21-J21)/J21)*100 -> -2.7292622 | AD21: =(C21/O21-1)*100 -> -0.53906381 | AE21: =(C21/V21-1)*100 -> -0.16457467
B22: 2014 | C22: 914.06999 | D22: =(C22/C21-1)*100 -> 1.9905402 | E22: =LN(C22) -> 6.8179071 | H22: 12 | I22: =$J$5 + $J$6*H22 -> 6.8384366 | J22: =EXP(I22) -> 933.02927 | K22: =(J22/J21-1)*100 -> 1.2646628 | N22: 6.826866 | O22: =EXP(N22) -> 922.29576 | P22: =100*(O22/O21-1) -> 2.3536175 | U22: -0.0093229138 | V22: =EXP(E22-U22) -> 922.63163 | W22: =100*(V22/V21-1) -> 2.7764125 | AC22: =((C22-J22)/J22)*100 -> -2.0320138 | AD22: =(C22/O22-1)*100 -> -0.89188003 | AE22: =(C22/V22-1)*100 -> -0.92795902
B23: 2015 | C23: 924.25039 | D23: =(C23/C22-1)*100 -> 1.1137441 | E23: =LN(C23) -> 6.828983 | H23: 13 | I23: =$J$5 + $J$6*H23 -> 6.8510039 | J23: =EXP(I23) -> 944.82894 | K23: =(J23/J22-1)*100 -> 1.2646628 | N23: 6.852753 | O23: =EXP(N23) -> 946.48301 | P23: =100*(O23/O22-1) -> 2.6225049 | U23: -0.027556345 | V23: =EXP(E23-U23) -> 950.07351 | W23: =100*(V23/V22-1) -> 2.9743052 | AC23: =((C23-J23)/J23)*100 -> -2.1780194 | AD23: =(C23/O23-1)*100 -> -2.3489722 | AE23: =(C23/V23-1)*100 -> -2.7180133
... B32: 2024 | C32: 1051.891 | D32: =(C32/C31-1)*100 -> 1.7165411 | E32: =LN(C32) -> 6.9583448 | H32: 22 | I32: =$J$5 + $J$6*H32 -> 6.9641098 | J32: =EXP(I32) -> 1057.9727 | K32: =(J32/J31-1)*100 -> 1.2646628 | N32: 6.9491466 | O32: =EXP(N32) -> 1042.2598 | P32: =100*(O32/O31-1) -> 0.59874126 | U32: 0.010240178 | V32: =EXP(E32-U32) -> 1041.1744 | W32: =100*(V32/V31-1) -> 0.84834292 | AC32: =((C32-J32)/J32)*100 -> -0.57484912 | AD32: =(C32/O32-1)*100 -> 0.92406408 | AE32: =(C32/V32-1)*100 -> 1.0292788
H35: Background | I35: Using the OLS derivation, we find B0, B1 such that the linear trend for REAL GDP is: y = B0 + B1 * x The intercept(B0) and the slope(B1) are calculated using the excel functions in cells J4 and J5 respectively to produce the potential GDP trend using a linear OLS model | M35: Background | N35: Hodrick Prescott Filter penalizes for goodness of fit and smoothness trends | T35: Background | U35: BPASS filter smooths out fluctations and deterministic trends over quarters
